<?xml version="1.0" encoding="UTF-8"?>
<robot xmlns:xacro="http://www.ros.org/wiki/xacro" name="kr10_r1100_2">
  <!-- include helper xacros -->
  <xacro:include filename="$(find kuka_resources)/urdf/common_materials.xacro"/>
  <xacro:macro name="kuka_kr10_r1100_2_robot" params="prefix package_name *origin">
    <!-- links - main serial chain -->
    <link name="world"/>
    <link name="${prefix}base_link">
      <collision>
        <geometry>
          <mesh filename="package://${package_name}/meshes/kr10_r1100_2/collision/base_link.stl"/>
        </geometry>
        <origin rpy="-0.0 0.0 -0.0" xyz="0.0 0.0 0.0"/>
      </collision>
      <inertial>
        <inertia ixx="0.16209200415615" ixy="0.0" ixz="0.0" iyy="0.10881181598555635" iyz="0.0" izz="0.18461591505869543"/>
        <mass value="1.6916E1"/>
        <origin rpy="1.6165592773339865 -1.221289277333065 3.10031147437779" xyz="-0.03713348309292976 2.6602033577676952E-5 0.10863850792149446"/>
      </inertial>
      <visual>
        <geometry>
          <mesh filename="package://${package_name}/meshes/kr10_r1100_2/visual/base_link.stl"/>
        </geometry>
        <origin rpy="-0.0 0.0 -0.0" xyz="0.0 0.0 0.0"/>
        <xacro:material_kuka_ral_pure_white/>
      </visual>
    </link>
    <link name="${prefix}link_1">
      <collision>
        <geometry>
          <mesh filename="package://${package_name}/meshes/kr10_r1100_2/collision/link_1.stl"/>
        </geometry>
        <origin rpy="-0.0 0.0 -0.0" xyz="0.0 0.0 0.0"/>
      </collision>
      <inertial>
        <inertia ixx="0.07406183855390855" ixy="0.0" ixz="0.0" iyy="0.0890478351825312" iyz="0.0" izz="0.11039570662759429"/>
        <mass value="8.4159999999999986E0"/>
        <origin rpy="1.304519343134156 -0.9428616016893947 -1.4226510948637578" xyz="0.006410408745247152 -0.01626805370722434 -0.10658893773764262"/>
      </inertial>
      <visual>
        <geometry>
          <mesh filename="package://${package_name}/meshes/kr10_r1100_2/visual/link_1.stl"/>
        </geometry>
        <origin rpy="-0.0 0.0 -0.0" xyz="0.0 0.0 0.0"/>
        <xacro:material_kuka_ral_pure_white/>
      </visual>
    </link>
    <link name="${prefix}link_2">
      <collision>
        <geometry>
          <mesh filename="package://${package_name}/meshes/kr10_r1100_2/collision/link_2.stl"/>
        </geometry>
        <origin rpy="-0.0 0.0 -0.0" xyz="0.0 0.0 0.0"/>
      </collision>
      <inertial>
        <inertia ixx="0.8751595055066254" ixy="0.0" ixz="0.0" iyy="0.09215049446198915" iyz="0.0" izz="0.9157117764876721"/>
        <mass value="1.78369E1"/>
        <origin rpy="1.9524873827550635 -1.5422358773344043 -0.3902815673307173" xyz="0.191160133767639 -0.004651344123698628 -0.07520541854245974"/>
      </inertial>
      <visual>
        <geometry>
          <mesh filename="package://${package_name}/meshes/kr10_r1100_2/visual/link_2.stl"/>
        </geometry>
        <origin rpy="-0.0 0.0 -0.0" xyz="0.0 0.0 0.0"/>
        <xacro:material_kuka_ral_pure_white/>
      </visual>
    </link>
    <link name="${prefix}link_3">
      <collision>
        <geometry>
          <mesh filename="package://${package_name}/meshes/kr10_r1100_2/collision/link_3.stl"/>
        </geometry>
        <origin rpy="-0.0 0.0 -0.0" xyz="0.0 0.0 0.0"/>
      </collision>
      <inertial>
        <inertia ixx="0.04469381119929391" ixy="0.0" ixz="0.0" iyy="0.018969508933922696" iyz="0.0" izz="0.0498412586885908"/>
        <mass value="6.075E0"/>
        <origin rpy="-2.676930368410595 -1.321895859309871 1.1860920267202666" xyz="0.04386106995884774 -0.012506995884773664 -0.06825142386831277"/>
      </inertial>
      <visual>
        <geometry>
          <mesh filename="package://${package_name}/meshes/kr10_r1100_2/visual/link_3.stl"/>
        </geometry>
        <origin rpy="-0.0 0.0 -0.0" xyz="0.0 0.0 0.0"/>
        <xacro:material_kuka_ral_pure_white/>
      </visual>
    </link>
    <link name="${prefix}link_4">
      <collision>
        <geometry>
          <mesh filename="package://${package_name}/meshes/kr10_r1100_2/collision/link_4.stl"/>
        </geometry>
        <origin rpy="-0.0 0.0 -0.0" xyz="0.0 0.0 0.0"/>
      </collision>
      <inertial>
        <inertia ixx="0.012301413884477554" ixy="0.0" ixz="0.0" iyy="0.08469612193319441" iyz="0.0" izz="0.08739834186747329"/>
        <mass value="5.1623807059999995E0"/>
        <origin rpy="-2.228094247436686 -1.5326119469267911 2.179783954730353" xyz="0.0013191433102012267 0.008607757626765767 -0.14098161935749579"/>
      </inertial>
      <visual>
        <geometry>
          <mesh filename="package://${package_name}/meshes/kr10_r1100_2/visual/link_4.stl"/>
        </geometry>
        <origin rpy="-0.0 0.0 -0.0" xyz="0.0 0.0 0.0"/>
        <xacro:material_kuka_ral_pure_white/>
      </visual>
    </link>
    <link name="${prefix}link_5">
      <collision>
        <geometry>
          <mesh filename="package://${package_name}/meshes/kr10_r1100_2/collision/link_5.stl"/>
        </geometry>
        <origin rpy="-0.0 0.0 -0.0" xyz="0.0 0.0 0.0"/>
      </collision>
      <inertial>
        <inertia ixx="0.0017317756133102904" ixy="0.0" ixz="0.0" iyy="0.002219500805440681" iyz="0.0" izz="0.002467090055442975"/>
        <mass value="1.6128E0"/>
        <origin rpy="1.567898714902774 -0.8611716764868309 -3.100280255900493" xyz="0.009320696924603175 7.83482142857143E-4 -0.026462549603174602"/>
      </inertial>
      <visual>
        <geometry>
          <mesh filename="package://${package_name}/meshes/kr10_r1100_2/visual/link_5.stl"/>
        </geometry>
        <origin rpy="-0.0 0.0 -0.0" xyz="0.0 0.0 0.0"/>
        <xacro:material_kuka_ral_pure_white/>
      </visual>
    </link>
    <link name="${prefix}link_6">
      <collision>
        <geometry>
          <mesh filename="package://${package_name}/meshes/kr10_r1100_2/collision/link_6.stl"/>
        </geometry>
        <origin rpy="-0.0 0.0 -0.0" xyz="0.0 0.0 0.0"/>
      </collision>
      <inertial>
        <inertia ixx="1.83698267603013E-4" ixy="0.0" ixz="0.0" iyy="1.8213621766783165E-4" iyz="0.0" izz="2.9589000000000004E-4"/>
        <mass value="7.34E-1"/>
        <origin rpy="0.0 -0.0 1.223427188696551" xyz="0.0 0.0 -0.011764604904632152"/>
      </inertial>
      <visual>
        <geometry>
          <mesh filename="package://${package_name}/meshes/kr10_r1100_2/visual/link_6.stl"/>
        </geometry>
        <origin rpy="-0.0 0.0 -0.0" xyz="0.0 0.0 0.0"/>
        <xacro:material_kuka_ral_pure_white/>
      </visual>
    </link>
    <!-- joints - main serial chain -->
    <joint name="${prefix}world-base_link" type="fixed">
      <parent link="world"/>
      <child link="${prefix}base_link"/>
      <xacro:insert_block name="origin"/>
    </joint>
    <joint name="${prefix}joint_1" type="revolute">
      <axis xyz="0.0 0.0 1.0"/>
      <child link="${prefix}link_1"/>
      <limit effort="288.36" lower="-2.9670597283903604E0" upper="2.9670597283903604E0" velocity="${radians(300)}"/>
      <origin rpy="-3.141592653589793 0.0 -0.0" xyz="0.0 0.0 0.0"/>
      <parent link="${prefix}base_link"/>
    </joint>
    <joint name="${prefix}joint_2" type="revolute">
      <axis xyz="0.0 0.0 1.0"/>
      <child link="${prefix}link_2"/>
      <limit effort="311.954897896674" lower="-3.3161255787892263E0" upper="7.853981633974483E-1" velocity="${radians(225)}"/>
      <origin rpy="1.5707963267948963 0.0 -0.0" xyz="0.025 0.0 -0.4"/>
      <parent link="${prefix}link_1"/>
    </joint>
    <joint name="${prefix}joint_3" type="revolute">
      <axis xyz="0.0 0.0 1.0"/>
      <child link="${prefix}link_3"/>
      <limit effort="119.76245366275" lower="-2.0943951023931953E0" upper="2.722713633111154E0" velocity="${radians(330)}"/>
      <origin rpy="0.0 0.0 -1.5707963267948963" xyz="0.56 0.0 0.0"/>
      <parent link="${prefix}link_2"/>
    </joint>
    <joint name="${prefix}joint_4" type="revolute">
      <axis xyz="0.0 0.0 1.0"/>
      <child link="${prefix}link_4"/>
      <limit effort="46.081304845791" lower="-3.2288591161895095E0" upper="3.2288591161895095E0" velocity="${radians(360)}"/>
      <origin rpy="1.5707963267948963 0.0 -0.0" xyz="0.025 0.0 0.0"/>
      <parent link="${prefix}link_3"/>
    </joint>
    <joint name="${prefix}joint_5" type="revolute">
      <axis xyz="0.0 0.0 1.0"/>
      <child link="${prefix}link_5"/>
      <limit effort="41.6154671315968" lower="-2.0943951023931953E0" upper="2.0943951023931953E0" velocity="${radians(360)}"/>
      <origin rpy="-1.5707963267948963 0.0 -0.0" xyz="0.0 0.0 -0.515"/>
      <parent link="${prefix}link_4"/>
    </joint>
    <joint name="${prefix}joint_6" type="revolute">
      <axis xyz="0.0 0.0 1.0"/>
      <child link="${prefix}link_6"/>
      <limit effort="28.03794" lower="-6.1086523819801535E0" upper="6.1086523819801535E0" velocity="${radians(433)}"/>
      <origin rpy="1.5707963267948963 0.0 -0.0" xyz="0.0 0.0 0.0"/>
      <parent link="${prefix}link_5"/>
    </joint>
    <!-- ROS-Industrial 'base' frame - equivalent of 'KUKA ROBROOT'-->
    <link name="${prefix}base"/>
    <joint name="${prefix}base_link-base" type="fixed">
      <origin xyz="0 0 0" rpy="0 0 0"/>
      <parent link="${prefix}base_link"/>
      <child link="${prefix}base"/>
    </joint>
    <!-- ROS-Industrial 'flange' frame - attachment point for EEF models -->
    <link name="${prefix}flange"/>
    <joint name="${prefix}link6-flange" type="fixed">
      <child link="${prefix}flange"/>
      <origin rpy="0 ${pi/2} -0.0" xyz="0.0 0.0 -0.09"/>
      <parent link="${prefix}link_6"/>
    </joint>
    <!-- ROS-Industrial 'tool0' frame - all-zeros tool frame -->
    <link name="${prefix}tool0"/>
    <joint name="${prefix}link6-tool0" type="fixed">
      <child link="${prefix}tool0"/>
      <origin rpy="0 ${pi} -0.0" xyz="0.0 0.0 -0.09"/>
      <parent link="${prefix}link_6"/>
    </joint>
  </xacro:macro>
</robot>
