<?xml version="1.0"?>
<robot xmlns:xacro="http://wiki.ros.org/xacro">
  <xacro:include filename="$(find kuka_gazebo)/gazebo/kuka_gazebo.xacro"/>
  <xacro:include filename="$(find kuka_resources)/urdf/common_constants.xacro"/>
  <xacro:include filename="$(find kuka_resources)/urdf/common_materials.xacro"/>
  <xacro:include filename="$(find kuka_agilus_support)/urdf/kr_agilus_ros2_control.xacro"/>
  <xacro:include filename="$(find kuka_agilus_support)/urdf/kr_agilus_transmission.xacro"/>
  <xacro:macro name="kuka_kr6_r700_sixx_robot" params="client_ip client_port prefix mode roundtrip_time *origin">
    <!-- gazebo -->
    <xacro:kuka_gazebo controller_config_package="kuka_resources" controller_config_path="config/fake_hardware_config_6_axis.yaml" />
    <!-- ros2 control instance -->
    <xacro:kuka_agilus_ros2_control name="${prefix}kr6_r700_sixx" client_ip="${client_ip}" client_port="${client_port}" prefix="${prefix}" mode="${mode}" roundtrip_time="${roundtrip_time}"/>
    <link name="world"/>
    <link name="${prefix}base_link">
      <visual>
        <origin xyz="0 0 0" rpy="0 0 0"/>
        <geometry>
          <mesh filename="package://kuka_agilus_support/meshes/kr6_r700_sixx/visual/base_link.dae"/>
        </geometry>
        <xacro:material_kuka_pedestal/>
      </visual>
      <inertial>
        <inertia ixx="0.16209200415615" ixy="0.0" ixz="0.0" iyy="0.10881181598555635" iyz="0.0" izz="0.18461591505869543"/>
        <mass value="1.6916E1"/>
        <origin rpy="1.6165592773339865 -1.221289277333065 3.10031147437779" xyz="-0.03713348309292976 2.6602033577676952E-5 0.10863850792149446"/>
      </inertial>
      <collision>
        <origin xyz="0 0 0" rpy="0 0 0"/>
        <geometry>
          <mesh filename="package://kuka_agilus_support/meshes/kr6_r700_sixx/collision/base_link.stl"/>
        </geometry>
      </collision>
    </link>
    <link name="${prefix}link_1">
      <visual>
        <origin xyz="0 0 0" rpy="0 0 0"/>
        <geometry>
          <mesh filename="package://kuka_agilus_support/meshes/kr6_r700_sixx/visual/link_1.dae"/>
        </geometry>
        <xacro:material_kuka_orange/>
      </visual>
      <inertial>
        <inertia ixx="0.07406183855390855" ixy="0.0" ixz="0.0" iyy="0.0890478351825312" iyz="0.0" izz="0.11039570662759429"/>
        <mass value="8.4159999999999986E0"/>
        <origin rpy="1.304519343134156 -0.9428616016893947 -1.4226510948637578" xyz="0.006410408745247152 -0.01626805370722434 -0.10658893773764262"/>
      </inertial>
      <collision>
        <origin xyz="0 0 0" rpy="0 0 0"/>
        <geometry>
          <mesh filename="package://kuka_agilus_support/meshes/kr6_r700_sixx/collision/link_1.stl"/>
        </geometry>
      </collision>
    </link>
    <link name="${prefix}link_2">
      <visual>
        <origin xyz="0 0 0" rpy="0 0 0"/>
        <geometry>
          <mesh filename="package://kuka_agilus_support/meshes/kr6_r700_sixx/visual/link_2.dae"/>
        </geometry>
        <xacro:material_kuka_orange/>
      </visual>
      <inertial>
        <inertia ixx="0.27913939628518236" ixy="0.0" ixz="0.0" iyy="0.08120682412128737" iyz="0.0" izz="0.31885940962560827"/>
        <mass value="1.55659E1"/>
        <origin rpy="-1.3903732489969973 -1.5149954424356888 -0.1998085283039958" xyz="0.09688971405443952 -0.004085391785890956 -0.07157586711979391"/>
      </inertial>
      <collision>
        <origin xyz="0 0 0" rpy="0 0 0"/>
        <geometry>
          <mesh filename="package://kuka_agilus_support/meshes/kr6_r700_sixx/collision/link_2.stl"/>
        </geometry>
      </collision>
    </link>
    <link name="${prefix}link_3">
      <visual>
        <origin xyz="0 0 0" rpy="0 0 0"/>
        <geometry>
          <mesh filename="package://kuka_agilus_support/meshes/kr6_r700_sixx/visual/link_3.dae"/>
        </geometry>
        <xacro:material_kuka_orange/>
      </visual>
      <inertial>
        <inertia ixx="0.016743444555446362" ixy="0.0" ixz="0.0" iyy="0.025482537016456808" iyz="0.0" izz="0.02822390996140248"/>
        <mass value="5.303E0"/>
        <origin rpy="2.3581203240627353 -0.21894199177335477 -3.004285178078088" xyz="0.022228738449934005 -0.011136149349424855 -0.06927623986422779"/>
      </inertial>
      <collision>
        <origin xyz="0 0 0" rpy="0 0 0"/>
        <geometry>
          <mesh filename="package://kuka_agilus_support/meshes/kr6_r700_sixx/collision/link_3.stl"/>
        </geometry>
      </collision>
    </link>
    <link name="${prefix}link_4">
      <visual>
        <origin xyz="0 0 0" rpy="0 0 0"/>
        <geometry>
          <mesh filename="package://kuka_agilus_support/meshes/kr6_r700_sixx/visual/link_4.dae"/>
        </geometry>
        <xacro:material_kuka_orange/>
      </visual>
      <inertial>
        <inertia ixx="0.010531272787231831" ixy="0.0" ixz="0.0" iyy="0.03425565311920862" iyz="0.0" izz="0.037359032949440756"/>
        <mass value="4.6129999999999995E0"/>
        <origin rpy="-2.0540104905408416 -1.5266176566842766 2.01813464445371" xyz="1.0969000650336042E-4 0.010267591588987646 -0.09163862995881207"/>
      </inertial>
      <collision>
        <origin xyz="0 0 0" rpy="0 0 0"/>
        <geometry>
          <mesh filename="package://kuka_agilus_support/meshes/kr6_r700_sixx/collision/link_4.stl"/>
        </geometry>
      </collision>
    </link>
    <link name="${prefix}link_5">
      <visual>
        <origin xyz="0 0 0" rpy="0 0 0"/>
        <geometry>
          <mesh filename="package://kuka_agilus_support/meshes/kr6_r700_sixx/visual/link_5.dae"/>
        </geometry>
        <xacro:material_kuka_orange/>
      </visual>
      <inertial>
        <inertia ixx="0.0017317756133102904" ixy="0.0" ixz="0.0" iyy="0.002219500805440681" iyz="0.0" izz="0.002467090055442975"/>
        <mass value="1.6128E0"/>
        <origin rpy="1.567898714902774 -0.8611716764868309 -3.100280255900493" xyz="0.009320696924603175 7.83482142857143E-4 -0.026462549603174602"/>
      </inertial>
      <collision>
        <origin xyz="0 0 0" rpy="0 0 0"/>
        <geometry>
          <mesh filename="package://kuka_agilus_support/meshes/kr6_r700_sixx/collision/link_5.stl"/>
        </geometry>
      </collision>
    </link>
    <link name="${prefix}link_6">
      <visual>
        <origin xyz="0 0 0" rpy="0 0 0"/>
        <geometry>
          <mesh filename="package://kuka_agilus_support/meshes/kr6_r700_sixx/visual/link_6.dae"/>
        </geometry>
        <xacro:material_kuka_pedestal/>
      </visual>
      <inertial>
        <inertia ixx="1.83698267603013E-4" ixy="0.0" ixz="0.0" iyy="1.8213621766783165E-4" iyz="0.0" izz="2.9589000000000004E-4"/>
        <mass value="7.34E-1"/>
        <origin rpy="0.0 -0.0 1.223427188696551" xyz="0.0 0.0 -0.011764604904632152"/>
      </inertial>
      <collision>
        <origin xyz="0 0 0" rpy="0 0 0"/>
        <geometry>
          <mesh filename="package://kuka_agilus_support/meshes/kr6_r700_sixx/collision/link_6.stl"/>
        </geometry>
      </collision>
    </link>
    <!-- Following REP199, this frame shall be use to attach EEF or other equipment -->
    <link name="${prefix}flange"/>
    <joint name="${prefix}world-base_link" type="fixed">
      <parent link="world"/>
      <child link="${prefix}base_link"/>
      <xacro:insert_block name="origin"/>
    </joint>
    <joint name="${prefix}joint_1" type="revolute">
      <origin xyz="0 0 0.4" rpy="0 0 0"/>
      <parent link="${prefix}base_link"/>
      <child link="${prefix}link_1"/>
      <axis xyz="0 0 -1"/>
      <limit lower="${radians(-170)}" upper="${radians(170)}" effort="0" velocity="${radians(360)}"/>
    </joint>
    <joint name="${prefix}joint_2" type="revolute">
      <origin xyz="0.025 0 0" rpy="0 0 0"/>
      <parent link="${prefix}link_1"/>
      <child link="${prefix}link_2"/>
      <axis xyz="0 1 0"/>
      <limit lower="${radians(-190)}" upper="${radians(45)}" effort="0" velocity="${radians(300)}"/>
    </joint>
    <joint name="${prefix}joint_3" type="revolute">
      <origin xyz="0.315 0 0" rpy="0 0 0"/>
      <parent link="${prefix}link_2"/>
      <child link="${prefix}link_3"/>
      <axis xyz="0 1 0"/>
      <limit lower="${radians(-120)}" upper="${radians(156)}" effort="0" velocity="${radians(360)}"/>
    </joint>
    <joint name="${prefix}joint_4" type="revolute">
      <origin xyz="0 0 0.035" rpy="0 0 0"/>
      <parent link="${prefix}link_3"/>
      <child link="${prefix}link_4"/>
      <axis xyz="-1 0 0"/>
      <limit lower="${radians(-185)}" upper="${radians(185)}" effort="0" velocity="${radians(381)}"/>
    </joint>
    <joint name="${prefix}joint_5" type="revolute">
      <origin xyz="0.365 0 0" rpy="0 0 0"/>
      <parent link="${prefix}link_4"/>
      <child link="${prefix}link_5"/>
      <axis xyz="0 1 0"/>
      <limit lower="${radians(-120)}" upper="${radians(120)}" effort="0" velocity="${radians(388)}"/>
    </joint>
    <joint name="${prefix}joint_6" type="revolute">
      <origin xyz="0.080 0 0" rpy="0 0 0"/>
      <parent link="${prefix}link_5"/>
      <child link="${prefix}link_6"/>
      <axis xyz="-1 0 0"/>
      <limit lower="${radians(-350)}" upper="${radians(350)}" effort="0" velocity="${radians(615)}"/>
    </joint>
    <joint name="${prefix}joint_6-flange" type="fixed">
      <parent link="${prefix}link_6"/>
      <child link="${prefix}flange"/>
      <origin xyz="0 0 0" rpy="0 0 0"/>
    </joint>
    <!-- ROS base_link to KUKA $ROBROOT coordinate system transform -->
    <link name="${prefix}base"/>
    <joint name="${prefix}base_link-base" type="fixed">
      <origin xyz="0 0 0" rpy="0 0 0"/>
      <parent link="${prefix}base_link"/>
      <child link="${prefix}base"/>
    </joint>
    <!-- This frame corresponds to the $TOOL coordinate system in KUKA KRC controllers -->
    <link name="${prefix}tool0"/>
    <joint name="${prefix}flange-tool0" type="fixed">
      <parent link="${prefix}flange"/>
      <child link="${prefix}tool0"/>
      <origin xyz="0 0 0" rpy="0 ${radians(90)} 0"/>
    </joint>
  </xacro:macro>
</robot>
