<?xml version="1.0" encoding="UTF-8"?>
<robot xmlns:xacro="http://www.ros.org/wiki/xacro" name="LBR3R760iisy">
  <xacro:macro name="iisy_robot" params="prefix client_ip controller_ip control_mode consequent_lost_packets lost_packets_in_timeframe timeframe_ms">
    <xacro:include filename="$(find kuka_iisy_support)/urdf/iisy_ros2_control.xacro" />

    <!-- ros2 control instance -->
    <xacro:iisy_ros2_control 
    prefix="${prefix}"
    client_ip="${client_ip}"
    controller_ip="${controller_ip}"
    control_mode="${control_mode}"
    consequent_lost_packets="${consequent_lost_packets}"
    lost_packets_in_timeframe="${lost_packets_in_timeframe}"
    timeframe_ms="${timeframe_ms}" />

    <!-- links - main serial chain -->
    <link name="${prefix}base_link" />
    <link name="${prefix}LBR3R760_iisy_fixedbase">
      <collision>
        <geometry>
          <mesh filename="package://kuka_iisy_support/meshes/LBR3R760/collision/base_link.stl" />
        </geometry>
        <origin rpy="-0.0 0.0 -0.0" xyz="0.0 0.0 0.0" />
      </collision>
      <inertial>
        <inertia ixx="5.0E-4" ixy="0.0" ixz="0.0" iyy="5.0E-4" iyz="0.0" izz="5.0E-4" />
        <mass value="3.6832E0" />
        <origin rpy="-0.0 0.0 -0.0" xyz="0.0 0.0 0.0" />
      </inertial>
      <visual>
        <geometry>
          <mesh filename="package://kuka_iisy_support/meshes/LBR3R760/visual/base_link.stl" />
        </geometry>
        <origin rpy="-0.0 0.0 -0.0" xyz="0.0 0.0 0.0" />
      </visual>
    </link>
    <link name="${prefix}LBR3R760_iisy_axis1">
      <collision>
        <geometry>
          <mesh filename="package://kuka_iisy_support/meshes/LBR3R760/collision/link_1.stl" />
        </geometry>
        <origin rpy="-0.0 0.0 -0.0" xyz="0.0 0.0 0.0" />
      </collision>
      <inertial>
        <inertia ixx="0.00864540353780418" ixy="0.0" ixz="0.0" iyy="0.00573103463618732" iyz="0.0" izz="0.00974792600424334" />
        <mass value="3.2492E0" />
        <origin rpy="-0.0 0.0 -0.0" xyz="0.0 0.0 0.0" />
      </inertial>
      <visual>
        <geometry>
          <mesh filename="package://kuka_iisy_support/meshes/LBR3R760/visual/link_1.stl" />
        </geometry>
        <origin rpy="-0.0 0.0 -0.0" xyz="0.0 0.0 0.0" />
      </visual>
    </link>
    <link name="${prefix}LBR3R760_iisy_axis2">
      <collision>
        <geometry>
          <mesh filename="package://kuka_iisy_support/meshes/LBR3R760/collision/link_2.stl" />
        </geometry>
        <origin rpy="-0.0 0.0 -0.0" xyz="0.0 0.0 0.0" />
      </collision>
      <inertial>
        <inertia ixx="0.0521692170047944" ixy="0.0" ixz="0.0" iyy="0.0042331111850977" iyz="0.0" izz="0.0534425693052013" />
        <mass value="3.212E0" />
        <origin rpy="-0.0 0.0 -0.0" xyz="0.0 0.0 0.0" />
      </inertial>
      <visual>
        <geometry>
          <mesh filename="package://kuka_iisy_support/meshes/LBR3R760/visual/link_2.stl" />
        </geometry>
        <origin rpy="-0.0 0.0 -0.0" xyz="0.0 0.0 0.0" />
      </visual>
    </link>
    <link name="${prefix}LBR3R760_iisy_axis3">
      <collision>
        <geometry>
          <mesh filename="package://kuka_iisy_support/meshes/LBR3R760/collision/link_3.stl" />
        </geometry>
        <origin rpy="-0.0 0.0 -0.0" xyz="0.0 0.0 0.0" />
      </collision>
      <inertial>
        <inertia ixx="0.0113804888378926" ixy="0.0" ixz="0.0" iyy="0.00566536942404497" iyz="0.0" izz="0.0133950588482047" />
        <mass value="3.471E0" />
        <origin rpy="-0.0 0.0 -0.0" xyz="0.0 0.0 0.0" />
      </inertial>
      <visual>
        <geometry>
          <mesh filename="package://kuka_iisy_support/meshes/LBR3R760/visual/link_3.stl" />
        </geometry>
        <origin rpy="-0.0 0.0 -0.0" xyz="0.0 0.0 0.0" />
      </visual>
    </link>
    <link name="${prefix}LBR3R760_iisy_axis4">
      <collision>
        <geometry>
          <mesh filename="package://kuka_iisy_support/meshes/LBR3R760/collision/link_4.stl" />
        </geometry>
        <origin rpy="-0.0 0.0 -0.0" xyz="0.0 0.0 0.0" />
      </collision>
      <inertial>
        <inertia ixx="0.00244684891934666" ixy="0.0" ixz="0.0" iyy="0.00929300990970133" iyz="0.0" izz="0.00957902612033654" />
        <mass value="2.0138E0" />
        <origin rpy="-0.0 0.0 -0.0" xyz="0.0 0.0 0.0" />
      </inertial>
      <visual>
        <geometry>
          <mesh filename="package://kuka_iisy_support/meshes/LBR3R760/visual/link_4.stl" />
        </geometry>
        <origin rpy="-0.0 0.0 -0.0" xyz="0.0 0.0 0.0" />
      </visual>
    </link>
    <link name="${prefix}LBR3R760_iisy_axis5">
      <collision>
        <geometry>
          <mesh filename="package://kuka_iisy_support/meshes/LBR3R760/collision/link_5.stl" />
        </geometry>
        <origin rpy="-0.0 0.0 -0.0" xyz="0.0 0.0 0.0" />
      </collision>
      <inertial>
        <inertia ixx="0.00236252846105637" ixy="0.0" ixz="0.0" iyy="0.00141854396142661" iyz="0.0" izz="0.0025813096143987" />
        <mass value="1.4418E0" />
        <origin rpy="-0.0 0.0 -0.0" xyz="0.0 0.0 0.0" />
      </inertial>
      <visual>
        <geometry>
          <mesh filename="package://kuka_iisy_support/meshes/LBR3R760/visual/link_5.stl" />
        </geometry>
        <origin rpy="-0.0 0.0 -0.0" xyz="0.0 0.0 0.0" />
      </visual>
    </link>
    <link name="${prefix}LBR3R760_iisy_axis6">
      <collision>
        <geometry>
          <mesh filename="package://kuka_iisy_support/meshes/LBR3R760/collision/link_6.stl" />
        </geometry>
        <origin rpy="-0.0 0.0 -0.0" xyz="0.0 0.0 0.0" />
      </collision>
      <inertial>
        <inertia ixx="0.0014673917002994" ixy="0.0" ixz="0.0" iyy="0.00112131520678352" iyz="0.0" izz="0.00158160486913488" />
        <mass value="8.43E-1" />
        <origin rpy="-0.0 0.0 -0.0" xyz="0.0 0.0 0.0" />
      </inertial>
      <visual>
        <geometry>
          <mesh filename="package://kuka_iisy_support/meshes/LBR3R760/visual/link_6.stl" />
        </geometry>
        <origin rpy="-0.0 0.0 -0.0" xyz="0.0 0.0 0.0" />
      </visual>
    </link>

    <!-- fix base to environment -->
    <joint name="${prefix}base_joint" type="fixed">
      <parent link="${prefix}base_link" />
      <child link="${prefix}LBR3R760_iisy_fixedbase" />
    </joint>

    <!-- joints - main serial chain -->
    <joint name="${prefix}joint_a1" type="revolute">
      <axis xyz="0.0 0.0 -1.0" />
      <child link="${prefix}LBR3R760_iisy_axis1" />
      <limit effort="5.0E0" lower="-3.2288591E0" upper="3.2288591E0" velocity="2.0E0" />
      <origin rpy="-0.0 0.0 -0.0" xyz="0.0 0.0 0.1264" />
      <parent link="${prefix}LBR3R760_iisy_fixedbase" />
    </joint>
    <joint name="${prefix}joint_a2" type="revolute">
      <axis xyz="0.0 0.0 1.0" />
      <child link="${prefix}LBR3R760_iisy_axis2" />
      <limit effort="5.0E0" lower="-4.0142572796E0" upper="8.726646E-1" velocity="2.0E0" />
      <origin rpy="-1.5707963267948963 0.0 -0.0" xyz="0.0 0.0 0.0886" />
      <parent link="${prefix}LBR3R760_iisy_axis1" />
    </joint>
    <joint name="${prefix}joint_a3" type="revolute">
      <axis xyz="0.0 0.0 1.0" />
      <child link="${prefix}LBR3R760_iisy_axis3" />
      <limit effort="5.0E0" lower="-2.61799387799E0" upper="2.61799387799E0" velocity="2.0E0" />
      <origin rpy="0.0 0.0 -1.5707963267948963" xyz="0.3 0.0 0.0" />
      <parent link="${prefix}LBR3R760_iisy_axis2" />
    </joint>
    <joint name="${prefix}joint_a4" type="revolute">
      <axis xyz="0.0 0.0 1.0" />
      <child link="${prefix}LBR3R760_iisy_axis4" />
      <limit effort="5.0E0" lower="-3.05432619E0" upper="3.05432619E0" velocity="2.0E0" />
      <origin rpy="1.5707963267948963 0.0 -0.0" xyz="0.0 0.0 0.0" />
      <parent link="${prefix}LBR3R760_iisy_axis3" />
    </joint>
    <joint name="${prefix}joint_a5" type="revolute">
      <axis xyz="0.0 0.0 1.0" />
      <child link="${prefix}LBR3R760_iisy_axis5" />
      <limit effort="5.0E0" lower="-1.919862177E0" upper="1.919862177E0" velocity="2.0E0" />
      <origin rpy="-1.5707963267948963 0.0 -0.0" xyz="0.0 0.0 -0.3" />
      <parent link="${prefix}LBR3R760_iisy_axis4" />
    </joint>
    <joint name="${prefix}joint_a6" type="revolute">
      <axis xyz="0.0 0.0 1.0" />
      <child link="${prefix}LBR3R760_iisy_axis6" />
      <limit effort="5.0E0" lower="-3.839724354E0" upper="3.839724354E0" velocity="2.0E0" />
      <origin rpy="1.5707963267948963 0.0 -0.0" xyz="0.0 0.0 0.0" />
      <parent link="${prefix}LBR3R760_iisy_axis5" />
    </joint>

    <!-- ROS-Industrial 'flange' frame - attachment point for EEF models -->
    <link name="${prefix}LBR3R760_iisy_flange" />
    <joint name="${prefix}link6-flange" type="fixed">
      <child link="${prefix}LBR3R760_iisy_flange" />
      <origin rpy="0 3.14159265359  -0.0" xyz="0.0 0.0 -0.1605" />
      <parent link="${prefix}LBR3R760_iisy_axis6" />
    </joint>

    <!-- ROS-Industrial 'tool0' frame - all-zeros tool frame -->
    <link name="${prefix}LBR3R760_iisy_tool0" />
    <joint name="${prefix}flange-tool0" type="fixed">
      <child link="${prefix}LBR3R760_iisy_tool0" />
      <origin rpy="0.0 0.0 0.0" xyz="0.0 0.0 0.0" />
      <parent link="${prefix}LBR3R760_iisy_flange" />
    </joint>
    <xacro:include filename="$(find kuka_iisy_support)/urdf/iisy_transmission.xacro" />
  </xacro:macro>
</robot>
