<?xml version="1.0" encoding="UTF-8"?>
<robot xmlns:xacro="http://www.ros.org/wiki/xacro" name="lbr_iisy15_r930">
  <!-- include helper xacros -->
  <xacro:include filename="$(find kuka_lbr_iisy_support)/urdf/lbr_iisy_ros2_control.xacro" />
  <xacro:include filename="$(find kuka_resources)/urdf/common_materials.xacro"/>
  <xacro:include filename="$(find kuka_lbr_iisy_support)/urdf/lbr_iisy_transmission.xacro" />

  <xacro:macro name="kuka_lbr_iisy15_r930_robot" params="prefix use_fake_hardware:=false">
    <!-- ros2 control instance -->
    <xacro:kuka_lbr_iisy_ros2_control
    name="lbr_iisy15_r930"
    prefix="${prefix}"
    use_fake_hardware="${use_fake_hardware}" />

    <!-- links - main serial chain -->
    <!-- links - root element cannot have inertia, therefore a dummy base_link is needed -->
    <link name="${prefix}base_link"/>
    <link name="${prefix}base_link_inertia">
      <collision>
        <geometry>
          <mesh filename="package://kuka_lbr_iisy_support/meshes/lbr_iisy15_r930/collision/base_link.stl" />
        </geometry>
        <origin rpy="-0.0 0.0 -0.0" xyz="0.0 0.0 0.0" />
      </collision>
      <inertial>
        <inertia ixx="0.0489108" ixy="0.0" ixz="0.0" iyy="0.03837059" iyz="0.0" izz="0.05221216"/>
        <mass value="8.666E0"/>
        <origin rpy="-0.0 0.0 -0.0" xyz="0.0 0.0 0.0" />
      </inertial>
      <visual>
        <geometry>
          <mesh filename="package://kuka_lbr_iisy_support/meshes/lbr_iisy15_r930/visual/base_link.stl" />
        </geometry>
        <origin rpy="-0.0 0.0 -0.0" xyz="0.0 0.0 0.0" />
        <xacro:material_kuka_ral_pure_white />
      </visual>
    </link>
    <link name="${prefix}link_1">
      <collision>
        <geometry>
          <mesh filename="package://kuka_lbr_iisy_support/meshes/lbr_iisy15_r930/collision/link_1.stl" />
        </geometry>
        <origin rpy="-0.0 0.0 -0.0" xyz="0.0 0.0 0.0" />
      </collision>
      <inertial>
        <inertia ixx="0.03061686" ixy="0.0" ixz="0.0" iyy="0.25204709" iyz="0.0" izz="0.25865036"/>
        <mass value="9.62E0"/>
        <origin rpy="-0.0 0.0 -0.0" xyz="0.0 0.0 0.0" />
      </inertial>
      <visual>
        <geometry>
          <mesh filename="package://kuka_lbr_iisy_support/meshes/lbr_iisy15_r930/visual/link_1.stl" />
        </geometry>
        <origin rpy="-0.0 0.0 -0.0" xyz="0.0 0.0 0.0" />
        <xacro:material_kuka_ral_pure_white />
      </visual>
    </link>
    <link name="${prefix}link_2">
      <collision>
        <geometry>
          <mesh filename="package://kuka_lbr_iisy_support/meshes/lbr_iisy15_r930/collision/link_2.stl" />
        </geometry>
        <origin rpy="-0.0 0.0 -0.0" xyz="0.0 0.0 0.0" />
      </collision>
      <inertial>
      <inertia ixx="0.0181557" ixy="0.0" ixz="0.0" iyy="0.03469164" iyz="0.0" izz="0.03777695"/>
      <mass value="8.079E0"/>
        <origin rpy="-0.0 0.0 -0.0" xyz="0.0 0.0 0.0" />
      </inertial>
      <visual>
        <geometry>
          <mesh filename="package://kuka_lbr_iisy_support/meshes/lbr_iisy15_r930/visual/link_2.stl" />
        </geometry>
        <origin rpy="-0.0 0.0 -0.0" xyz="0.0 0.0 0.0" />
        <xacro:material_kuka_ral_pure_white />
      </visual>
    </link>
    <link name="${prefix}link_3">
      <collision>
        <geometry>
          <mesh filename="package://kuka_lbr_iisy_support/meshes/lbr_iisy15_r930/collision/link_3.stl" />
        </geometry>
        <origin rpy="-0.0 0.0 -0.0" xyz="0.0 0.0 0.0" />
      </collision>
      <inertial>
        <inertia ixx="0.02087716" ixy="0.0" ixz="0.0" iyy="0.05261357" iyz="0.0" izz="0.05874859"/>
        <mass value="7.6604E0"/>
        <origin rpy="-0.0 0.0 -0.0" xyz="0.0 0.0 0.0" />
      </inertial>
      <visual>
        <geometry>
          <mesh filename="package://kuka_lbr_iisy_support/meshes/lbr_iisy15_r930/visual/link_3.stl" />
        </geometry>
        <origin rpy="-0.0 0.0 -0.0" xyz="0.0 0.0 0.0" />
        <xacro:material_kuka_ral_pure_white />
      </visual>
    </link>
    <link name="${prefix}link_4">
      <collision>
        <geometry>
          <mesh filename="package://kuka_lbr_iisy_support/meshes/lbr_iisy15_r930/collision/link_4.stl" />
        </geometry>
        <origin rpy="-0.0 0.0 -0.0" xyz="0.0 0.0 0.0" />
      </collision>
      <inertial>
        <inertia ixx="0.00667163" ixy="0.0" ixz="0.0" iyy="0.00503488" iyz="0.0" izz="0.00840869"/>
        <mass value="5.7014E0"/>
        <origin rpy="-0.0 0.0 -0.0" xyz="0.0 0.0 0.0" />
      </inertial>
      <visual>
        <geometry>
          <mesh filename="package://kuka_lbr_iisy_support/meshes/lbr_iisy15_r930/visual/link_4.stl" />
        </geometry>
        <origin rpy="-0.0 0.0 -0.0" xyz="0.0 0.0 0.0" />
        <xacro:material_kuka_ral_pure_white />
      </visual>
    </link>
    <link name="${prefix}link_5">
      <collision>
        <geometry>
          <mesh filename="package://kuka_lbr_iisy_support/meshes/lbr_iisy15_r930/collision/link_5.stl" />
        </geometry>
        <origin rpy="-0.0 0.0 -0.0" xyz="0.0 0.0 0.0" />
      </collision>
      <inertial>
        <inertia ixx="0.00390274" ixy="0.0" ixz="0.0" iyy="0.00286931" iyz="0.0" izz="0.00403512"/>
        <mass value="2.381E0"/>
        <origin rpy="-0.0 0.0 -0.0" xyz="0.0 0.0 0.0" />
      </inertial>
      <visual>
        <geometry>
          <mesh filename="package://kuka_lbr_iisy_support/meshes/lbr_iisy15_r930/visual/link_5.stl" />
        </geometry>
        <origin rpy="-0.0 0.0 -0.0" xyz="0.0 0.0 0.0" />
        <xacro:material_kuka_ral_pure_white />
      </visual>
    </link>
    <link name="${prefix}link_6">
      <collision>
        <geometry>
          <mesh filename="package://kuka_lbr_iisy_support/meshes/lbr_iisy15_r930/collision/link_6.stl" />
        </geometry>
        <origin rpy="-0.0 0.0 -0.0" xyz="0.0 0.0 0.0" />
      </collision>
      <inertial>
        <inertia ixx="0.00390274" ixy="0.0" ixz="0.0" iyy="0.00286931" iyz="0.0" izz="0.00403512"/>
        <mass value="1.509E0"/>
        <origin rpy="-0.0 0.0 -0.0" xyz="0.0 0.0 0.0" />
      </inertial>
      <visual>
        <geometry>
          <mesh filename="package://kuka_lbr_iisy_support/meshes/lbr_iisy15_r930/visual/link_6.stl" />
        </geometry>
        <origin rpy="-0.0 0.0 -0.0" xyz="0.0 0.0 0.0" />
        <xacro:material_kuka_ral_pure_white />
      </visual>
    </link>

    <!-- joints - main serial chain -->
    <joint name="${prefix}base_link-base_link_inertia" type="fixed">
      <parent link="${prefix}base_link" />
      <child link="${prefix}base_link_inertia" />
      <origin xyz="0 0 0" rpy="0 0 0" />
    </joint>
    <joint name="${prefix}joint_1" type="revolute">
      <axis xyz="0.0 0.0 1.0" />
      <child link="${prefix}link_1" />
      <limit effort="398.011277" lower="-3.2288591161895095E0" upper="3.2288591161895095E0" velocity="3.490656"/>
      <origin rpy="${-pi} 0.0 -0.0" xyz="0.0 0.0 0.0"/>
      <parent link="${prefix}base_link_inertia" />
    </joint>
    <joint name="${prefix}joint_2" type="revolute">
      <axis xyz="0.0 0.0 1.0" />
      <child link="${prefix}link_2" />
      <limit effort="286.529873" lower="-4.014257279586958E0" upper="8.726646259971648E-1" velocity="3.490656"/>
      <origin rpy="${pi/2.0} 0.0 -0.0" xyz="0.0 0.0 -0.3"/>
      <parent link="${prefix}link_1" />
    </joint>
    <joint name="${prefix}joint_3" type="revolute">
      <axis xyz="0.0 0.0 1.0" />
      <child link="${prefix}link_3" />
      <limit effort="137.666701" lower="-2.6179938779914944E0" upper="2.6179938779914944E0" velocity="3.490656"/>
      <origin rpy="0.0 0.0 ${-pi/2.0}" xyz="0.385 0.0 0.0"/>
      <parent link="${prefix}link_2" />
    </joint>
    <joint name="${prefix}joint_4" type="revolute">
      <axis xyz="0.0 0.0 1.0" />
      <child link="${prefix}link_4" />
      <limit effort="63.574238" lower="-3.141592653589793E0" upper="3.141592653589793E0" velocity="4.014255"/>
      <origin rpy="${pi/2.0} 0.0 -0.0" xyz="0.0 0.0 0.0"/>
      <parent link="${prefix}link_3" />
    </joint>
    <joint name="${prefix}joint_5" type="revolute">
      <axis xyz="0.0 0.0 1.0" />
      <child link="${prefix}link_5" />
      <limit effort="58.580298" lower="-1.9198621771937625E0" upper="1.9198621771937625E0" velocity="4.537856"/>
      <origin rpy="${-pi/2.0} 0.0 -0.0" xyz="0.0 0.0 -0.367"/>
      <parent link="${prefix}link_4" />
    </joint>
    <joint name="${prefix}joint_6" type="revolute">
      <axis xyz="0.0 0.0 1.0" />
      <child link="${prefix}link_6" />
      <limit effort="15.927568" lower="-3.839724354387525E0" upper="3.839724354387525E0" velocity="7.504909"/>
      <origin rpy="${pi/2.0} 0.0 -0.0" xyz="0.0 0.0 0.0"/>
      <parent link="${prefix}link_5" />
    </joint>

    <!-- ROS-Industrial 'base' frame - equivalent of 'KUKA ROBROOT'-->
    <link name="${prefix}base" />
    <joint name="${prefix}base_link-base" type="fixed">
      <origin xyz="0 0 0" rpy="0 0 0"/>
      <parent link="${prefix}base_link"/>
      <child link="${prefix}base"/>
    </joint>

    <!-- ROS-Industrial 'flange' frame - attachment point for EEF models -->
    <link name="${prefix}flange" />
    <joint name="${prefix}link6-flange" type="fixed">
      <child link="${prefix}flange" />
      <origin rpy="0 ${pi/2} -0.0" xyz="0.0 0.0 -0.178" />
      <parent link="${prefix}link_6" />
    </joint>

    <!-- ROS-Industrial 'tool0' frame - all-zeros tool frame -->
    <link name="${prefix}tool0" />
    <joint name="${prefix}link6-tool0" type="fixed">
      <child link="${prefix}tool0" />
      <origin rpy="0 ${pi} -0.0" xyz="0.0 0.0 -0.178" />
      <parent link="${prefix}link_6" />
    </joint>
  </xacro:macro>
</robot>
