<?xml version="1.0" encoding="UTF-8"?>
<robot xmlns:xacro="http://www.ros.org/wiki/xacro" name="lbr_iisy3_r760">
  <!-- include helper xacros -->
  <xacro:include filename="$(find kuka_lbr_iisy_support)/urdf/lbr_iisy_ros2_control.xacro" />
  <xacro:include filename="$(find kuka_resources)/urdf/common_materials.xacro"/>
  <xacro:include filename="$(find kuka_lbr_iisy_support)/urdf/lbr_iisy_transmission.xacro" />

  <xacro:macro name="kuka_lbr_iisy3_r760_robot" params="prefix use_fake_hardware:=false">
    <!-- ros2 control instance -->
    <xacro:kuka_lbr_iisy_ros2_control
    name="lbr_iisy3_r760"
    prefix="${prefix}"
    use_fake_hardware="${use_fake_hardware}" />

    <!-- links - main serial chain -->
    <!-- links - root element cannot have inertia, therefore a dummy base_link is needed -->
    <link name="${prefix}base_link"/>
    <link name="${prefix}base_link_inertia">
      <collision>
        <geometry>
          <mesh filename="package://kuka_lbr_iisy_support/meshes/lbr_iisy3_r760/collision/base_link.stl" />
        </geometry>
        <origin rpy="-0.0 0.0 -0.0" xyz="0.0 0.0 0.0" />
      </collision>
      <inertial>
        <inertia ixx="0.00865396" ixy="0.0" ixz="0.0" iyy="0.0057294" iyz="0.0" izz="0.00975485"/>
        <mass value="3.6896E0"/>
        <origin rpy="-0.0 0.0 -0.0" xyz="0.0 0.0 0.0" />
      </inertial>
      <visual>
        <geometry>
          <mesh filename="package://kuka_lbr_iisy_support/meshes/lbr_iisy3_r760/visual/base_link.stl" />
        </geometry>
        <origin rpy="-0.0 0.0 -0.0" xyz="0.0 0.0 0.0" />
        <xacro:material_kuka_ral_pure_white />
      </visual>
    </link>
    <link name="${prefix}link_1">
      <collision>
        <geometry>
          <mesh filename="package://kuka_lbr_iisy_support/meshes/lbr_iisy3_r760/collision/link_1.stl" />
        </geometry>
        <origin rpy="-0.0 0.0 -0.0" xyz="0.0 0.0 0.0" />
      </collision>
      <inertial>
        <inertia ixx="0.05207611" ixy="0.0" ixz="0.0" iyy="0.00423" iyz="0.0" izz="0.05335256"/>
        <mass value="3.2536E0"/>
        <origin rpy="-0.0 0.0 -0.0" xyz="0.0 0.0 0.0" />
      </inertial>
      <visual>
        <geometry>
          <mesh filename="package://kuka_lbr_iisy_support/meshes/lbr_iisy3_r760/visual/link_1.stl" />
        </geometry>
        <origin rpy="-0.0 0.0 -0.0" xyz="0.0 0.0 0.0" />
        <xacro:material_kuka_ral_pure_white />
      </visual>
    </link>
    <link name="${prefix}link_2">
      <collision>
        <geometry>
          <mesh filename="package://kuka_lbr_iisy_support/meshes/lbr_iisy3_r760/collision/link_2.stl" />
        </geometry>
        <origin rpy="-0.0 0.0 -0.0" xyz="0.0 0.0 0.0" />
      </collision>
      <inertial>
        <inertia ixx="0.01136164" ixy="0.0" ixz="0.0" iyy="0.0056706" iyz="0.0" izz="0.01338145"/>
        <mass value="3.208E0"/>
        <origin rpy="-0.0 0.0 -0.0" xyz="0.0 0.0 0.0" />
      </inertial>
      <visual>
        <geometry>
          <mesh filename="package://kuka_lbr_iisy_support/meshes/lbr_iisy3_r760/visual/link_2.stl" />
        </geometry>
        <origin rpy="-0.0 0.0 -0.0" xyz="0.0 0.0 0.0" />
        <xacro:material_kuka_ral_pure_white />
      </visual>
    </link>
    <link name="${prefix}link_3">
      <collision>
        <geometry>
          <mesh filename="package://kuka_lbr_iisy_support/meshes/lbr_iisy3_r760/collision/link_3.stl" />
        </geometry>
        <origin rpy="-0.0 0.0 -0.0" xyz="0.0 0.0 0.0" />
      </collision>
      <inertial>
        <inertia ixx="0.00244685" ixy="0.0" ixz="0.0" iyy="0.00929301" iyz="0.0" izz="0.00957903"/>
        <mass value="3.4737E0"/>
        <origin rpy="-0.0 0.0 -0.0" xyz="0.0 0.0 0.0" />
      </inertial>
      <visual>
        <geometry>
          <mesh filename="package://kuka_lbr_iisy_support/meshes/lbr_iisy3_r760/visual/link_3.stl" />
        </geometry>
        <origin rpy="-0.0 0.0 -0.0" xyz="0.0 0.0 0.0" />
        <xacro:material_kuka_ral_pure_white />
      </visual>
    </link>
    <link name="${prefix}link_4">
      <collision>
        <geometry>
          <mesh filename="package://kuka_lbr_iisy_support/meshes/lbr_iisy3_r760/collision/link_4.stl" />
        </geometry>
        <origin rpy="-0.0 0.0 -0.0" xyz="0.0 0.0 0.0" />
      </collision>
      <inertial>
        <inertia ixx="0.00235422" ixy="0.0" ixz="0.0" iyy="0.00141662" iyz="0.0" izz="0.00257108"/>
        <mass value="2.0138E0"/>
        <origin rpy="-0.0 0.0 -0.0" xyz="0.0 0.0 0.0" />
      </inertial>
      <visual>
        <geometry>
          <mesh filename="package://kuka_lbr_iisy_support/meshes/lbr_iisy3_r760/visual/link_4.stl" />
        </geometry>
        <origin rpy="-0.0 0.0 -0.0" xyz="0.0 0.0 0.0" />
        <xacro:material_kuka_ral_pure_white />
      </visual>
    </link>
    <link name="${prefix}link_5">
      <collision>
        <geometry>
          <mesh filename="package://kuka_lbr_iisy_support/meshes/lbr_iisy3_r760/collision/link_5.stl" />
        </geometry>
        <origin rpy="-0.0 0.0 -0.0" xyz="0.0 0.0 0.0" />
      </collision>
      <inertial>
        <inertia ixx="0.00146739" ixy="0.0" ixz="0.0" iyy="0.00112132" iyz="0.0" izz="0.0015816"/>
        <mass value="1.4344E0"/>
        <origin rpy="-0.0 0.0 -0.0" xyz="0.0 0.0 0.0" />
      </inertial>
      <visual>
        <geometry>
          <mesh filename="package://kuka_lbr_iisy_support/meshes/lbr_iisy3_r760/visual/link_5.stl" />
        </geometry>
        <origin rpy="-0.0 0.0 -0.0" xyz="0.0 0.0 0.0" />
        <xacro:material_kuka_ral_pure_white />
      </visual>
    </link>
    <link name="${prefix}link_6">
      <collision>
        <geometry>
          <mesh filename="package://kuka_lbr_iisy_support/meshes/lbr_iisy3_r760/collision/link_6.stl" />
        </geometry>
        <origin rpy="-0.0 0.0 -0.0" xyz="0.0 0.0 0.0" />
      </collision>
      <inertial>
        <inertia ixx="0.00146739" ixy="0.0" ixz="0.0" iyy="0.00112132" iyz="0.0" izz="0.0015816"/>
        <mass value="8.43E-1"/>
        <origin rpy="-0.0 0.0 -0.0" xyz="0.0 0.0 0.0" />
      </inertial>
      <visual>
        <geometry>
          <mesh filename="package://kuka_lbr_iisy_support/meshes/lbr_iisy3_r760/visual/link_6.stl" />
        </geometry>
        <origin rpy="-0.0 0.0 -0.0" xyz="0.0 0.0 0.0" />
        <xacro:material_kuka_ral_pure_white />
      </visual>
    </link>

    <!-- joints - main serial chain -->
    <joint name="${prefix}base_link-base_link_inertia" type="fixed">
      <parent link="${prefix}base_link" />
      <child link="${prefix}base_link_inertia" />
      <origin xyz="0 0 0" rpy="0 0 0" />
    </joint>
    <joint name="${prefix}joint_1" type="revolute">
      <axis xyz="0.0 0.0 -1.0" />
      <child link="${prefix}link_1" />
      <limit effort="74.930405" lower="-3.2288591E0" upper="3.2288591E0" velocity="3.490656" />
      <origin rpy="-0.0 0.0 -0.0" xyz="0.0 0.0 0.1264" />
      <parent link="${prefix}base_link_inertia" />
    </joint>
    <joint name="${prefix}joint_2" type="revolute">
      <axis xyz="0.0 0.0 1.0" />
      <child link="${prefix}link_2" />
      <limit effort="74.472453" lower="-4.0142572796E0" upper="8.726646E-1" velocity="3.490656" />
      <origin rpy="${-pi/2.0} 0.0 -0.0" xyz="0.0 0.0 0.0886" />
      <parent link="${prefix}link_1" />
    </joint>
    <joint name="${prefix}joint_3" type="revolute">
      <axis xyz="0.0 0.0 1.0" />
      <child link="${prefix}link_3" />
      <limit effort="43.393430" lower="-2.61799387799E0" upper="2.61799387799E0" velocity="3.490656" />
      <origin rpy="0.0 0.0 ${-pi/2.0}" xyz="0.3 0.0 0.0" />
      <parent link="${prefix}link_2" />
    </joint>
    <joint name="${prefix}joint_4" type="revolute">
      <axis xyz="0.0 0.0 1.0" />
      <child link="${prefix}link_4" />
      <limit effort="14.767719" lower="-3.05432619E0" upper="3.05432619E0" velocity="5.235988" />
      <origin rpy="${pi/2.0} 0.0 -0.0" xyz="0.0 0.0 0.0" />
      <parent link="${prefix}link_3" />
    </joint>
    <joint name="${prefix}joint_5" type="revolute">
      <axis xyz="0.0 0.0 1.0" />
      <child link="${prefix}link_5" />
      <limit effort="13.187655" lower="-1.919862177E0" upper="1.919862177E0" velocity="5.235988" />
      <origin rpy="${-pi/2.0} 0.0 -0.0" xyz="0.0 0.0 -0.3" />
      <parent link="${prefix}link_4" />
    </joint>
    <joint name="${prefix}joint_6" type="revolute">
      <axis xyz="0.0 0.0 1.0" />
      <child link="${prefix}link_6" />
      <limit effort="4.834440" lower="-3.839724354E0" upper="3.839724354E0" velocity="6.981310" />
      <origin rpy="${pi/2.0} 0.0 -0.0" xyz="0.0 0.0 0.0" />
      <parent link="${prefix}link_5" />
    </joint>

    <!-- ROS-Industrial 'base' frame - equivalent of 'KUKA ROBROOT'-->
    <link name="${prefix}base" />
    <joint name="${prefix}base_link-base" type="fixed">
      <origin xyz="0 0 0" rpy="0 0 0"/>
      <parent link="${prefix}base_link"/>
      <child link="${prefix}base"/>
    </joint>

    <!-- ROS-Industrial 'flange' frame - attachment point for EEF models -->
    <link name="${prefix}flange" />
    <joint name="${prefix}link6-flange" type="fixed">
      <child link="${prefix}flange" />
      <origin rpy="0 ${pi/2} -0.0" xyz="0.0 0.0 -0.1605" />
      <parent link="${prefix}link_6" />
    </joint>

    <!-- ROS-Industrial 'tool0' frame - all-zeros tool frame -->
    <link name="${prefix}tool0" />
    <joint name="${prefix}link6-tool0" type="fixed">
      <child link="${prefix}tool0" />
      <origin rpy="0 ${pi} -0.0" xyz="0.0 0.0 -0.1605" />
      <parent link="${prefix}link_6" />
    </joint>
  </xacro:macro>
</robot>
