<?xml version="1.0" encoding="UTF-8"?>
<robot xmlns:xacro="http://www.ros.org/wiki/xacro" name="lbr_iisy3_r760">
  <!-- include helper xacros -->
  <xacro:include filename="$(find kuka_resources)/urdf/common_materials.xacro"/>
  <xacro:macro name="kuka_lbr_iisy3_r760_robot" params="prefix package_name *origin">
    <!-- links - main serial chain -->
    <link name="world"/>
    <link name="${prefix}base_link">
      <collision>
        <geometry>
          <mesh filename="package://${package_name}/meshes/lbr_iisy3_r760/collision/base_link.stl"/>
        </geometry>
        <origin rpy="-0.0 0.0 -0.0" xyz="0.0 0.0 0.0"/>
      </collision>
      <inertial>
        <inertia ixx="0.012748224322771616" ixy="0.0" ixz="0.0" iyy="0.010816256892101183" iyz="0.0" izz="0.014034253414070816"/>
        <mass value="3.6832E0"/>
        <origin rpy="-1.635646718734919 -1.5587113211406542 -3.076430534295977" xyz="-0.010469427580225498 2.2191996713941945E-18 0.06527114050303555"/>
      </inertial>
      <visual>
        <geometry>
          <mesh filename="package://${package_name}/meshes/lbr_iisy3_r760/visual/base_link.stl"/>
        </geometry>
        <origin rpy="-0.0 0.0 -0.0" xyz="0.0 0.0 0.0"/>
        <xacro:material_kuka_ral_pure_white/>
      </visual>
    </link>
    <link name="${prefix}link_1">
      <collision>
        <geometry>
          <mesh filename="package://${package_name}/meshes/lbr_iisy3_r760/collision/link_1.stl"/>
        </geometry>
        <origin rpy="-0.0 0.0 -0.0" xyz="0.0 0.0 0.0"/>
      </collision>
      <inertial>
        <inertia ixx="0.00864540353780418" ixy="0.0" ixz="0.0" iyy="0.00573103463618732" iyz="0.0" izz="0.00974792600424334"/>
        <mass value="3.2492E0"/>
        <origin rpy="-1.5252872042613295 -0.9405332807925293 1.5213371149412753" xyz="-1.91677951495753E-4 0.024070491197833298 -0.0710631416964176"/>
      </inertial>
      <visual>
        <geometry>
          <mesh filename="package://${package_name}/meshes/lbr_iisy3_r760/visual/link_1.stl"/>
        </geometry>
        <origin rpy="-0.0 0.0 -0.0" xyz="0.0 0.0 0.0"/>
        <xacro:material_kuka_ral_pure_white/>
      </visual>
    </link>
    <link name="${prefix}link_2">
      <collision>
        <geometry>
          <mesh filename="package://${package_name}/meshes/lbr_iisy3_r760/collision/link_2.stl"/>
        </geometry>
        <origin rpy="-0.0 0.0 -0.0" xyz="0.0 0.0 0.0"/>
      </collision>
      <inertial>
        <inertia ixx="0.0521692170047944" ixy="0.0" ixz="0.0" iyy="0.0042331111850977" iyz="0.0" izz="0.0534425693052013"/>
        <mass value="3.212E0"/>
        <origin rpy="9.692351535578106E-5 0.0015557646011294692 -1.5702311120941035" xyz="0.151061643835616 -6.75591531755915E-4 -0.034993673723536706"/>
      </inertial>
      <visual>
        <geometry>
          <mesh filename="package://${package_name}/meshes/lbr_iisy3_r760/visual/link_2.stl"/>
        </geometry>
        <origin rpy="-0.0 0.0 -0.0" xyz="0.0 0.0 0.0"/>
        <xacro:material_kuka_ral_pure_white/>
      </visual>
    </link>
    <link name="${prefix}link_3">
      <collision>
        <geometry>
          <mesh filename="package://${package_name}/meshes/lbr_iisy3_r760/collision/link_3.stl"/>
        </geometry>
        <origin rpy="-0.0 0.0 -0.0" xyz="0.0 0.0 0.0"/>
      </collision>
      <inertial>
        <inertia ixx="0.0113804888378926" ixy="0.0" ixz="0.0" iyy="0.00566536942404497" iyz="0.0" izz="0.0133950588482047"/>
        <mass value="3.471E0"/>
        <origin rpy="1.5993955084701255 -1.1491769762279627 3.1012276608488882" xyz="0.029424678766926 2.54105445116681E-4 0.058670936329588"/>
      </inertial>
      <visual>
        <geometry>
          <mesh filename="package://${package_name}/meshes/lbr_iisy3_r760/visual/link_3.stl"/>
        </geometry>
        <origin rpy="-0.0 0.0 -0.0" xyz="0.0 0.0 0.0"/>
        <xacro:material_kuka_ral_pure_white/>
      </visual>
    </link>
    <link name="${prefix}link_4">
      <collision>
        <geometry>
          <mesh filename="package://${package_name}/meshes/lbr_iisy3_r760/collision/link_4.stl"/>
        </geometry>
        <origin rpy="-0.0 0.0 -0.0" xyz="0.0 0.0 0.0"/>
      </collision>
      <inertial>
        <inertia ixx="0.00244684891934666" ixy="0.0" ixz="0.0" iyy="0.00929300990970133" iyz="0.0" izz="0.00957902612033654"/>
        <mass value="2.0138E0"/>
        <origin rpy="1.6613960972986936 -1.1557380835519457 -1.5702834955545293" xyz="1.05670870990168E-4 0.038203987486344196 -0.0813488578806237"/>
      </inertial>
      <visual>
        <geometry>
          <mesh filename="package://${package_name}/meshes/lbr_iisy3_r760/visual/link_4.stl"/>
        </geometry>
        <origin rpy="-0.0 0.0 -0.0" xyz="0.0 0.0 0.0"/>
        <xacro:material_kuka_ral_pure_white/>
      </visual>
    </link>
    <link name="${prefix}link_5">
      <collision>
        <geometry>
          <mesh filename="package://${package_name}/meshes/lbr_iisy3_r760/collision/link_5.stl"/>
        </geometry>
        <origin rpy="-0.0 0.0 -0.0" xyz="0.0 0.0 0.0"/>
      </collision>
      <inertial>
        <inertia ixx="0.00236252846105637" ixy="0.0" ixz="0.0" iyy="0.00141854396142661" iyz="0.0" izz="0.0025813096143987"/>
        <mass value="1.4418E0"/>
        <origin rpy="-1.7233052822660835 -1.3466087566012612 0.1844343658550185" xyz="0.0223951033430434 -2.98134988556471E-21 -0.0316419475655431"/>
      </inertial>
      <visual>
        <geometry>
          <mesh filename="package://${package_name}/meshes/lbr_iisy3_r760/visual/link_5.stl"/>
        </geometry>
        <origin rpy="-0.0 0.0 -0.0" xyz="0.0 0.0 0.0"/>
        <xacro:material_kuka_ral_pure_white/>
      </visual>
    </link>
    <link name="${prefix}link_6">
      <collision>
        <geometry>
          <mesh filename="package://${package_name}/meshes/lbr_iisy3_r760/collision/link_6.stl"/>
        </geometry>
        <origin rpy="-0.0 0.0 -0.0" xyz="0.0 0.0 0.0"/>
      </collision>
      <inertial>
        <inertia ixx="0.00130428196885741" ixy="0.0" ixz="0.0" iyy="8.59824496082689E-4" iyz="0.0" izz="0.00133168575299756"/>
        <mass value="7.25E-1"/>
        <origin rpy="-0.5546496285205927 -0.9838872221389914 0.47057095417629574" xyz="-8.78896551724138E-4 0.0100584827586207 -0.0396903310344828"/>
      </inertial>
      <visual>
        <geometry>
          <mesh filename="package://${package_name}/meshes/lbr_iisy3_r760/visual/link_6.stl"/>
        </geometry>
        <origin rpy="-0.0 0.0 -0.0" xyz="0.0 0.0 0.0"/>
        <xacro:material_kuka_ral_pure_white/>
      </visual>
    </link>
    <!-- joints - main serial chain -->
    <joint name="${prefix}world-base_link" type="fixed">
      <parent link="world"/>
      <child link="${prefix}base_link"/>
      <xacro:insert_block name="origin"/>
    </joint>
    <joint name="${prefix}joint_1" type="revolute">
      <axis xyz="0.0 0.0 -1.0"/>
      <child link="${prefix}link_1"/>
      <limit effort="74.930405" lower="-3.2288591E0" upper="3.2288591E0" velocity="3.490656"/>
      <origin rpy="-0.0 0.0 -0.0" xyz="0.0 0.0 0.1264"/>
      <parent link="${prefix}base_link"/>
    </joint>
    <joint name="${prefix}joint_2" type="revolute">
      <axis xyz="0.0 0.0 1.0"/>
      <child link="${prefix}link_2"/>
      <limit effort="74.472453" lower="-4.0142572796E0" upper="8.726646E-1" velocity="3.490656"/>
      <origin rpy="${-pi/2.0} 0.0 -0.0" xyz="0.0 0.0 0.0886"/>
      <parent link="${prefix}link_1"/>
    </joint>
    <joint name="${prefix}joint_3" type="revolute">
      <axis xyz="0.0 0.0 1.0"/>
      <child link="${prefix}link_3"/>
      <limit effort="43.393430" lower="-2.61799387799E0" upper="2.61799387799E0" velocity="3.490656"/>
      <origin rpy="0.0 0.0 ${-pi/2.0}" xyz="0.3 0.0 0.0"/>
      <parent link="${prefix}link_2"/>
    </joint>
    <joint name="${prefix}joint_4" type="revolute">
      <axis xyz="0.0 0.0 1.0"/>
      <child link="${prefix}link_4"/>
      <limit effort="14.767719" lower="-3.05432619E0" upper="3.05432619E0" velocity="5.235988"/>
      <origin rpy="${pi/2.0} 0.0 -0.0" xyz="0.0 0.0 0.0"/>
      <parent link="${prefix}link_3"/>
    </joint>
    <joint name="${prefix}joint_5" type="revolute">
      <axis xyz="0.0 0.0 1.0"/>
      <child link="${prefix}link_5"/>
      <limit effort="13.187655" lower="-1.919862177E0" upper="1.919862177E0" velocity="5.235988"/>
      <origin rpy="${-pi/2.0} 0.0 -0.0" xyz="0.0 0.0 -0.3"/>
      <parent link="${prefix}link_4"/>
    </joint>
    <joint name="${prefix}joint_6" type="revolute">
      <axis xyz="0.0 0.0 1.0"/>
      <child link="${prefix}link_6"/>
      <limit effort="4.834440" lower="-3.839724354E0" upper="3.839724354E0" velocity="6.981310"/>
      <origin rpy="${pi/2.0} 0.0 -0.0" xyz="0.0 0.0 0.0"/>
      <parent link="${prefix}link_5"/>
    </joint>
    <!-- ROS-Industrial 'base' frame - equivalent of 'KUKA ROBROOT'-->
    <link name="${prefix}base"/>
    <joint name="${prefix}base_link-base" type="fixed">
      <origin xyz="0 0 0" rpy="0 0 0"/>
      <parent link="${prefix}base_link"/>
      <child link="${prefix}base"/>
    </joint>
    <!-- ROS-Industrial 'flange' frame - attachment point for EEF models -->
    <link name="${prefix}flange"/>
    <joint name="${prefix}link6-flange" type="fixed">
      <child link="${prefix}flange"/>
      <origin rpy="0 ${pi/2} -0.0" xyz="0.0 0.0 -0.1605"/>
      <parent link="${prefix}link_6"/>
    </joint>
    <!-- ROS-Industrial 'tool0' frame - all-zeros tool frame -->
    <link name="${prefix}tool0"/>
    <joint name="${prefix}link6-tool0" type="fixed">
      <child link="${prefix}tool0"/>
      <origin rpy="0 ${pi} -0.0" xyz="0.0 0.0 -0.1605"/>
      <parent link="${prefix}link_6"/>
    </joint>
  </xacro:macro>
</robot>
