<?xml version="1.0" encoding="UTF-8"?>
<robot xmlns:xacro="http://www.ros.org/wiki/xacro" name="lbr_iisy11_r1300">
  <!-- include helper xacros -->
  <xacro:include filename="$(find kuka_lbr_iisy_support)/urdf/lbr_iisy_ros2_control.xacro" />
  <xacro:include filename="$(find kuka_resources)/urdf/common_materials.xacro"/>
  <xacro:include filename="$(find kuka_lbr_iisy_support)/urdf/lbr_iisy_transmission.xacro" />

  <xacro:macro name="kuka_lbr_iisy11_r1300_robot" params="prefix use_fake_hardware:=false">
    <!-- ros2 control instance -->
    <xacro:kuka_lbr_iisy_ros2_control
    name="lbr_iisy11_r1300"
    prefix="${prefix}"
    use_fake_hardware="${use_fake_hardware}" />

    <!-- links - main serial chain -->
    <!-- links - root element cannot have inertia, therefore a dummy base_link is needed -->
    <link name="${prefix}base_link"/>
    <link name="${prefix}base_link_inertia">
      <collision>
        <geometry>
          <mesh filename="package://kuka_lbr_iisy_support/meshes/lbr_iisy11_r1300/collision/base_link.stl" />
        </geometry>
        <origin rpy="-0.0 0.0 -0.0" xyz="0.0 0.0 0.0" />
      </collision>
      <inertial>
        <inertia ixx="0.05163236" ixy="0.0" ixz="0.0" iyy="0.03961305" iyz="0.0" izz="0.05515706"/>
        <mass value="8.865E0"/>
        <origin rpy="-0.0 0.0 -0.0" xyz="0.0 0.0 0.0" />
      </inertial>
      <visual>
        <geometry>
          <mesh filename="package://kuka_lbr_iisy_support/meshes/lbr_iisy11_r1300/visual/base_link.stl" />
        </geometry>
        <origin rpy="-0.0 0.0 -0.0" xyz="0.0 0.0 0.0" />
        <xacro:material_kuka_ral_pure_white />
      </visual>
    </link>
    <link name="${prefix}link_1">
      <collision>
        <geometry>
          <mesh filename="package://kuka_lbr_iisy_support/meshes/lbr_iisy11_r1300/collision/link_1.stl" />
        </geometry>
        <origin rpy="-0.0 0.0 -0.0" xyz="0.0 0.0 0.0" />
      </collision>
      <inertial>
        <inertia ixx="0.62408426" ixy="0.0" ixz="0.0" iyy="0.03943643" iyz="0.0" izz="0.63132936"/>
        <mass value="9.87E0"/>
        <origin rpy="-0.0 0.0 -0.0" xyz="0.0 0.0 0.0" />
      </inertial>
      <visual>
        <geometry>
          <mesh filename="package://kuka_lbr_iisy_support/meshes/lbr_iisy11_r1300/visual/link_1.stl" />
        </geometry>
        <origin rpy="-0.0 0.0 -0.0" xyz="0.0 0.0 0.0" />
        <xacro:material_kuka_ral_pure_white />
      </visual>
    </link>
    <link name="${prefix}link_2">
      <collision>
        <geometry>
          <mesh filename="package://kuka_lbr_iisy_support/meshes/lbr_iisy11_r1300/collision/link_2.stl" />
        </geometry>
        <origin rpy="-0.0 0.0 -0.0" xyz="0.0 0.0 0.0" />
      </collision>
      <inertial>
        <inertia ixx="0.01739898" ixy="0.0" ixz="0.0" iyy="0.03354988" iyz="0.0" izz="0.0366683"/>
        <mass value="1.0139E1"/>
        <origin rpy="-0.0 0.0 -0.0" xyz="0.0 0.0 0.0" />
      </inertial>
      <visual>
        <geometry>
          <mesh filename="package://kuka_lbr_iisy_support/meshes/lbr_iisy11_r1300/visual/link_2.stl" />
        </geometry>
        <origin rpy="-0.0 0.0 -0.0" xyz="0.0 0.0 0.0" />
        <xacro:material_kuka_ral_pure_white />
      </visual>
    </link>
    <link name="${prefix}link_3">
      <collision>
        <geometry>
          <mesh filename="package://kuka_lbr_iisy_support/meshes/lbr_iisy11_r1300/collision/link_3.stl" />
        </geometry>
        <origin rpy="-0.0 0.0 -0.0" xyz="0.0 0.0 0.0" />
      </collision>
      <inertial>
        <inertia ixx="0.02748508" ixy="0.0" ixz="0.0" iyy="0.16186323" iyz="0.0" izz="0.1694282"/>
        <mass value="7.5014E0"/>
        <origin rpy="-0.0 0.0 -0.0" xyz="0.0 0.0 0.0" />
      </inertial>
      <visual>
        <geometry>
          <mesh filename="package://kuka_lbr_iisy_support/meshes/lbr_iisy11_r1300/visual/link_3.stl" />
        </geometry>
        <origin rpy="-0.0 0.0 -0.0" xyz="0.0 0.0 0.0" />
        <xacro:material_kuka_ral_pure_white />
      </visual>
    </link>
    <link name="${prefix}link_4">
      <collision>
        <geometry>
          <mesh filename="package://kuka_lbr_iisy_support/meshes/lbr_iisy11_r1300/collision/link_4.stl" />
        </geometry>
        <origin rpy="-0.0 0.0 -0.0" xyz="0.0 0.0 0.0" />
      </collision>
      <inertial>
        <inertia ixx="0.00716767" ixy="0.0" ixz="0.0" iyy="0.00536601" iyz="0.0" izz="0.0089832"/>
        <mass value="6.9744E0"/>
        <origin rpy="-0.0 0.0 -0.0" xyz="0.0 0.0 0.0" />
      </inertial>
      <visual>
        <geometry>
          <mesh filename="package://kuka_lbr_iisy_support/meshes/lbr_iisy11_r1300/visual/link_4.stl" />
        </geometry>
        <origin rpy="-0.0 0.0 -0.0" xyz="0.0 0.0 0.0" />
        <xacro:material_kuka_ral_pure_white />
      </visual>
    </link>
    <link name="${prefix}link_5">
      <collision>
        <geometry>
          <mesh filename="package://kuka_lbr_iisy_support/meshes/lbr_iisy11_r1300/collision/link_5.stl" />
        </geometry>
        <origin rpy="-0.0 0.0 -0.0" xyz="0.0 0.0 0.0" />
      </collision>
      <inertial>
        <inertia ixx="0.00396428" ixy="0.0" ixz="0.0" iyy="0.00292738" iyz="0.0" izz="0.00410763"/>
        <mass value="2.509E0"/>
        <origin rpy="-0.0 0.0 -0.0" xyz="0.0 0.0 0.0" />
      </inertial>
      <visual>
        <geometry>
          <mesh filename="package://kuka_lbr_iisy_support/meshes/lbr_iisy11_r1300/visual/link_5.stl" />
        </geometry>
        <origin rpy="-0.0 0.0 -0.0" xyz="0.0 0.0 0.0" />
        <xacro:material_kuka_ral_pure_white />
      </visual>
    </link>
    <link name="${prefix}link_6">
      <collision>
        <geometry>
          <mesh filename="package://kuka_lbr_iisy_support/meshes/lbr_iisy11_r1300/collision/link_6.stl" />
        </geometry>
        <origin rpy="-0.0 0.0 -0.0" xyz="0.0 0.0 0.0" />
      </collision>
      <inertial>
        <inertia ixx="0.00396428" ixy="0.0" ixz="0.0" iyy="0.00292738" iyz="0.0" izz="0.00410763"/>
        <mass value="1.527E0"/>
        <origin rpy="-0.0 0.0 -0.0" xyz="0.0 0.0 0.0" />
      </inertial>
      <visual>
        <geometry>
          <mesh filename="package://kuka_lbr_iisy_support/meshes/lbr_iisy11_r1300/visual/link_6.stl" />
        </geometry>
        <origin rpy="-0.0 0.0 -0.0" xyz="0.0 0.0 0.0" />
        <xacro:material_kuka_ral_pure_white />
      </visual>
    </link>

    <!-- joints - main serial chain -->
    <joint name="${prefix}base_link-base_link_inertia" type="fixed">
      <parent link="${prefix}base_link" />
      <child link="${prefix}base_link_inertia" />
      <origin xyz="0 0 0" rpy="0 0 0" />
    </joint>
    <joint name="${prefix}joint_1" type="revolute">
      <axis xyz="0.0 0.0 1.0" />
      <child link="${prefix}link_1" />
      <limit effort="405.840000" lower="-3.2288591161895095E0" upper="3.2288591161895095E0" velocity="3.490656"/>
      <origin rpy="${-pi} 0.0 -0.0" xyz="0.0 0.0 0.0"/>
      <parent link="${prefix}base_link_inertia" />
    </joint>
    <joint name="${prefix}joint_2" type="revolute">
      <axis xyz="0.0 0.0 1.0" />
      <child link="${prefix}link_2" />
      <limit effort="366.247685" lower="-4.014257279586958E0" upper="8.726646259971648E-1" velocity="3.490656"/>
      <origin rpy="${pi/2.0} 0.0 -0.0" xyz="0.0 0.0 -0.3"/>
      <parent link="${prefix}link_1" />
    </joint>
    <joint name="${prefix}joint_3" type="revolute">
      <axis xyz="0.0 0.0 1.0" />
      <child link="${prefix}link_3" />
      <limit effort="147.189440" lower="-2.6179938779914944E0" upper="2.6179938779914944E0" velocity="3.490656"/>
      <origin rpy="0.0 0.0 ${-pi/2.0}" xyz="0.59 0.0 0.0"/>
      <parent link="${prefix}link_2" />
    </joint>
    <joint name="${prefix}joint_4" type="revolute">
      <axis xyz="0.0 0.0 1.0" />
      <child link="${prefix}link_4" />
      <limit effort="65.482547" lower="-3.141592653589793E0" upper="3.141592653589793E0" velocity="4.014255"/>
      <origin rpy="${pi/2.0} 0.0 -0.0" xyz="0.0 0.0 0.0"/>
      <parent link="${prefix}link_3" />
    </joint>
    <joint name="${prefix}joint_5" type="revolute">
      <axis xyz="0.0 0.0 1.0" />
      <child link="${prefix}link_5" />
      <limit effort="64.657647" lower="-1.9198621771937625E0" upper="1.9198621771937625E0" velocity="4.537856"/>
      <origin rpy="${-pi/2.0} 0.0 -0.0" xyz="0.0 0.0 -0.532"/>
      <parent link="${prefix}link_4" />
    </joint>
    <joint name="${prefix}joint_6" type="revolute">
      <axis xyz="0.0 0.0 1.0" />
      <child link="${prefix}link_6" />
      <limit effort="15.720233" lower="-3.839724354387525E0" upper="3.839724354387525E0" velocity="7.504909"/>
      <origin rpy="${pi/2.0} 0.0 -0.0" xyz="0.0 0.0 0.0"/>
      <parent link="${prefix}link_5" />
    </joint>

    <!-- ROS-Industrial 'base' frame - equivalent of 'KUKA ROBROOT'-->
    <link name="${prefix}base" />
    <joint name="${prefix}base_link-base" type="fixed">
      <origin xyz="0 0 0" rpy="0 0 0"/>
      <parent link="${prefix}base_link"/>
      <child link="${prefix}base"/>
    </joint>

    <!-- ROS-Industrial 'flange' frame - attachment point for EEF models -->
    <link name="${prefix}flange" />
    <joint name="${prefix}link6-flange" type="fixed">
      <child link="${prefix}flange" />
      <origin rpy="0 ${pi/2} -0.0" xyz="0.0 0.0 -0.178" />
      <parent link="${prefix}link_6" />
    </joint>

    <!-- ROS-Industrial 'tool0' frame - all-zeros tool frame -->
    <link name="${prefix}tool0" />
    <joint name="${prefix}link6-tool0" type="fixed">
      <child link="${prefix}tool0" />
      <origin rpy="0 ${pi} -0.0" xyz="0.0 0.0 -0.178" />
      <parent link="${prefix}link_6" />
    </joint>
  </xacro:macro>
</robot>
