<?xml version="1.0" encoding="UTF-8"?>
<robot xmlns:xacro="http://www.ros.org/wiki/xacro" name="lbr_iisy15_r930">
  <!-- include helper xacros -->
  <xacro:include filename="$(find kuka_resources)/urdf/common_materials.xacro"/>
  <xacro:macro name="kuka_lbr_iisy15_r930_robot" params="prefix *origin package_name">
    <!-- links - main serial chain -->
    <link name="world"/>
    <link name="${prefix}base_link">
      <collision>
        <geometry>
          <mesh filename="package://${package_name}/meshes/lbr_iisy15_r930/collision/base_link.stl"/>
        </geometry>
        <origin rpy="-0.0 0.0 -0.0" xyz="0.0 0.0 0.0"/>
      </collision>
      <inertial>
        <inertia ixx="1.0" ixy="0.0" ixz="0.0" iyy="1.0" iyz="0.0" izz="1.0"/>
        <mass value="8.666E0"/>
        <origin rpy="0.0 -0.0 0.0" xyz="0.0 0.0 0.0"/>
      </inertial>
      <visual>
        <geometry>
          <mesh filename="package://${package_name}/meshes/lbr_iisy15_r930/visual/base_link.stl"/>
        </geometry>
        <origin rpy="-0.0 0.0 -0.0" xyz="0.0 0.0 0.0"/>
        <xacro:material_kuka_ral_pure_white/>
      </visual>
    </link>
    <link name="${prefix}link_1">
      <collision>
        <geometry>
          <mesh filename="package://${package_name}/meshes/lbr_iisy15_r930/collision/link_1.stl"/>
        </geometry>
        <origin rpy="-0.0 0.0 -0.0" xyz="0.0 0.0 0.0"/>
      </collision>
      <inertial>
        <inertia ixx="0.0489108039022503" ixy="0.0" ixz="0.0" iyy="0.0383705935400879" iyz="0.0" izz="0.0522121642769911"/>
        <mass value="9.62E0"/>
        <origin rpy="-1.3035636348359196 -0.7815781053554747 1.2529437882898196" xyz="0.00344301039501039 0.0191980353430353 -0.08662803846153849"/>
      </inertial>
      <visual>
        <geometry>
          <mesh filename="package://${package_name}/meshes/lbr_iisy15_r930/visual/link_1.stl"/>
        </geometry>
        <origin rpy="-0.0 0.0 -0.0" xyz="0.0 0.0 0.0"/>
        <xacro:material_kuka_ral_pure_white/>
      </visual>
    </link>
    <link name="${prefix}link_2">
      <collision>
        <geometry>
          <mesh filename="package://${package_name}/meshes/lbr_iisy15_r930/collision/link_2.stl"/>
        </geometry>
        <origin rpy="-0.0 0.0 -0.0" xyz="0.0 0.0 0.0"/>
      </collision>
      <inertial>
        <inertia ixx="0.0306168627253135" ixy="0.0" ixz="0.0" iyy="0.252047093745431" iyz="0.0" izz="0.258650362609461"/>
        <mass value="8.079E0"/>
        <origin rpy="-0.017400716172763755 1.2184236596039677E-4 7.609596915052352E-4" xyz="0.144939171927219 4.90834261666048E-4 -0.0453728741180839"/>
      </inertial>
      <visual>
        <geometry>
          <mesh filename="package://${package_name}/meshes/lbr_iisy15_r930/visual/link_2.stl"/>
        </geometry>
        <origin rpy="-0.0 0.0 -0.0" xyz="0.0 0.0 0.0"/>
        <xacro:material_kuka_ral_pure_white/>
      </visual>
    </link>
    <link name="${prefix}link_3">
      <collision>
        <geometry>
          <mesh filename="package://${package_name}/meshes/lbr_iisy15_r930/collision/link_3.stl"/>
        </geometry>
        <origin rpy="-0.0 0.0 -0.0" xyz="0.0 0.0 0.0"/>
      </collision>
      <inertial>
        <inertia ixx="0.0181557035426496" ixy="0.0" ixz="0.0" iyy="0.0346916391676837" iyz="0.0" izz="0.037776951242458"/>
        <mass value="7.6604E0"/>
        <origin rpy="0.1692981167548117 0.5271433699021747 -2.9605806714357508" xyz="0.0400709362435382 0.00400998642368544 0.0499127101717926"/>
      </inertial>
      <visual>
        <geometry>
          <mesh filename="package://${package_name}/meshes/lbr_iisy15_r930/visual/link_3.stl"/>
        </geometry>
        <origin rpy="-0.0 0.0 -0.0" xyz="0.0 0.0 0.0"/>
        <xacro:material_kuka_ral_pure_white/>
      </visual>
    </link>
    <link name="${prefix}link_4">
      <collision>
        <geometry>
          <mesh filename="package://${package_name}/meshes/lbr_iisy15_r930/collision/link_4.stl"/>
        </geometry>
        <origin rpy="-0.0 0.0 -0.0" xyz="0.0 0.0 0.0"/>
      </collision>
      <inertial>
        <inertia ixx="0.0208771593304277" ixy="0.0" ixz="0.0" iyy="0.0526135698207455" iyz="0.0" izz="0.0587485883681802"/>
        <mass value="5.7014E0"/>
        <origin rpy="1.535166999601284 -1.2065715961818437 -1.512863903166617" xyz="0.00141160065948714 0.060839292103693904 -0.12025970463395"/>
      </inertial>
      <visual>
        <geometry>
          <mesh filename="package://${package_name}/meshes/lbr_iisy15_r930/visual/link_4.stl"/>
        </geometry>
        <origin rpy="-0.0 0.0 -0.0" xyz="0.0 0.0 0.0"/>
        <xacro:material_kuka_ral_pure_white/>
      </visual>
    </link>
    <link name="${prefix}link_5">
      <collision>
        <geometry>
          <mesh filename="package://${package_name}/meshes/lbr_iisy15_r930/collision/link_5.stl"/>
        </geometry>
        <origin rpy="-0.0 0.0 -0.0" xyz="0.0 0.0 0.0"/>
      </collision>
      <inertial>
        <inertia ixx="0.00667288072123254" ixy="0.0" ixz="0.0" iyy="0.00503543168148481" iyz="0.0" izz="0.00841044585602456"/>
        <mass value="2.382E0"/>
        <origin rpy="0.4256203528755516 0.1454426479570896 1.2195648324165669" xyz="0.0365444794290512 -0.00829581863979849 -0.0371200125944584"/>
      </inertial>
      <visual>
        <geometry>
          <mesh filename="package://${package_name}/meshes/lbr_iisy15_r930/visual/link_5.stl"/>
        </geometry>
        <origin rpy="-0.0 0.0 -0.0" xyz="0.0 0.0 0.0"/>
        <xacro:material_kuka_ral_pure_white/>
      </visual>
    </link>
    <link name="${prefix}link_6">
      <collision>
        <geometry>
          <mesh filename="package://${package_name}/meshes/lbr_iisy15_r930/collision/link_6.stl"/>
        </geometry>
        <origin rpy="-0.0 0.0 -0.0" xyz="0.0 0.0 0.0"/>
      </collision>
      <inertial>
        <inertia ixx="0.00390274036654823" ixy="0.0" ixz="0.0" iyy="0.00286930887521153" iyz="0.0" izz="0.00403512413298348"/>
        <mass value="1.509E0"/>
        <origin rpy="-0.051936335875096745 -0.1296523529795729 -0.0038347791577379832" xyz="-5.61365142478463E-4 0.00904387011265739 -0.0494449237905898"/>
      </inertial>
      <visual>
        <geometry>
          <mesh filename="package://${package_name}/meshes/lbr_iisy15_r930/visual/link_6.stl"/>
        </geometry>
        <origin rpy="-0.0 0.0 -0.0" xyz="0.0 0.0 0.0"/>
        <xacro:material_kuka_ral_pure_white/>
      </visual>
    </link>
    <!-- joints - main serial chain -->
    <joint name="${prefix}world-base_link" type="fixed">
      <parent link="world"/>
      <child link="${prefix}base_link"/>
      <xacro:insert_block name="origin"/>
    </joint>
    <joint name="${prefix}joint_1" type="revolute">
      <axis xyz="0.0 0.0 1.0"/>
      <child link="${prefix}link_1"/>
      <limit effort="398.011277" lower="-3.2288591161895095E0" upper="3.2288591161895095E0" velocity="3.490656"/>
      <origin rpy="${-pi} 0.0 -0.0" xyz="0.0 0.0 0.0"/>
      <parent link="${prefix}base_link"/>
    </joint>
    <joint name="${prefix}joint_2" type="revolute">
      <axis xyz="0.0 0.0 1.0"/>
      <child link="${prefix}link_2"/>
      <limit effort="286.529873" lower="-4.014257279586958E0" upper="8.726646259971648E-1" velocity="3.490656"/>
      <origin rpy="${pi/2.0} 0.0 -0.0" xyz="0.0 0.0 -0.3"/>
      <parent link="${prefix}link_1"/>
    </joint>
    <joint name="${prefix}joint_3" type="revolute">
      <axis xyz="0.0 0.0 1.0"/>
      <child link="${prefix}link_3"/>
      <limit effort="137.666701" lower="-2.6179938779914944E0" upper="2.6179938779914944E0" velocity="3.490656"/>
      <origin rpy="0.0 0.0 ${-pi/2.0}" xyz="0.385 0.0 0.0"/>
      <parent link="${prefix}link_2"/>
    </joint>
    <joint name="${prefix}joint_4" type="revolute">
      <axis xyz="0.0 0.0 1.0"/>
      <child link="${prefix}link_4"/>
      <limit effort="63.574238" lower="-3.141592653589793E0" upper="3.141592653589793E0" velocity="4.014255"/>
      <origin rpy="${pi/2.0} 0.0 -0.0" xyz="0.0 0.0 0.0"/>
      <parent link="${prefix}link_3"/>
    </joint>
    <joint name="${prefix}joint_5" type="revolute">
      <axis xyz="0.0 0.0 1.0"/>
      <child link="${prefix}link_5"/>
      <limit effort="58.580298" lower="-1.9198621771937625E0" upper="1.9198621771937625E0" velocity="4.537856"/>
      <origin rpy="${-pi/2.0} 0.0 -0.0" xyz="0.0 0.0 -0.367"/>
      <parent link="${prefix}link_4"/>
    </joint>
    <joint name="${prefix}joint_6" type="revolute">
      <axis xyz="0.0 0.0 1.0"/>
      <child link="${prefix}link_6"/>
      <limit effort="15.927568" lower="-3.839724354387525E0" upper="3.839724354387525E0" velocity="7.504909"/>
      <origin rpy="${pi/2.0} 0.0 -0.0" xyz="0.0 0.0 0.0"/>
      <parent link="${prefix}link_5"/>
    </joint>
    <!-- ROS-Industrial 'base' frame - equivalent of 'KUKA ROBROOT'-->
    <link name="${prefix}base"/>
    <joint name="${prefix}base_link-base" type="fixed">
      <origin xyz="0 0 0" rpy="0 0 0"/>
      <parent link="${prefix}base_link"/>
      <child link="${prefix}base"/>
    </joint>
    <!-- ROS-Industrial 'flange' frame - attachment point for EEF models -->
    <link name="${prefix}flange"/>
    <joint name="${prefix}link6-flange" type="fixed">
      <child link="${prefix}flange"/>
      <origin rpy="0 ${pi/2} -0.0" xyz="0.0 0.0 -0.178"/>
      <parent link="${prefix}link_6"/>
    </joint>
    <!-- ROS-Industrial 'tool0' frame - all-zeros tool frame -->
    <link name="${prefix}tool0"/>
    <joint name="${prefix}link6-tool0" type="fixed">
      <child link="${prefix}tool0"/>
      <origin rpy="0 ${pi} -0.0" xyz="0.0 0.0 -0.178"/>
      <parent link="${prefix}link_6"/>
    </joint>
  </xacro:macro>
</robot>
