<?xml version="1.0"?>
<robot xmlns:xacro="http://wiki.ros.org/xacro">
  <xacro:include filename="$(find kuka_quantec_support)/urdf/kr_quantec_ros2_control.xacro"/>
  <xacro:include filename="$(find kuka_quantec_support)/urdf/kr_quantec_transmission.xacro"/>
  <xacro:macro name="kuka_kr210_r3100_2_robot" params="client_ip client_port prefix use_fake_hardware roundtrip_time *origin">
    <!-- ros2 control instance -->
    <xacro:kuka_quantec_ros2_control name="${prefix}kr210_r3100_2" client_ip="${client_ip}" client_port="${client_port}" prefix="${prefix}" use_fake_hardware="${use_fake_hardware}" roundtrip_time="${roundtrip_time}"/>
    <link name="world"/>
    <link name="${prefix}base_link">
      <collision>
        <geometry>
          <mesh filename="package://kuka_quantec_support/meshes/kr210_r3100_2/collision/base_link.stl"/>
        </geometry>
        <origin rpy="-0.0 0.0 -0.0" xyz="0.0 0.0 0.0"/>
      </collision>
      <visual>
        <geometry>
          <mesh filename="package://kuka_quantec_support/meshes/kr210_r3100_2/visual/base_link.stl"/>
        </geometry>
        <origin rpy="-0.0 0.0 -0.0" xyz="0.0 0.0 0.0"/>
      </visual>
    </link>
    <link name="${prefix}link_1">
      <collision>
        <geometry>
          <mesh filename="package://kuka_quantec_support/meshes/kr210_r3100_2/collision/link_1.stl"/>
        </geometry>
        <origin rpy="-0.0 0.0 -0.0" xyz="0.0 0.0 0.0"/>
      </collision>
      <visual>
        <geometry>
          <mesh filename="package://kuka_quantec_support/meshes/kr210_r3100_2/visual/link_1.stl"/>
        </geometry>
        <origin rpy="-0.0 0.0 -0.0" xyz="0.0 0.0 0.0"/>
      </visual>
    </link>
    <link name="${prefix}link_2">
      <collision>
        <geometry>
          <mesh filename="package://kuka_quantec_support/meshes/kr210_r3100_2/collision/link_2.stl"/>
        </geometry>
        <origin rpy="-0.0 0.0 -0.0" xyz="0.0 0.0 0.0"/>
      </collision>
      <visual>
        <geometry>
          <mesh filename="package://kuka_quantec_support/meshes/kr210_r3100_2/visual/link_2.stl"/>
        </geometry>
        <origin rpy="-0.0 0.0 -0.0" xyz="0.0 0.0 0.0"/>
      </visual>
    </link>
    <link name="${prefix}link_3">
      <collision>
        <geometry>
          <mesh filename="package://kuka_quantec_support/meshes/kr210_r3100_2/collision/link_3.stl"/>
        </geometry>
        <origin rpy="-0.0 0.0 -0.0" xyz="0.0 0.0 0.0"/>
      </collision>
      <visual>
        <geometry>
          <mesh filename="package://kuka_quantec_support/meshes/kr210_r3100_2/visual/link_3.stl"/>
        </geometry>
        <origin rpy="-0.0 0.0 -0.0" xyz="0.0 0.0 0.0"/>
      </visual>
    </link>
    <link name="${prefix}link_4">
      <collision>
        <geometry>
          <mesh filename="package://kuka_quantec_support/meshes/kr210_r3100_2/collision/link_4.stl"/>
        </geometry>
        <origin rpy="-0.0 0.0 -0.0" xyz="0.0 0.0 0.0"/>
      </collision>
      <visual>
        <geometry>
          <mesh filename="package://kuka_quantec_support/meshes/kr210_r3100_2/visual/link_4.stl"/>
        </geometry>
        <origin rpy="-0.0 0.0 -0.0" xyz="0.0 0.0 0.0"/>
      </visual>
    </link>
    <link name="${prefix}link_5">
      <collision>
        <geometry>
          <mesh filename="package://kuka_quantec_support/meshes/kr210_r3100_2/collision/link_5.stl"/>
        </geometry>
        <origin rpy="-0.0 0.0 -0.0" xyz="0.0 0.0 0.0"/>
      </collision>
      <visual>
        <geometry>
          <mesh filename="package://kuka_quantec_support/meshes/kr210_r3100_2/visual/link_5.stl"/>
        </geometry>
        <origin rpy="-0.0 0.0 -0.0" xyz="0.0 0.0 0.0"/>
      </visual>
    </link>
    <link name="${prefix}link_6">
      <collision>
        <geometry>
          <mesh filename="package://kuka_quantec_support/meshes/kr210_r3100_2/collision/link_6.stl"/>
        </geometry>
        <origin rpy="-0.0 0.0 -0.0" xyz="0.0 0.0 0.0"/>
      </collision>
      <visual>
        <geometry>
          <mesh filename="package://kuka_quantec_support/meshes/kr210_r3100_2/visual/link_6.stl"/>
        </geometry>
        <origin rpy="-0.0 0.0 -0.0" xyz="0.0 0.0 0.0"/>
      </visual>
    </link>
    <joint name="${prefix}world-base_link" type="fixed">
      <parent link="world"/>
      <child link="${prefix}base_link"/>
      <xacro:insert_block name="origin"/>
    </joint>
    <joint name="${prefix}joint_1" type="revolute">
      <axis xyz="0.0 0.0 1.0"/>
      <child link="${prefix}link_1"/>
      <limit effort="7290" lower="-3.2288591161895095E0" upper="3.2288591161895095E0" velocity="${radians(105)}"/>
      <origin rpy="-3.141592653589793 0.0 -0.0" xyz="0.0 0.0 0.0"/>
      <parent link="${prefix}base_link"/>
    </joint>
    <joint name="${prefix}joint_2" type="revolute">
      <axis xyz="0.0 0.0 1.0"/>
      <child link="${prefix}link_2"/>
      <limit effort="8910" lower="-2.443460952792061E0" upper="-8.726646259971647E-2" velocity="${radians(94)}"/>
      <origin rpy="1.5707963267948963 0.0 -0.0" xyz="0.33 0.0 -0.645"/>
      <parent link="${prefix}link_1"/>
    </joint>
    <joint name="${prefix}joint_3" type="revolute">
      <axis xyz="0.0 0.0 1.0"/>
      <child link="${prefix}link_3"/>
      <limit effort="7251.2876" lower="-2.0943951023931953E0" upper="2.9321531433504737E0" velocity="${radians(100)}"/>
      <origin rpy="0.0 0.0 -1.5707963267948963" xyz="1.35 0.0 0.0"/>
      <parent link="${prefix}link_2"/>
    </joint>
    <joint name="${prefix}joint_4" type="revolute">
      <axis xyz="0.0 0.0 1.0"/>
      <child link="${prefix}link_4"/>
      <limit effort="2356.12598" lower="-6.1086523819801535E0" upper="6.1086523819801535E0" velocity="${radians(136)}"/>
      <origin rpy="1.5707963267948963 0.0 -0.0" xyz="0.115 0.0 0.0"/>
      <parent link="${prefix}link_3"/>
    </joint>
    <joint name="${prefix}joint_5" type="revolute">
      <axis xyz="0.0 0.0 1.0"/>
      <child link="${prefix}link_5"/>
      <limit effort="2358.44531" lower="-2.138028333693054E0" upper="2.138028333693054E0" velocity="${radians(129)}"/>
      <origin rpy="-1.5707963267948963 0.0 -0.0" xyz="0.0 0.0 -1.42"/>
      <parent link="${prefix}link_4"/>
    </joint>
    <joint name="${prefix}joint_6" type="revolute">
      <axis xyz="0.0 0.0 1.0"/>
      <child link="${prefix}link_6"/>
      <limit effort="1508.75476" lower="-6.1086523819801535E0" upper="6.1086523819801535E0" velocity="${radians(206)}"/>
      <origin rpy="1.5707963267948963 0.0 -0.0" xyz="0.0 0.0 0.0"/>
      <parent link="${prefix}link_5"/>
    </joint>
    <!-- ROS-Industrial 'base' frame - equivalent of 'KUKA ROBROOT'-->
    <link name="${prefix}base"/>
    <joint name="${prefix}base_link-base" type="fixed">
      <origin xyz="0 0 0" rpy="0 0 0"/>
      <parent link="${prefix}base_link"/>
      <child link="${prefix}base"/>
    </joint>
    <!-- ROS-Industrial 'flange' frame - attachment point for EEF models -->
    <link name="${prefix}flange"/>
    <joint name="${prefix}link6-flange" type="fixed">
      <child link="${prefix}flange"/>
      <origin rpy="0 ${pi/2} -0.0" xyz="0.0 0.0 -0.240"/>
      <parent link="${prefix}link_6"/>
    </joint>
    <!-- ROS-Industrial 'tool0' frame - all-zeros tool frame -->
    <link name="${prefix}tool0"/>
    <joint name="${prefix}link6-tool0" type="fixed">
      <child link="${prefix}tool0"/>
      <origin rpy="0 ${pi} -0.0" xyz="0.0 0.0 -0.240"/>
      <parent link="${prefix}link_6"/>
    </joint>
  </xacro:macro>
</robot>
