<?xml version="1.0" encoding="UTF-8"?>
<robot xmlns:xacro="http://www.ros.org/wiki/xacro" name="kr210_r3100_ultra">
  <xacro:macro name="kuka_kr210_r3100_ultra_robot" params="prefix package_name">
    <link name="${prefix}base"/>
    <link name="${prefix}base_link">
      <collision>
        <geometry>
          <mesh filename="package://${package_name}/meshes/kr210_r3100_ultra/collision/base_link.stl"/>
        </geometry>
        <origin rpy="0.0 -0.0 0.0" xyz="0.0 0.0 0.0"/>
      </collision>
      <inertial>
        <inertia ixx="0.0" ixy="0.0" ixz="0.0" iyy="0.0" iyz="0.0" izz="0.0"/>
        <mass value="2.2839E2"/>
        <origin rpy="0.0 -0.0 0.0" xyz="0.0 0.0 0.0"/>
      </inertial>
      <visual>
        <geometry>
          <mesh filename="package://${package_name}/meshes/kr210_r3100_ultra/visual/base_link.dae"/>
        </geometry>
        <origin rpy="0.0 -0.0 0.0" xyz="0.0 0.0 0.0"/>
      </visual>
    </link>
    <link name="${prefix}flange"/>
    <link name="${prefix}link_1">
      <collision>
        <geometry>
          <mesh filename="package://${package_name}/meshes/kr210_r3100_ultra/collision/link_1.stl"/>
        </geometry>
        <origin rpy="0.0 -0.0 0.0" xyz="0.0 0.0 -0.675"/>
      </collision>
      <inertial>
        <inertia ixx="0.0" ixy="0.0" ixz="0.0" iyy="0.0" iyz="0.0" izz="31.24"/>
        <mass value="3.95720001E2"/>
        <origin rpy="0.0 -0.0 0.0" xyz="0.076220001 0.01017 -0.547549988"/>
      </inertial>
      <visual>
        <geometry>
          <mesh filename="package://${package_name}/meshes/kr210_r3100_ultra/visual/link_1.dae"/>
        </geometry>
        <origin rpy="0.0 -0.0 0.0" xyz="0.0 0.0 -0.675"/>
      </visual>
    </link>
    <link name="${prefix}link_2">
      <collision>
        <geometry>
          <mesh filename="package://${package_name}/meshes/kr210_r3100_ultra/collision/link_2.stl"/>
        </geometry>
        <origin rpy="1.5707963267948966 0.0 1.5707963267948966" xyz="-0.675 -0.35 4.133182947122317e-17"/>
      </collision>
      <inertial>
        <inertia ixx="6.36" ixy="0.0" ixz="0.0" iyy="81.129997" iyz="0.0" izz="81.779999"/>
        <mass value="2.56149994E2"/>
        <origin rpy="1.5707963267948966 -0.0 -3.141592653589793" xyz="0.564940002 0.0 0.0"/>
      </inertial>
      <visual>
        <geometry>
          <mesh filename="package://${package_name}/meshes/kr210_r3100_ultra/visual/link_2.dae"/>
        </geometry>
        <origin rpy="1.5707963267948966 0.0 1.5707963267948966" xyz="-0.675 -0.35 4.133182947122317e-17"/>
      </visual>
    </link>
    <link name="${prefix}link_3">
      <collision>
        <geometry>
          <mesh filename="package://${package_name}/meshes/kr210_r3100_ultra/collision/link_3.stl"/>
        </geometry>
        <origin rpy="1.5707963267948966 0.0 1.5707963267948966" xyz="-2.0250000000000004 -0.35 4.1331829471223196e-17"/>
      </collision>
      <inertial>
        <inertia ixx="3.48" ixy="0.0" ixz="0.0" iyy="42.060001" iyz="0.0" izz="43.07"/>
        <mass value="1.86610001E2"/>
        <origin rpy="-1.5707963267948966 -0.0 1.5707963267948966" xyz="-0.041 0.260540009 0.0"/>
      </inertial>
      <visual>
        <geometry>
          <mesh filename="package://${package_name}/meshes/kr210_r3100_ultra/visual/link_3.dae"/>
        </geometry>
        <origin rpy="1.5707963267948966 0.0 1.5707963267948966" xyz="-2.0250000000000004 -0.35 4.1331829471223196e-17"/>
      </visual>
    </link>
    <link name="${prefix}link_4">
      <collision>
        <geometry>
          <mesh filename="package://${package_name}/meshes/kr210_r3100_ultra/collision/link_4.stl"/>
        </geometry>
        <origin rpy="3.141592653589793 1.5707963267948966 0.0" xyz="1.9840000000000002 -6.582476545417024e-17 1.75"/>
      </collision>
      <inertial>
        <inertia ixx="0.83" ixy="0.0" ixz="0.0" iyy="2.31" iyz="0.0" izz="2.53"/>
        <mass value="7.8879997E1"/>
        <origin rpy="0.0 1.5707963267948966 -0.0" xyz="0.0 0.0 0.01497"/>
      </inertial>
      <visual>
        <geometry>
          <mesh filename="package://${package_name}/meshes/kr210_r3100_ultra/visual/link_4.dae"/>
        </geometry>
        <origin rpy="3.141592653589793 1.5707963267948966 0.0" xyz="1.9840000000000002 -6.582476545417024e-17 1.75"/>
      </visual>
    </link>
    <link name="${prefix}link_5">
      <collision>
        <geometry>
          <mesh filename="package://${package_name}/meshes/kr210_r3100_ultra/collision/link_5.stl"/>
        </geometry>
        <origin rpy="1.5707963267948966 0.0 1.5707963267948966" xyz="-1.9840000000000002 -1.75 4.133182947122316e-17"/>
      </collision>
      <inertial>
        <inertia ixx="0.0" ixy="0.0" ixz="0.0" iyy="0.0" iyz="0.0" izz="0.0"/>
        <mass value="0.0E0"/>
        <origin rpy="0.0 -0.0 0.0" xyz="0.0 0.0 0.0"/>
      </inertial>
      <visual>
        <geometry>
          <mesh filename="package://${package_name}/meshes/kr210_r3100_ultra/visual/link_5.dae"/>
        </geometry>
        <origin rpy="1.5707963267948966 0.0 1.5707963267948966" xyz="-1.9840000000000002 -1.75 4.133182947122316e-17"/>
      </visual>
    </link>
    <link name="${prefix}link_6">
      <collision>
        <geometry>
          <mesh filename="package://${package_name}/meshes/kr210_r3100_ultra/collision/link_6.stl"/>
        </geometry>
        <origin rpy="3.141592653589793 1.5707963267948966 0.0" xyz="1.9840000000000002 -6.582476545417024e-17 1.75"/>
      </collision>
      <inertial>
        <inertia ixx="0.0" ixy="0.0" ixz="0.0" iyy="0.0" iyz="0.0" izz="0.0"/>
        <mass value="0.0E0"/>
        <origin rpy="0.0 -0.0 0.0" xyz="0.0 0.0 0.0"/>
      </inertial>
      <visual>
        <geometry>
          <mesh filename="package://${package_name}/meshes/kr210_r3100_ultra/visual/link_6.dae"/>
        </geometry>
        <origin rpy="3.141592653589793 1.5707963267948966 0.0" xyz="1.9840000000000002 -6.582476545417024e-17 1.75"/>
      </visual>
    </link>
    <link name="${prefix}tool0"/>
    <joint name="${prefix}base_link-base" type="fixed">
      <child link="${prefix}base"/>
      <parent link="${prefix}base_link"/>
    </joint>
    <joint name="${prefix}joint_1" type="revolute">
      <axis xyz="0.0 0.0 1.0"/>
      <child link="${prefix}link_1"/>
      <limit effort="9.6E3" lower="-3.2288591125E0" upper="3.2288591125E0" velocity="1.84E0"/>
      <origin rpy="0.0 0.0 0.0" xyz="0.0 0.0 0.675"/>
      <parent link="${prefix}base_link"/>
    </joint>
    <joint name="${prefix}joint_2" type="revolute">
      <axis xyz="0.0 0.0 1.0"/>
      <child link="${prefix}link_2"/>
      <limit effort="9.6E3" lower="-2.44346095E0" upper="-8.72664625E-2" velocity="1.77E0"/>
      <origin rpy="-1.5707963267948966 -0.0 0.0" xyz="0.35000000000000003 0.0 0.0"/>
      <parent link="${prefix}link_1"/>
    </joint>
    <joint name="${prefix}joint_3" type="revolute">
      <axis xyz="0.0 0.0 1.0"/>
      <child link="${prefix}link_3"/>
      <limit effort="6.64852E3" lower="-2.0943951E0" upper="2.7052603375E0" velocity="1.87E0"/>
      <origin rpy="0.0 -0.0 -1.5707963267948966" xyz="1.35 0.0 0.0"/>
      <parent link="${prefix}link_2"/>
    </joint>
    <joint name="${prefix}joint_4" type="revolute">
      <axis xyz="0.0 0.0 1.0"/>
      <child link="${prefix}link_4"/>
      <limit effort="2.17309E3" lower="-6.108652375E0" upper="6.108652375E0" velocity="2.37E0"/>
      <origin rpy="1.5707963267948966 -0.0 0.0" xyz="-0.041 1.4000000000000001 0.0"/>
      <parent link="${prefix}link_3"/>
    </joint>
    <joint name="${prefix}joint_5" type="revolute">
      <axis xyz="0.0 0.0 1.0"/>
      <child link="${prefix}link_5"/>
      <limit effort="2.17309E3" lower="-2.13802833125E0" upper="2.13802833125E0" velocity="2.26E0"/>
      <origin rpy="-1.5707963267948966 -0.0 0.0" xyz="0.0 0.0 0.0"/>
      <parent link="${prefix}link_4"/>
    </joint>
    <joint name="${prefix}joint_6" type="revolute">
      <axis xyz="0.0 0.0 1.0"/>
      <child link="${prefix}link_6"/>
      <limit effort="1.26875E3" lower="-6.108652375E0" upper="6.108652375E0" velocity="3.6E0"/>
      <origin rpy="1.5707963267948966 -0.0 0.0" xyz="0.0 0.0 0.0"/>
      <parent link="${prefix}link_5"/>
    </joint>
    <joint name="${prefix}link6-flange" type="fixed">
      <child link="${prefix}flange"/>
      <origin rpy="0.0 1.5707963267948966 0.0" xyz="0.0 0.0 -0.24"/>
      <parent link="${prefix}link_6"/>
    </joint>
    <joint name="${prefix}link6-tool0" type="fixed">
      <child link="${prefix}tool0"/>
      <origin rpy="0.0 ${pi} 0.0" xyz="0.0 0.0 -0.24"/>
      <parent link="${prefix}link_6"/>
    </joint>
  </xacro:macro>
</robot>
