<?xml version="1.0"?>
<robot xmlns:xacro="http://wiki.ros.org/xacro">
  <xacro:include filename="$(find kuka_quantec_support)/urdf/kr_quantec_ros2_control.xacro" />
  <xacro:include filename="$(find kuka_quantec_support)/urdf/kr_quantec_transmission.xacro" />

  <xacro:macro name="kuka_kr210_r3100_2_robot" params="prefix use_fake_hardware">
    <!-- ros2 control instance -->
    <xacro:kuka_quantec_ros2_control
    name="kr210_r3100_2"
    prefix="${prefix}"
    use_fake_hardware="${use_fake_hardware}" />

    <link name="${prefix}base_link"/>
    <link name="${prefix}base_link_inertia">
      <collision>
        <geometry>
          <mesh filename="package://kuka_quantec_support/meshes/kr210_r3100_2/collision/base_link.stl"/>
        </geometry>
        <origin rpy="-0.0 0.0 -0.0" xyz="0.0 0.0 0.0"/>
      </collision>
      <inertial>
        <inertia ixx="31.78631557" ixy="0.0" ixz="0.0" iyy="13.33103186" iyz="0.0" izz="34.18067231"/>
        <mass value="2.2596E2"/>
        <origin rpy="-0.0 0.0 -0.0" xyz="0.0 0.0 0.0"/>
      </inertial>
      <visual>
        <geometry>
          <mesh filename="package://kuka_quantec_support/meshes/kr210_r3100_2/visual/base_link.stl"/>
        </geometry>
        <origin rpy="-0.0 0.0 -0.0" xyz="0.0 0.0 0.0"/>
      </visual>
    </link>
    <link name="${prefix}link_1">
      <collision>
        <geometry>
          <mesh filename="package://kuka_quantec_support/meshes/kr210_r3100_2/collision/link_1.stl"/>
        </geometry>
        <origin rpy="-0.0 0.0 -0.0" xyz="0.0 0.0 0.0"/>
      </collision>
      <inertial>
        <inertia ixx="6.11156633" ixy="0.0" ixz="0.0" iyy="82.75093024" iyz="0.0" izz="83.25859672"/>
        <mass value="3.6737E2"/>
        <origin rpy="-0.0 0.0 -0.0" xyz="0.0 0.0 0.0"/>
      </inertial>
      <visual>
        <geometry>
          <mesh filename="package://kuka_quantec_support/meshes/kr210_r3100_2/visual/link_1.stl"/>
        </geometry>
        <origin rpy="-0.0 0.0 -0.0" xyz="0.0 0.0 0.0"/>
      </visual>
    </link>
    <link name="${prefix}link_2">
      <collision>
        <geometry>
          <mesh filename="package://kuka_quantec_support/meshes/kr210_r3100_2/collision/link_2.stl"/>
        </geometry>
        <origin rpy="-0.0 0.0 -0.0" xyz="0.0 0.0 0.0"/>
      </collision>
      <inertial>
        <inertia ixx="3.68215916" ixy="0.0" ixz="0.0" iyy="33.53420017" iyz="0.0" izz="34.55729351"/>
        <mass value="2.5056E2"/>
        <origin rpy="-0.0 0.0 -0.0" xyz="0.0 0.0 0.0"/>
      </inertial>
      <visual>
        <geometry>
          <mesh filename="package://kuka_quantec_support/meshes/kr210_r3100_2/visual/link_2.stl"/>
        </geometry>
        <origin rpy="-0.0 0.0 -0.0" xyz="0.0 0.0 0.0"/>
      </visual>
    </link>
    <link name="${prefix}link_3">
      <collision>
        <geometry>
          <mesh filename="package://kuka_quantec_support/meshes/kr210_r3100_2/collision/link_3.stl"/>
        </geometry>
        <origin rpy="-0.0 0.0 -0.0" xyz="0.0 0.0 0.0"/>
      </collision>
      <inertial>
        <inertia ixx="0.20114802" ixy="0.0" ixz="0.0" iyy="1.61560245" iyz="0.0" izz="1.64041745"/>
        <mass value="2.0653E2"/>
        <origin rpy="-0.0 0.0 -0.0" xyz="0.0 0.0 0.0"/>
      </inertial>
      <visual>
        <geometry>
          <mesh filename="package://kuka_quantec_support/meshes/kr210_r3100_2/visual/link_3.stl"/>
        </geometry>
        <origin rpy="-0.0 0.0 -0.0" xyz="0.0 0.0 0.0"/>
      </visual>
    </link>
    <link name="${prefix}link_4">
      <collision>
        <geometry>
          <mesh filename="package://kuka_quantec_support/meshes/kr210_r3100_2/collision/link_4.stl"/>
        </geometry>
        <origin rpy="-0.0 0.0 -0.0" xyz="0.0 0.0 0.0"/>
      </collision>
      <inertial>
        <inertia ixx="0.34306034" ixy="0.0" ixz="0.0" iyy="0.1968928" iyz="0.0" izz="0.34797641"/>
        <mass value="4.7942845677E1"/>
        <origin rpy="-0.0 0.0 -0.0" xyz="0.0 0.0 0.0"/>
      </inertial>
      <visual>
        <geometry>
          <mesh filename="package://kuka_quantec_support/meshes/kr210_r3100_2/visual/link_4.stl"/>
        </geometry>
        <origin rpy="-0.0 0.0 -0.0" xyz="0.0 0.0 0.0"/>
      </visual>
    </link>
    <link name="${prefix}link_5">
      <collision>
        <geometry>
          <mesh filename="package://kuka_quantec_support/meshes/kr210_r3100_2/collision/link_5.stl"/>
        </geometry>
        <origin rpy="-0.0 0.0 -0.0" xyz="0.0 0.0 0.0"/>
      </collision>
      <inertial>
        <inertia ixx="0.03694113" ixy="0.0" ixz="0.0" iyy="0.03695315" iyz="0.0" izz="0.048251"/>
        <mass value="2.3687644624E1"/>
        <origin rpy="-0.0 0.0 -0.0" xyz="0.0 0.0 0.0"/>
      </inertial>
      <visual>
        <geometry>
          <mesh filename="package://kuka_quantec_support/meshes/kr210_r3100_2/visual/link_5.stl"/>
        </geometry>
        <origin rpy="-0.0 0.0 -0.0" xyz="0.0 0.0 0.0"/>
      </visual>
    </link>
    <link name="${prefix}link_6">
      <collision>
        <geometry>
          <mesh filename="package://kuka_quantec_support/meshes/kr210_r3100_2/collision/link_6.stl"/>
        </geometry>
        <origin rpy="-0.0 0.0 -0.0" xyz="0.0 0.0 0.0"/>
      </collision>
      <inertial>
        <inertia ixx="0.03694113" ixy="0.0" ixz="0.0" iyy="0.03695315" iyz="0.0" izz="0.048251"/>
        <mass value="6.6E0"/>
        <origin rpy="-0.0 0.0 -0.0" xyz="0.0 0.0 0.0"/>
      </inertial>
      <visual>
        <geometry>
          <mesh filename="package://kuka_quantec_support/meshes/kr210_r3100_2/visual/link_6.stl"/>
        </geometry>
        <origin rpy="-0.0 0.0 -0.0" xyz="0.0 0.0 0.0"/>
      </visual>
    </link>

    <joint name="${prefix}base_link-base_link_inertia" type="fixed">
      <parent link="${prefix}base_link" />
      <child link="${prefix}base_link_inertia" />
      <origin xyz="0 0 0" rpy="0 0 0" />
    </joint>
    <joint name="${prefix}joint_1" type="revolute">
      <axis xyz="0.0 0.0 1.0"/>
      <child link="${prefix}link_1"/>
      <limit effort="7290" lower="-3.2288591161895095E0" upper="3.2288591161895095E0" velocity="${radians(105)}"/>
      <origin rpy="-3.141592653589793 0.0 -0.0" xyz="0.0 0.0 0.0"/>
      <parent link="${prefix}base_link_inertia"/>
    </joint>
    <joint name="${prefix}joint_2" type="revolute">
      <axis xyz="0.0 0.0 1.0"/>
      <child link="${prefix}link_2"/>
      <limit effort="8910" lower="-2.443460952792061E0" upper="-8.726646259971647E-2" velocity="${radians(94)}"/>
      <origin rpy="1.5707963267948963 0.0 -0.0" xyz="0.33 0.0 -0.645"/>
      <parent link="${prefix}link_1"/>
    </joint>
    <joint name="${prefix}joint_3" type="revolute">
      <axis xyz="0.0 0.0 1.0"/>
      <child link="${prefix}link_3"/>
      <limit effort="7251.2876" lower="-2.0943951023931953E0" upper="2.9321531433504737E0" velocity="${radians(100)}"/>
      <origin rpy="0.0 0.0 -1.5707963267948963" xyz="1.35 0.0 0.0"/>
      <parent link="${prefix}link_2"/>
    </joint>
    <joint name="${prefix}joint_4" type="revolute">
      <axis xyz="0.0 0.0 1.0"/>
      <child link="${prefix}link_4"/>
      <limit effort="2356.12598" lower="-6.1086523819801535E0" upper="6.1086523819801535E0" velocity="${radians(136)}"/>
      <origin rpy="1.5707963267948963 0.0 -0.0" xyz="0.115 0.0 0.0"/>
      <parent link="${prefix}link_3"/>
    </joint>
    <joint name="${prefix}joint_5" type="revolute">
      <axis xyz="0.0 0.0 1.0"/>
      <child link="${prefix}link_5"/>
      <limit effort="2358.44531" lower="-2.138028333693054E0" upper="2.138028333693054E0" velocity="${radians(129)}"/>
      <origin rpy="-1.5707963267948963 0.0 -0.0" xyz="0.0 0.0 -1.42"/>
      <parent link="${prefix}link_4"/>
    </joint>
    <joint name="${prefix}joint_6" type="revolute">
      <axis xyz="0.0 0.0 1.0"/>
      <child link="${prefix}link_6"/>
      <limit effort="1508.75476" lower="-6.1086523819801535E0" upper="6.1086523819801535E0" velocity="${radians(206)}"/>
      <origin rpy="1.5707963267948963 0.0 -0.0" xyz="0.0 0.0 0.0"/>
      <parent link="${prefix}link_5"/>
    </joint>

    <!-- ROS-Industrial 'base' frame - equivalent of 'KUKA ROBROOT'-->
    <link name="${prefix}base" />
    <joint name="${prefix}base_link-base" type="fixed">
      <origin xyz="0 0 0" rpy="0 0 0"/>
      <parent link="${prefix}base_link"/>
      <child link="${prefix}base"/>
    </joint>

    <!-- ROS-Industrial 'flange' frame - attachment point for EEF models -->
    <link name="${prefix}flange" />
    <joint name="${prefix}link6-flange" type="fixed">
      <child link="${prefix}flange" />
      <origin rpy="0 ${pi/2} -0.0" xyz="0.0 0.0 -0.240" />
      <parent link="${prefix}link_6" />
    </joint>

    <!-- ROS-Industrial 'tool0' frame - all-zeros tool frame -->
    <link name="${prefix}tool0" />
    <joint name="${prefix}link6-tool0" type="fixed">
      <child link="${prefix}tool0" />
      <origin rpy="0 ${pi} -0.0" xyz="0.0 0.0 -0.240" />
      <parent link="${prefix}link_6" />
    </joint>
  </xacro:macro>
</robot>
