<?xml version="1.0"?>
<robot xmlns:xacro="http://wiki.ros.org/xacro">
  <xacro:macro name="kuka_kr210_r2700_2_robot" params="prefix package_name *origin">
    <!-- links - main serial chain -->
    <link name="world"/>
    <link name="${prefix}base_link">
      <collision>
        <geometry>
          <mesh filename="package://${package_name}/meshes/kr210_r2700_2/collision/base_link.stl"/>
        </geometry>
        <origin rpy="-0.0 0.0 -0.0" xyz="0.0 0.0 0.0"/>
      </collision>
      <inertial>
        <inertia ixx="12.8309" ixy="0.0" ixz="0.0" iyy="9.012" iyz="0.0" izz="14.2959"/>
        <mass value="2.2596E2"/>
        <origin rpy="-0.050860639732366764 -0.0019879300180215415 1.5231488382154512" xyz="-0.0594893 0.0021560000000000004 0.2032507"/>
      </inertial>
      <visual>
        <geometry>
          <mesh filename="package://${package_name}/meshes/kr210_r2700_2/visual/base_link.stl"/>
        </geometry>
        <origin rpy="-0.0 0.0 -0.0" xyz="0.0 0.0 0.0"/>
      </visual>
    </link>
    <link name="${prefix}link_1">
      <collision>
        <geometry>
          <mesh filename="package://${package_name}/meshes/kr210_r2700_2/collision/link_1.stl"/>
        </geometry>
        <origin rpy="-0.0 0.0 -0.0" xyz="0.0 0.0 0.0"/>
      </collision>
      <inertial>
        <inertia ixx="13.2088588047575" ixy="0.0" ixz="0.0" iyy="31.4949853249961" iyz="0.0" izz="33.8838908182464"/>
        <mass value="3.6307E2"/>
        <origin rpy="1.8661968490595335 0.10258164628689437 -0.21632411420056308" xyz="0.0287871760266615 0.011875249400942 -0.23402828104773202"/>
      </inertial>
      <visual>
        <geometry>
          <mesh filename="package://${package_name}/meshes/kr210_r2700_2/visual/link_1.stl"/>
        </geometry>
        <origin rpy="-0.0 0.0 -0.0" xyz="0.0 0.0 0.0"/>
      </visual>
    </link>
    <link name="${prefix}link_2">
      <collision>
        <geometry>
          <mesh filename="package://${package_name}/meshes/kr210_r2700_2/collision/link_2.stl"/>
        </geometry>
        <origin rpy="-0.0 0.0 -0.0" xyz="0.0 0.0 0.0"/>
      </collision>
      <inertial>
        <inertia ixx="57.7957098112911" ixy="0.0" ixz="0.0" iyy="5.63272995683345" iyz="0.0" izz="58.559845591006"/>
        <mass value="2.3206E2"/>
        <origin rpy="-2.820395530490072 -1.218114484700482 1.2776348095029473" xyz="0.486870981642679 -0.00190295613203482 -0.11763677497199"/>
      </inertial>
      <visual>
        <geometry>
          <mesh filename="package://${package_name}/meshes/kr210_r2700_2/visual/link_2.stl"/>
        </geometry>
        <origin rpy="-0.0 0.0 -0.0" xyz="0.0 0.0 0.0"/>
      </visual>
    </link>
    <link name="${prefix}link_3">
      <collision>
        <geometry>
          <mesh filename="package://${package_name}/meshes/kr210_r2700_2/collision/link_3.stl"/>
        </geometry>
        <origin rpy="-0.0 0.0 -0.0" xyz="0.0 0.0 0.0"/>
      </collision>
      <inertial>
        <inertia ixx="3.46995402943128" ixy="0.0" ixz="0.0" iyy="21.1713007283949" iyz="0.0" izz="22.2067749058774"/>
        <mass value="1.9033E2"/>
        <origin rpy="2.182263605188562 -0.06560775132626494 -0.05349640342552061" xyz="0.17377229023275398 -0.07596253874848949 0.136185412704251"/>
      </inertial>
      <visual>
        <geometry>
          <mesh filename="package://${package_name}/meshes/kr210_r2700_2/visual/link_3.stl"/>
        </geometry>
        <origin rpy="-0.0 0.0 -0.0" xyz="0.0 0.0 0.0"/>
      </visual>
    </link>
    <link name="${prefix}link_4">
      <collision>
        <geometry>
          <mesh filename="package://${package_name}/meshes/kr210_r2700_2/collision/link_4.stl"/>
        </geometry>
        <origin rpy="-0.0 0.0 -0.0" xyz="0.0 0.0 0.0"/>
      </collision>
      <inertial>
        <inertia ixx="0.161324366141546" ixy="0.0" ixz="0.0" iyy="1.3645139545175" iyz="0.0" izz="1.39158127634524"/>
        <mass value="4.2411794929E1"/>
        <origin rpy="1.5711454552070345 -1.4368320268822927 -1.5712071247684845" xyz="-7.5764465140740704E-6 0.0192023882938968 -0.197888748752496"/>
      </inertial>
      <visual>
        <geometry>
          <mesh filename="package://${package_name}/meshes/kr210_r2700_2/visual/link_4.stl"/>
        </geometry>
        <origin rpy="-0.0 0.0 -0.0" xyz="0.0 0.0 0.0"/>
      </visual>
    </link>
    <link name="${prefix}link_5">
      <collision>
        <geometry>
          <mesh filename="package://${package_name}/meshes/kr210_r2700_2/collision/link_5.stl"/>
        </geometry>
        <origin rpy="-0.0 0.0 -0.0" xyz="0.0 0.0 0.0"/>
      </collision>
      <inertial>
        <inertia ixx="0.200111908543801" ixy="0.0" ixz="0.0" iyy="0.120553626775201" iyz="0.0" izz="0.220956494925724"/>
        <mass value="1.6991732133E1"/>
        <origin rpy="1.5704759351872302 -0.8762558401259876 -0.0022796281329216955" xyz="0.062235569792816796 3.0314811620972E-4 -0.0657532427101687"/>
      </inertial>
      <visual>
        <geometry>
          <mesh filename="package://${package_name}/meshes/kr210_r2700_2/visual/link_5.stl"/>
        </geometry>
        <origin rpy="-0.0 0.0 -0.0" xyz="0.0 0.0 0.0"/>
      </visual>
    </link>
    <link name="${prefix}link_6">
      <collision>
        <geometry>
          <mesh filename="package://${package_name}/meshes/kr210_r2700_2/collision/link_6.stl"/>
        </geometry>
        <origin rpy="-0.0 0.0 -0.0" xyz="0.0 0.0 0.0"/>
      </collision>
      <inertial>
        <inertia ixx="0.0114565" ixy="0.0" ixz="0.0" iyy="0.0114565" iyz="0.0" izz="0.014535"/>
        <mass value="6.6E0"/>
        <origin rpy="0.0 -0.0 0.0" xyz="0.0 0.0 -0.006500000000000001"/>
      </inertial>
      <visual>
        <geometry>
          <mesh filename="package://${package_name}/meshes/kr210_r2700_2/visual/link_6.stl"/>
        </geometry>
        <origin rpy="-0.0 0.0 -0.0" xyz="0.0 0.0 0.0"/>
      </visual>
    </link>
    <joint name="${prefix}world-base_link" type="fixed">
      <parent link="world"/>
      <child link="${prefix}base_link"/>
      <xacro:insert_block name="origin"/>
    </joint>
    <joint name="${prefix}joint_1" type="revolute">
      <axis xyz="0.0 0.0 1.0"/>
      <child link="${prefix}link_1"/>
      <limit effort="7290" lower="-3.2288591161895095E0" upper="3.2288591161895095E0" velocity="2.0384"/>
      <origin rpy="-3.141592653589793 0.0 -0.0" xyz="0.0 0.0 0.0"/>
      <parent link="${prefix}base_link"/>
    </joint>
    <joint name="${prefix}joint_2" type="revolute">
      <axis xyz="0.0 0.0 1.0"/>
      <child link="${prefix}link_2"/>
      <limit effort="8910" lower="-2.443460952792061E0" upper="-8.726646259971647E-2" velocity="1.9451"/>
      <origin rpy="1.5707963267948963 0.0 -0.0" xyz="0.33 0.0 -0.645"/>
      <parent link="${prefix}link_1"/>
    </joint>
    <joint name="${prefix}joint_3" type="revolute">
      <axis xyz="0.0 0.0 1.0"/>
      <child link="${prefix}link_3"/>
      <limit effort="6988.84717" lower="-2.0943951023931953E0" upper="2.9321531433504737E0" velocity="${radians(112)}"/>
      <origin rpy="0.0 0.0 -1.5707963267948963" xyz="1.15 0.0 0.0"/>
      <parent link="${prefix}link_2"/>
    </joint>
    <joint name="${prefix}joint_4" type="revolute">
      <axis xyz="0.0 0.0 1.0"/>
      <child link="${prefix}link_4"/>
      <limit effort="2274.29199" lower="-6.1086523819801535E0" upper="6.1086523819801535E0" velocity="${radians(179)}"/>
      <origin rpy="1.5707963267948963 0.0 -0.0" xyz="0.115 0.0 0.0"/>
      <parent link="${prefix}link_3"/>
    </joint>
    <joint name="${prefix}joint_5" type="revolute">
      <axis xyz="0.0 0.0 1.0"/>
      <child link="${prefix}link_5"/>
      <limit effort="1398.30298" lower="-2.181661564992912E0" upper="2.181661564992912E0" velocity="${radians(172)}"/>
      <origin rpy="-1.5707963267948963 0.0 -0.0" xyz="0.0 0.0 -1.22"/>
      <parent link="${prefix}link_4"/>
    </joint>
    <joint name="${prefix}joint_6" type="revolute">
      <axis xyz="0.0 0.0 1.0"/>
      <child link="${prefix}link_6"/>
      <limit effort="781.554626" lower="-6.1086523819801535E0" upper="6.1086523819801535E0" velocity="${radians(220)}"/>
      <origin rpy="1.5707963267948963 0.0 -0.0" xyz="0.0 0.0 0.0"/>
      <parent link="${prefix}link_5"/>
    </joint>
    <!-- ROS-Industrial 'base' frame - equivalent of 'KUKA ROBROOT'-->
    <link name="${prefix}base"/>
    <joint name="${prefix}base_link-base" type="fixed">
      <origin xyz="0 0 0" rpy="0 0 0"/>
      <parent link="${prefix}base_link"/>
      <child link="${prefix}base"/>
    </joint>
    <!-- ROS-Industrial 'flange' frame - attachment point for EEF models -->
    <link name="${prefix}flange"/>
    <joint name="${prefix}link6-flange" type="fixed">
      <child link="${prefix}flange"/>
      <origin rpy="0 ${pi/2} -0.0" xyz="0.0 0.0 -0.215"/>
      <parent link="${prefix}link_6"/>
    </joint>
    <!-- ROS-Industrial 'tool0' frame - all-zeros tool frame -->
    <link name="${prefix}tool0"/>
    <joint name="${prefix}link6-tool0" type="fixed">
      <child link="${prefix}tool0"/>
      <origin rpy="0 ${pi} -0.0" xyz="0.0 0.0 -0.215"/>
      <parent link="${prefix}link_6"/>
    </joint>
  </xacro:macro>
</robot>
