<?xml version="1.0" encoding="UTF-8"?>
<robot xmlns:xacro="http://www.ros.org/wiki/xacro" name="kr240_r2900_2">
  <xacro:macro name="kuka_kr240_r2900_2_robot" params="prefix package_name">
    <link name="${prefix}base"/>
    <link name="${prefix}base_link">
      <collision>
        <geometry>
          <mesh filename="package://${package_name}/meshes/kr240_r2900_2/collision/base_link.stl"/>
        </geometry>
        <origin rpy="0.0 -0.0 0.0" xyz="0.0 0.0 0.0"/>
      </collision>
      <inertial>
        <inertia ixx="12.830880390826952" ixy="0.0" ixz="0.0" iyy="9.011969895031742" iyz="0.0" izz="14.295886015581125"/>
        <mass value="2.2596E2"/>
        <origin rpy="-0.05086013141183935 -0.0019883389878401834 1.5231487443995264" xyz="-0.05948933351035582 0.002155950610727567 0.20325069304301646"/>
      </inertial>
      <visual>
        <geometry>
          <mesh filename="package://${package_name}/meshes/kr240_r2900_2/visual/base_link.dae"/>
        </geometry>
        <origin rpy="0.0 -0.0 0.0" xyz="0.0 0.0 0.0"/>
      </visual>
    </link>
    <link name="${prefix}flange"/>
    <link name="${prefix}link_1">
      <collision>
        <geometry>
          <mesh filename="package://${package_name}/meshes/kr240_r2900_2/collision/link_1.stl"/>
        </geometry>
        <origin rpy="-3.141592653589793 0.0 -0.0" xyz="0.0 -3.742520618194312e-17 0.30560000000000004"/>
      </collision>
      <inertial>
        <inertia ixx="31.786315571363236" ixy="0.0" ixz="0.0" iyy="13.331031863287905" iyz="0.0" izz="34.18067231472547"/>
        <mass value="3.6737E2"/>
        <origin rpy="-0.3511974418307095 -1.2748494702775004 -1.4514723788195052" xyz="0.02826300460026675 0.011134569507580913 -0.23533673952690748"/>
      </inertial>
      <visual>
        <geometry>
          <mesh filename="package://${package_name}/meshes/kr240_r2900_2/visual/link_1.dae"/>
        </geometry>
        <origin rpy="-3.141592653589793 0.0 -0.0" xyz="0.0 -3.742520618194312e-17 0.30560000000000004"/>
      </visual>
    </link>
    <link name="${prefix}link_2">
      <collision>
        <geometry>
          <mesh filename="package://${package_name}/meshes/kr240_r2900_2/collision/link_2.stl"/>
        </geometry>
        <origin rpy="1.5707963267948968 -0.0 1.5707963267948966" xyz="-0.645 -0.32999999999999996 0.07200000000000009"/>
      </collision>
      <inertial>
        <inertia ixx="6.111566329697311" ixy="0.0" ixz="0.0" iyy="82.75093024358235" iyz="0.0" izz="83.25859671643981"/>
        <mass value="2.5056E2"/>
        <origin rpy="0.537627734526058 0.09067448308201616 0.007191247120022791" xyz="0.5778711685823756 -0.00138469827586207 -0.12557167943805878"/>
      </inertial>
      <visual>
        <geometry>
          <mesh filename="package://${package_name}/meshes/kr240_r2900_2/visual/link_2.dae"/>
        </geometry>
        <origin rpy="1.5707963267948968 -0.0 1.5707963267948966" xyz="-0.645 -0.32999999999999996 0.07200000000000009"/>
      </visual>
    </link>
    <link name="${prefix}link_3">
      <collision>
        <geometry>
          <mesh filename="package://${package_name}/meshes/kr240_r2900_2/collision/link_3.stl"/>
        </geometry>
        <origin rpy="1.5707963267948968 -0.0 -0.0" xyz="-0.33000000000000007 1.995 0.1750000000000001"/>
      </collision>
      <inertial>
        <inertia ixx="3.5116656416771987" ixy="0.0" ixz="0.0" iyy="21.23693820622933" iyz="0.0" izz="22.256837418726807"/>
        <mass value="1.9153E2"/>
        <origin rpy="2.1669667459514166 -0.06384171041203489 -0.0541724555106102" xyz="0.17268469691432153 -0.0754866078421135 0.13713156998903567"/>
      </inertial>
      <visual>
        <geometry>
          <mesh filename="package://${package_name}/meshes/kr240_r2900_2/visual/link_3.dae"/>
        </geometry>
        <origin rpy="1.5707963267948968 -0.0 -0.0" xyz="-0.33000000000000007 1.995 0.1750000000000001"/>
      </visual>
    </link>
    <link name="${prefix}link_4">
      <collision>
        <geometry>
          <mesh filename="package://${package_name}/meshes/kr240_r2900_2/collision/link_4.stl"/>
        </geometry>
        <origin rpy="1.8369701987210297e-16 1.5707963267948966 0.0" xyz="-2.11 1.2451666974470345e-17 1.158"/>
      </collision>
      <inertial>
        <inertia ixx="0.20114801831278567" ixy="0.0" ixz="0.0" iyy="1.6156024516095278" iyz="0.0" izz="1.6404174473993862"/>
        <mass value="4.7942845677E1"/>
        <origin rpy="1.5709922511064425 -1.3912820307912837 -1.5710550346492322" xyz="-8.827699851665032E-6 0.030038038468557137 -0.22035014882022413"/>
      </inertial>
      <visual>
        <geometry>
          <mesh filename="package://${package_name}/meshes/kr240_r2900_2/visual/link_4.dae"/>
        </geometry>
        <origin rpy="1.8369701987210297e-16 1.5707963267948966 0.0" xyz="-2.11 1.2451666974470345e-17 1.158"/>
      </visual>
    </link>
    <link name="${prefix}link_5">
      <collision>
        <geometry>
          <mesh filename="package://${package_name}/meshes/kr240_r2900_2/collision/link_5.stl"/>
        </geometry>
        <origin rpy="1.5707963267948968 -3.749399456654644e-33 -6.123233995736766e-17" xyz="-1.55 2.11 -0.1065"/>
      </collision>
      <inertial>
        <inertia ixx="0.3430603374426301" ixy="0.0" ixz="0.0" iyy="0.1968927981343499" iyz="0.0" izz="0.34797640983422673"/>
        <mass value="2.3687644624E1"/>
        <origin rpy="1.6224506086845343 -0.9319967320369545 -0.06488528019058373" xyz="0.062409087507206966 2.1098685344562437E-4 -0.06405788459182832"/>
      </inertial>
      <visual>
        <geometry>
          <mesh filename="package://${package_name}/meshes/kr240_r2900_2/visual/link_5.dae"/>
        </geometry>
        <origin rpy="1.5707963267948968 -3.749399456654644e-33 -6.123233995736766e-17" xyz="-1.55 2.11 -0.1065"/>
      </visual>
    </link>
    <link name="${prefix}link_6">
      <collision>
        <geometry>
          <mesh filename="package://${package_name}/meshes/kr240_r2900_2/collision/link_6.stl"/>
        </geometry>
        <origin rpy="1.2246467991473532e-16 1.5707963267948966 0.0" xyz="-2.11 -1.233749536060084e-16 1.7194999999999998"/>
      </collision>
      <inertial>
        <inertia ixx="0.03694112716090631" ixy="0.0" ixz="0.0" iyy="0.03695315329552191" iyz="0.0" izz="0.04825100132618141"/>
        <mass value="1.2245718539E1"/>
        <origin rpy="1.0758644105165148E-4 -9.812464461473682E-5 -0.03310542818381573" xyz="4.595822618513483E-6 -5.5908945912619675E-6 -0.02543618981825055"/>
      </inertial>
      <visual>
        <geometry>
          <mesh filename="package://${package_name}/meshes/kr240_r2900_2/visual/link_6.dae"/>
        </geometry>
        <origin rpy="1.2246467991473532e-16 1.5707963267948966 0.0" xyz="-2.11 -1.233749536060084e-16 1.7194999999999998"/>
      </visual>
    </link>
    <link name="${prefix}tool0"/>
    <joint name="${prefix}base_link-base" type="fixed">
      <child link="${prefix}base"/>
      <parent link="${prefix}base_link"/>
    </joint>
    <joint name="${prefix}joint_1" type="revolute">
      <axis xyz="0.0 0.0 1.0"/>
      <child link="${prefix}link_1"/>
      <limit effort="7.29E3" lower="-3.2288591125E0" upper="3.2288591125E0" velocity="1.7976891295541595E0"/>
      <origin rpy="3.141592653589793 -0.0 0.0" xyz="0.0 0.0 0.30560000000000004"/>
      <parent link="${prefix}base_link"/>
    </joint>
    <joint name="${prefix}joint_2" type="revolute">
      <axis xyz="0.0 0.0 1.0"/>
      <child link="${prefix}link_2"/>
      <limit effort="9.2399999999999982E3" lower="-2.44346095E0" upper="-8.72664625E-2" velocity="1.6406094968746698E0"/>
      <origin rpy="1.5707963267948966 -0.0 0.0" xyz="0.33 0.07200000000000001 -0.3394"/>
      <parent link="${prefix}link_1"/>
    </joint>
    <joint name="${prefix}joint_3" type="revolute">
      <axis xyz="0.0 0.0 1.0"/>
      <child link="${prefix}link_3"/>
      <limit effort="7.29542236549771E3" lower="-2.0943951E0" upper="2.93215314E0" velocity="1.7453292519943295E0"/>
      <origin rpy="0.0 -0.0 0.0" xyz="1.35 0.0 -0.10300000000000001"/>
      <parent link="${prefix}link_2"/>
    </joint>
    <joint name="${prefix}joint_4" type="revolute">
      <axis xyz="0.0 0.0 1.0"/>
      <child link="${prefix}link_4"/>
      <limit effort="2.3237103673905E3" lower="-6.108652375E0" upper="6.108652375E0" velocity="2.9670597283903604E0"/>
      <origin rpy="1.5707963267948966 -0.0 -1.5707963267948966" xyz="0.8280000000000001 -0.115 0.17500000000000002"/>
      <parent link="${prefix}link_3"/>
    </joint>
    <joint name="${prefix}joint_5" type="revolute">
      <axis xyz="0.0 0.0 1.0"/>
      <child link="${prefix}link_5"/>
      <limit effort="2.32603308821414E3" lower="-2.13802833125E0" upper="2.13802833125E0" velocity="2.2514747350726849E0"/>
      <origin rpy="0.0 1.5707963267948966 1.5707963267948966" xyz="0.0 0.1065 -0.392"/>
      <parent link="${prefix}link_4"/>
    </joint>
    <joint name="${prefix}joint_6" type="revolute">
      <axis xyz="0.0 0.0 1.0"/>
      <child link="${prefix}link_6"/>
      <limit effort="1.49286251041991E3" lower="-6.108652375E0" upper="6.108652375E0" velocity="3.595378259108319E0"/>
      <origin rpy="1.5707963267948966 -0.0 -1.5707963267948966" xyz="0.1695 0.0 -0.1065"/>
      <parent link="${prefix}link_5"/>
    </joint>
    <joint name="${prefix}link6-flange" type="fixed">
      <child link="${prefix}flange"/>
      <origin rpy="0.0 1.5707963267948966 0.0" xyz="0.0 0.0 -0.07050000000000001"/>
      <parent link="${prefix}link_6"/>
    </joint>
    <joint name="${prefix}link6-tool0" type="fixed">
      <child link="${prefix}tool0"/>
      <origin rpy="3.141592653589793 1.2246467991473532E-16 3.141592653589793" xyz="0.0 0.0 -0.07050000000000001"/>
      <parent link="${prefix}link_6"/>
    </joint>
  </xacro:macro>
</robot>
