<?xml version="1.0" encoding="UTF-8"?>
<robot xmlns:xacro="http://www.ros.org/wiki/xacro" name="kr300_r2700_2">
  <xacro:macro name="kuka_kr300_r2700_2_robot" params="prefix package_name">
    <link name="${prefix}base"/>
    <link name="${prefix}base_link">
      <collision>
        <geometry>
          <mesh filename="package://${package_name}/meshes/kr300_r2700_2/collision/base_link.stl"/>
        </geometry>
        <origin rpy="0.0 -0.0 0.0" xyz="0.0 0.0 0.0"/>
      </collision>
      <inertial>
        <inertia ixx="0.0" ixy="0.0" ixz="0.0" iyy="0.0" iyz="0.0" izz="0.0"/>
        <mass value="2.2596E2"/>
        <origin rpy="0.0 -0.0 0.0" xyz="0.0 0.0 0.0"/>
      </inertial>
      <visual>
        <geometry>
          <mesh filename="package://${package_name}/meshes/kr300_r2700_2/visual/base_link.dae"/>
        </geometry>
        <origin rpy="0.0 -0.0 0.0" xyz="0.0 0.0 0.0"/>
      </visual>
    </link>
    <link name="${prefix}flange"/>
    <link name="${prefix}link_1">
      <collision>
        <geometry>
          <mesh filename="package://${package_name}/meshes/kr300_r2700_2/collision/link_1.stl"/>
        </geometry>
        <origin rpy="-3.141592653589793 0.0 -0.0" xyz="0.0 -3.742520618194312e-17 0.30560000000000004"/>
      </collision>
      <inertial>
        <inertia ixx="31.7863155713632" ixy="0.0" ixz="0.0" iyy="13.3310318632879" iyz="0.0" izz="34.1806723147255"/>
        <mass value="3.6737E2"/>
        <origin rpy="-0.3511974418307098 -1.2748494702775013 -1.451472378819504" xyz="0.0282630046002668 0.011134569507580901 -0.235336739526907"/>
      </inertial>
      <visual>
        <geometry>
          <mesh filename="package://${package_name}/meshes/kr300_r2700_2/visual/link_1.dae"/>
        </geometry>
        <origin rpy="-3.141592653589793 0.0 -0.0" xyz="0.0 -3.742520618194312e-17 0.30560000000000004"/>
      </visual>
    </link>
    <link name="${prefix}link_2">
      <collision>
        <geometry>
          <mesh filename="package://${package_name}/meshes/kr300_r2700_2/collision/link_2.stl"/>
        </geometry>
        <origin rpy="1.5707963267948968 -0.0 1.5707963267948966" xyz="-0.645 -0.32999999999999996 0.07200000000000009"/>
      </collision>
      <inertial>
        <inertia ixx="57.7957098112911" ixy="0.0" ixz="0.0" iyy="5.63272995683346" iyz="0.0" izz="58.559845591006"/>
        <mass value="2.3206E2"/>
        <origin rpy="-2.820395530490072 -1.2181144847004783 1.2776348095029488" xyz="0.486870981642679 -0.00190295613203482 -0.11763677497199"/>
      </inertial>
      <visual>
        <geometry>
          <mesh filename="package://${package_name}/meshes/kr300_r2700_2/visual/link_2.dae"/>
        </geometry>
        <origin rpy="1.5707963267948968 -0.0 1.5707963267948966" xyz="-0.645 -0.32999999999999996 0.07200000000000009"/>
      </visual>
    </link>
    <link name="${prefix}link_3">
      <collision>
        <geometry>
          <mesh filename="package://${package_name}/meshes/kr300_r2700_2/collision/link_3.stl"/>
        </geometry>
        <origin rpy="1.5707963267948968 -0.0 -0.0" xyz="-0.33000000000000007 1.7950000000000002 0.17500000000000007"/>
      </collision>
      <inertial>
        <inertia ixx="3.5116656416772" ixy="0.0" ixz="0.0" iyy="21.2369382062293" iyz="0.0" izz="22.2568374187268"/>
        <mass value="1.9153E2"/>
        <origin rpy="2.1669667459514192 -0.06384171041203483 -0.05417245551061014" xyz="0.172684696914322 -0.0754866078421135 0.137131569989036"/>
      </inertial>
      <visual>
        <geometry>
          <mesh filename="package://${package_name}/meshes/kr300_r2700_2/visual/link_3.dae"/>
        </geometry>
        <origin rpy="1.5707963267948968 -0.0 -0.0" xyz="-0.33000000000000007 1.7950000000000002 0.17500000000000007"/>
      </visual>
    </link>
    <link name="${prefix}link_4">
      <collision>
        <geometry>
          <mesh filename="package://${package_name}/meshes/kr300_r2700_2/collision/link_4.stl"/>
        </geometry>
        <origin rpy="1.8369701987210297e-16 1.5707963267948966 0.0" xyz="-1.9100000000000001 2.0519898299688948e-19 1.158"/>
      </collision>
      <inertial>
        <inertia ixx="0.201148018312786" ixy="0.0" ixz="0.0" iyy="1.61560245160953" iyz="0.0" izz="1.64041744739939"/>
        <mass value="4.7942845677E1"/>
        <origin rpy="1.570992251106443 -1.3912820307912874 -1.5710550346492322" xyz="-8.82769985166503E-6 0.030038038468557102 -0.22035014882022402"/>
      </inertial>
      <visual>
        <geometry>
          <mesh filename="package://${package_name}/meshes/kr300_r2700_2/visual/link_4.dae"/>
        </geometry>
        <origin rpy="1.8369701987210297e-16 1.5707963267948966 0.0" xyz="-1.9100000000000001 2.0519898299688948e-19 1.158"/>
      </visual>
    </link>
    <link name="${prefix}link_5">
      <collision>
        <geometry>
          <mesh filename="package://${package_name}/meshes/kr300_r2700_2/collision/link_5.stl"/>
        </geometry>
        <origin rpy="1.5707963267948968 -3.749399456654644e-33 -6.123233995736766e-17" xyz="-1.55 1.9100000000000001 -0.1065"/>
      </collision>
      <inertial>
        <inertia ixx="0.34306033744263" ixy="0.0" ixz="0.0" iyy="0.19689279813435" iyz="0.0" izz="0.347976409834227"/>
        <mass value="2.3687644624E1"/>
        <origin rpy="1.6224506086845345 -0.9319967320369543 -0.06488528019058366" xyz="0.062409087507207 2.1098685344562402E-4 -0.0640578845918283"/>
      </inertial>
      <visual>
        <geometry>
          <mesh filename="package://${package_name}/meshes/kr300_r2700_2/visual/link_5.dae"/>
        </geometry>
        <origin rpy="1.5707963267948968 -3.749399456654644e-33 -6.123233995736766e-17" xyz="-1.55 1.9100000000000001 -0.1065"/>
      </visual>
    </link>
    <link name="${prefix}link_6">
      <collision>
        <geometry>
          <mesh filename="package://${package_name}/meshes/kr300_r2700_2/collision/link_6.stl"/>
        </geometry>
        <origin rpy="1.2246467991473532e-16 1.5707963267948966 0.0" xyz="-1.9100000000000004 -1.233749536060084e-16 1.7194999999999998"/>
      </collision>
      <inertial>
        <inertia ixx="0.0369411271609063" ixy="0.0" ixz="0.0" iyy="0.0369531532955219" iyz="0.0" izz="0.0482510013261814"/>
        <mass value="1.2245718539E1"/>
        <origin rpy="1.0758644105165322E-4 -9.812464461473523E-5 -0.03310542818383201" xyz="4.5958226185134805E-6 -5.59089459126197E-6 -0.0254361898182505"/>
      </inertial>
      <visual>
        <geometry>
          <mesh filename="package://${package_name}/meshes/kr300_r2700_2/visual/link_6.dae"/>
        </geometry>
        <origin rpy="1.2246467991473532e-16 1.5707963267948966 0.0" xyz="-1.9100000000000004 -1.233749536060084e-16 1.7194999999999998"/>
      </visual>
    </link>
    <link name="${prefix}tool0"/>
    <joint name="${prefix}base_link-base" type="fixed">
      <child link="${prefix}base"/>
      <parent link="${prefix}base_link"/>
    </joint>
    <joint name="${prefix}joint_1" type="revolute">
      <axis xyz="0.0 0.0 1.0"/>
      <child link="${prefix}link_1"/>
      <limit effort="7.29E3" lower="-3.2288591125E0" upper="3.2288591125E0" velocity="1.83259571459405E0"/>
      <origin rpy="3.141592653589793 -0.0 0.0" xyz="0.0 0.0 0.30560000000000004"/>
      <parent link="${prefix}base_link"/>
    </joint>
    <joint name="${prefix}joint_2" type="revolute">
      <axis xyz="0.0 0.0 1.0"/>
      <child link="${prefix}link_2"/>
      <limit effort="9.60003E3" lower="-2.44346095E0" upper="-8.72664625E-2" velocity="1.76278254451427E0"/>
      <origin rpy="1.5707963267948966 -0.0 0.0" xyz="0.33 0.07200000000000001 -0.3394"/>
      <parent link="${prefix}link_1"/>
    </joint>
    <joint name="${prefix}joint_3" type="revolute">
      <axis xyz="0.0 0.0 1.0"/>
      <child link="${prefix}link_3"/>
      <limit effort="7.08714342281144E3" lower="-2.0943951E0" upper="2.93215314E0" velocity="1.86750229963393E0"/>
      <origin rpy="0.0 -0.0 0.0" xyz="1.1500000000000001 0.0 -0.10300000000000001"/>
      <parent link="${prefix}link_2"/>
    </joint>
    <joint name="${prefix}joint_4" type="revolute">
      <axis xyz="0.0 0.0 1.0"/>
      <child link="${prefix}link_4"/>
      <limit effort="2.25887888718356E3" lower="-6.108652375E0" upper="6.108652375E0" velocity="2.44346095279206E0"/>
      <origin rpy="1.5707963267948966 -0.0 -1.5707963267948966" xyz="0.8280000000000001 -0.115 0.17500000000000002"/>
      <parent link="${prefix}link_3"/>
    </joint>
    <joint name="${prefix}joint_5" type="revolute">
      <axis xyz="0.0 0.0 1.0"/>
      <child link="${prefix}link_5"/>
      <limit effort="2.26120660090655E3" lower="-2.13802833125E0" upper="2.13802833125E0" velocity="1.97222205475359E0"/>
      <origin rpy="0.0 1.5707963267948966 1.5707963267948966" xyz="0.0 0.1065 -0.392"/>
      <parent link="${prefix}link_4"/>
    </joint>
    <joint name="${prefix}joint_6" type="revolute">
      <axis xyz="0.0 0.0 1.0"/>
      <child link="${prefix}link_6"/>
      <limit effort="1.46107811041986E3" lower="-6.108652375E0" upper="6.108652375E0" velocity="3.14159265358979E0"/>
      <origin rpy="1.5707963267948966 -0.0 -1.5707963267948966" xyz="0.1695 0.0 -0.1065"/>
      <parent link="${prefix}link_5"/>
    </joint>
    <joint name="${prefix}link6-flange" type="fixed">
      <child link="${prefix}flange"/>
      <origin rpy="0.0 1.5707963267948966 0.0" xyz="0.0 0.0 -0.07050000000000001"/>
      <parent link="${prefix}link_6"/>
    </joint>
    <joint name="${prefix}link6-tool0" type="fixed">
      <child link="${prefix}tool0"/>
      <origin rpy="3.141592653589793 1.2246467991473532E-16 3.141592653589793" xyz="0.0 0.0 -0.07050000000000001"/>
      <parent link="${prefix}link_6"/>
    </joint>
  </xacro:macro>
</robot>
