<?xml version="1.0"?>
<robot xmlns:xacro="http://wiki.ros.org/xacro">
  <xacro:macro name="kuka_lbr_iiwa7" params="io_access">
  <ros2_control name="iiwa_hardware" type="system">
    <hardware>
      <plugin>kuka_sunrise::KUKAFRIHardwareInterface</plugin>
    </hardware>
    <!-- define joints and command/state interfaces for each joint -->
    <joint name="LBRiiwa7Joint1">
      <command_interface name="position">
        <param name="min">-1</param>
        <param name="max"> 1</param>
      </command_interface>
      <command_interface name="effort">
        <param name="min">-1</param>
        <param name="max"> 1</param>
      </command_interface>
      <state_interface name="position"/>
      <state_interface name="effort"/>
      <state_interface name="external_torque"/>
    </joint>
    <joint name="LBRiiwa7Joint2">
      <command_interface name="position">
        <param name="min">-1</param>
        <param name="max"> 1</param>
      </command_interface>
      <command_interface name="effort">
        <param name="min">-1</param>
        <param name="max"> 1</param>
      </command_interface>
      <state_interface name="position"/>
      <state_interface name="effort"/>
      <state_interface name="external_torque"/>
    </joint>
    <joint name="LBRiiwa7Joint3">
      <command_interface name="position">
        <param name="min">-1</param>
        <param name="max"> 1</param>
      </command_interface>
      <command_interface name="effort">
        <param name="min">-1</param>
        <param name="max"> 1</param>
      </command_interface>
      <state_interface name="position"/>
      <state_interface name="effort"/>
      <state_interface name="external_torque"/>
    </joint>
    <joint name="LBRiiwa7Joint4">
      <command_interface name="position">
        <param name="min">-1</param>
        <param name="max"> 1</param>
      </command_interface>
      <command_interface name="effort">
        <param name="min">-1</param>
        <param name="max"> 1</param>
      </command_interface>
      <state_interface name="position"/>
      <state_interface name="effort"/>
      <state_interface name="external_torque"/>
    </joint>
    <joint name="LBRiiwa7Joint5">
      <command_interface name="position">
        <param name="min">-1</param>
        <param name="max"> 1</param>
      </command_interface>
      <command_interface name="effort">
        <param name="min">-1</param>
        <param name="max"> 1</param>
      </command_interface>
      <state_interface name="position"/>
      <state_interface name="effort"/>
      <state_interface name="external_torque"/>
    </joint>
    <joint name="LBRiiwa7Joint6">
      <command_interface name="position">
        <param name="min">-1</param>
        <param name="max"> 1</param>
      </command_interface>
      <command_interface name="effort">
        <param name="min">-1</param>
        <param name="max"> 1</param>
      </command_interface>
      <state_interface name="position"/>
      <state_interface name="effort"/>
      <state_interface name="external_torque"/>
    </joint>
    <joint name="LBRiiwa7Joint7">
      <command_interface name="position">
        <param name="min">-1</param>
        <param name="max"> 1</param>
      </command_interface>
      <command_interface name="effort">
        <param name="min">-1</param>
        <param name="max"> 1</param>
      </command_interface>
      <state_interface name="position"/>
      <state_interface name="effort"/>
      <state_interface name="external_torque"/>
    </joint>
    <!-- TODO(Svastits): update GPIO list from config file-->
    <xacro:if value="${io_access}">
      <xacro:include filename="$(find kuka_sunrise)/config/gpio_config.xacro" />
      <xacro:fri_gpio_config/>
    </xacro:if>
    <xacro:unless value="${io_access}">
      <gpio name="gpio"/>
    </xacro:unless>
  </ros2_control>
  <gazebo>
    <plugin name="gazebo_ros2_control" filename="libgazebo_ros2_control.so">
      <robotNamespace>/lbriiwa7</robotNamespace>
      <robotSimType>gazebo_ros2_control/DefaultRobotHWSim</robotSimType>
      <parameters>$(find kuka_lbr_iiwa7_support)/config/lbriiwa7_control.yaml</parameters>
    </plugin>
  </gazebo>
  <gazebo reference="LBRiiwa7RobotBase">
    <selfCollide>true</selfCollide>
    <material>Gazebo/Orange</material>
  </gazebo>
  <gazebo reference="LBRiiwa7Axis1">
    <selfCollide>true</selfCollide>
    <material>Gazebo/Orange</material>
  </gazebo>
  <gazebo reference="LBRiiwa7Axis2">
    <selfCollide>true</selfCollide>
    <material>Gazebo/Orange</material>
  </gazebo>
  <gazebo reference="LBRiiwaAxis3">
    <selfCollide>true</selfCollide>
    <material>Gazebo/Orange</material>
  </gazebo>
  <gazebo reference="LBRiiwaAxis4">
    <selfCollide>true</selfCollide>
    <material>Gazebo/Orange</material>
  </gazebo>
  <gazebo reference="LBRiiwaAxis5">
    <selfCollide>true</selfCollide>
    <material>Gazebo/Orange</material>
  </gazebo>
  <gazebo reference="LBRiiwaAxis6">
    <selfCollide>true</selfCollide>
    <material>Gazebo/Orange</material>
  </gazebo>
  <gazebo reference="LBRiiwaAxis7">
    <selfCollide>true</selfCollide>
    <material>Gazebo/Orange</material>
  </gazebo>
  <link name="world"/>
  <link name="LBRiiwa7RobotBase">
    <visual>
      <geometry>
        <mesh filename="package://kuka_lbr_iiwa7_support/meshes/visual/iiwa_r820_link_0_hull_v0.1_iiwa_r820_link_0_hull.stl"/>
      </geometry>
      <origin rpy="-0.0 0.0 0.0" xyz="0.0 0.0 0.0"/>
    </visual>
    <collision>
      <origin rpy="-0.0 0.0 0.0" xyz="0.0 0.0 0.0"/>
      <geometry>
        <mesh filename="package://kuka_lbr_iiwa7_support/meshes/collision/iiwa_r820_link_0_collision_v0.1_iiwa_r820_link_0_collision.stl"/>
      </geometry>
    </collision>
    <inertial>
      <mass value="3.2832"/>
      <origin rpy="0 0 0" xyz="0.0 0.0 0.0"/>
      <inertia ixx="5.0E-4" ixy="0.0" ixz="0.0" iyy="5.0E-4" iyz="0.0" izz="5.0E-4"/>
    </inertial>
  </link>
  <link name="LBRiiwa7Axis1">
    <visual>
      <geometry>
        <mesh filename="package://kuka_lbr_iiwa7_support/meshes/visual/iiwa_r820_link_1_hull_v0.1_iiwa_r820_link_1_hull.stl"/>
      </geometry>
      <origin rpy="-0.0 0.0 0.0" xyz="0.0 0.0 0.0"/>
    </visual>
    <collision>
      <origin rpy="-0.0 0.0 0.0" xyz="0.0 0.0 0.0"/>
      <geometry>
        <mesh filename="package://kuka_lbr_iiwa7_support/meshes/collision/iiwa_r820_link_1_collision_v0.1_iiwa_r820_link_1_collision.stl"/>
      </geometry>
    </collision>
    <inertial>
      <mass value="6.495"/>
      <origin rpy="0 0 0" xyz="0.0 0.0 0.0"/>
      <inertia ixx="0.06907" ixy="0.0" ixz="0.0" iyy="0.0711" iyz="0.0" izz="0.02"/>
    </inertial>
  </link>
  <link name="LBRiiwa7Axis2">
    <visual>
      <geometry>
        <mesh filename="package://kuka_lbr_iiwa7_support/meshes/visual/iiwa_r820_link_2_hull_v0.1_iiwa_r820_link_2_hull.stl"/>
      </geometry>
      <origin rpy="-0.0 0.0 0.0" xyz="0.0 0.0 0.0"/>
    </visual>
    <collision>
      <origin rpy="-0.0 0.0 0.0" xyz="0.0 0.0 0.0"/>
      <geometry>
        <mesh filename="package://kuka_lbr_iiwa7_support/meshes/collision/iiwa_r820_link_2_collision_v0.1_iiwa_r820_link_2_collision.stl"/>
      </geometry>
    </collision>
    <inertial>
      <mass value="8.365"/>
      <origin rpy="0 0 0" xyz="0.0 0.0 0.0"/>
      <inertia ixx="0.08" ixy="0.0" ixz="0.0" iyy="0.08" iyz="0.0" izz="0.01"/>
    </inertial>
  </link>
  <link name="LBRiiwaAxis3">
    <visual>
      <geometry>
        <mesh filename="package://kuka_lbr_iiwa7_support/meshes/visual/iiwa_r820_link_3_hull_v0.1_iiwa_r820_link_3_hull.stl"/>
      </geometry>
      <origin rpy="-0.0 0.0 0.0" xyz="0.0 0.0 0.0"/>
    </visual>
    <collision>
      <origin rpy="-0.0 0.0 0.0" xyz="0.0 0.0 0.0"/>
      <geometry>
        <mesh filename="package://kuka_lbr_iiwa7_support/meshes/collision/iiwa_r820_link_3_collision_v0.1_iiwa_r820_link_3_collision.stl"/>
      </geometry>
    </collision>
    <inertial>
      <mass value="2.5697"/>
      <origin rpy="0 0 0" xyz="0.0 0.0 0.0"/>
      <inertia ixx="0.02" ixy="0.0" ixz="0.0" iyy="0.02" iyz="0.0" izz="0.06"/>
    </inertial>
  </link>
  <link name="LBRiiwaAxis4">
    <visual>
      <geometry>
        <mesh filename="package://kuka_lbr_iiwa7_support/meshes/visual/iiwa_r820_link_4_hull_v0.1_iiwa_r820_link_4_hull.stl"/>
      </geometry>
      <origin rpy="-0.0 0.0 0.0" xyz="0.0 0.0 0.0"/>
    </visual>
    <collision>
      <origin rpy="-0.0 0.0 0.0" xyz="0.0 0.0 0.0"/>
      <geometry>
        <mesh filename="package://kuka_lbr_iiwa7_support/meshes/collision/iiwa_r820_link_4_collision_v0.1_iiwa_r820_link_4_collision.stl"/>
      </geometry>
    </collision>
    <inertial>
      <mass value="5.41"/>
      <origin rpy="0 0 0" xyz="0.0 0.0 0.0"/>
      <inertia ixx="0.04" ixy="0.0" ixz="0.0" iyy="0.03" iyz="0.0" izz="0.01"/>
    </inertial>
  </link>
  <link name="LBRiiwaAxis5">
    <visual>
      <geometry>
        <mesh filename="package://kuka_lbr_iiwa7_support/meshes/visual/iiwa_r820_link_5_hull_v0.1_iiwa_r820_link_5_hull.stl"/>
      </geometry>
      <origin rpy="-0.0 0.0 0.0" xyz="0.0 0.0 0.0"/>
    </visual>
    <collision>
      <origin rpy="-0.0 0.0 0.0" xyz="0.0 0.0 0.0"/>
      <geometry>
        <mesh filename="package://kuka_lbr_iiwa7_support/meshes/collision/iiwa_r820_link_5_collision_v0.1_iiwa_r820_link_5_collision.stl"/>
      </geometry>
    </collision>
    <inertial>
      <mass value="1.867"/>
      <origin rpy="0 0 0" xyz="0.0 0.0 0.0"/>
      <inertia ixx="0.01" ixy="0.0" ixz="0.0" iyy="0.01" iyz="0.0" izz="0.01"/>
    </inertial>
  </link>
  <link name="LBRiiwaAxis6">
    <visual>
      <geometry>
        <mesh filename="package://kuka_lbr_iiwa7_support/meshes/visual/iiwa_r820_link_6_hull_v0.1_iiwa_r820_link_6_hull.stl"/>
      </geometry>
      <origin rpy="-0.0 0.0 0.0" xyz="0.0 0.0 0.0"/>
    </visual>
    <collision>
      <origin rpy="-0.0 0.0 0.0" xyz="0.0 0.0 0.0"/>
      <geometry>
        <mesh filename="package://kuka_lbr_iiwa7_support/meshes/collision/iiwa_r820_link_6_collision_v0.1_iiwa_r820_link_6_collision.stl"/>
      </geometry>
    </collision>
    <inertial>
      <mass value="2.458"/>
      <origin rpy="0 0 0" xyz="0.0 0.0 0.0"/>
      <inertia ixx="0.007" ixy="0.0" ixz="0.0" iyy="0.006" iyz="0.0" izz="0.005"/>
    </inertial>
  </link>
  <link name="LBRiiwaAxis7">
    <visual>
      <geometry>
        <mesh filename="package://kuka_lbr_iiwa7_support/meshes/visual/iiwa_r820_link_7_hull_v0.1_iiwa_r820_link_7_hull.stl"/>
      </geometry>
      <origin rpy="-0.0 0.0 0.0" xyz="0.0 0.0 0.0"/>
    </visual>
    <collision>
      <origin rpy="-0.0 0.0 0.0" xyz="0.0 0.0 0.0"/>
      <geometry>
        <mesh filename="package://kuka_lbr_iiwa7_support/meshes/collision/iiwa_r820_link_7_collision_v0.1_iiwa_r820_link_7_collision.stl"/>
      </geometry>
    </collision>
    <inertial>
      <mass value="0.627"/>
      <origin rpy="0 0 0" xyz="0.0 0.0 0.0"/>
      <inertia ixx="3.0E-4" ixy="0.0" ixz="0.0" iyy="3.0E-4" iyz="0.0" izz="5.0E-4"/>
    </inertial>
  </link>
  <link name="LBRiiwaFlange"></link>
  <joint name="LBRiiwa7RobotBaseJoint" type="fixed">
    <parent link="world"/>
    <child link="LBRiiwa7RobotBase"/>
  </joint>
  <joint name="LBRiiwa7Joint1" type="revolute">
    <parent link="LBRiiwa7RobotBase"/>
    <child link="LBRiiwa7Axis1"/>
    <origin rpy="-0.0 0.0 0.0" xyz="0.0 0.0 0.1375"/>
    <axis xyz="0.0 0.0 1.0"/>
    <limit effort="158.4" lower="-2.67035" upper="2.67035" velocity="6.283"/>
  </joint>
  <joint name="LBRiiwa7Joint2" type="revolute">
    <parent link="LBRiiwa7Axis1"/>
    <child link="LBRiiwa7Axis2"/>
    <origin rpy="-0.0 0.0 0.0" xyz="0.0 0.0 0.2025"/>
    <axis xyz="0.0 1.0 0.0"/>
    <limit effort="158.4" lower="-1.8849" upper="1.8849" velocity="6.283"/>
  </joint>
  <joint name="LBRiiwaJoint3" type="revolute">
    <parent link="LBRiiwa7Axis2"/>
    <child link="LBRiiwaAxis3"/>
    <origin rpy="-0.0 0.0 0.0" xyz="0.0 0.0 0.1845"/>
    <axis xyz="0.0 0.0 1.0"/>
    <limit effort="99" lower="-2.67035" upper="2.67035" velocity="6.283"/>
  </joint>
  <joint name="LBRiiwaJoint4" type="revolute">
    <parent link="LBRiiwaAxis3"/>
    <child link="LBRiiwaAxis4"/>
    <origin rpy="-0.0 0.0 0.0" xyz="0.0 0.0 0.2155"/>
    <axis xyz="0.0 -1.0 0.0"/>
    <limit effort="99" lower="-1.8849" upper="1.8849" velocity="6.283"/>
  </joint>
  <joint name="LBRiiwaJoint5" type="revolute">
    <parent link="LBRiiwaAxis4"/>
    <child link="LBRiiwaAxis5"/>
    <origin rpy="-0.0 0.0 0.0" xyz="0.0 0.0 0.1845"/>
    <axis xyz="0.0 0.0 1.0"/>
    <limit effort="99" lower="-2.67035" upper="2.67035" velocity="6.283"/>
  </joint>
  <joint name="LBRiiwaJoint6" type="revolute">
    <parent link="LBRiiwaAxis5"/>
    <child link="LBRiiwaAxis6"/>
    <origin rpy="-0.0 0.0 0.0" xyz="0.0 0.0 0.2155"/>
    <axis xyz="0.0 1.0 0.0"/>
    <limit effort="36" lower="-1.8849" upper="1.8849" velocity="6.283"/>
  </joint>
  <joint name="LBRiiwaJoint7" type="revolute">
    <parent link="LBRiiwaAxis6"/>
    <child link="LBRiiwaAxis7"/>
    <origin rpy="-0.0 0.0 0.0" xyz="0.0 0.0 0.081"/>
    <axis xyz="0.0 0.0 1.0"/>
    <limit effort="36" lower="-2.74889" upper="2.74889" velocity="6.283"/>
  </joint>
  <joint name="LBRiiwaTCP" type="fixed">
    <parent link="LBRiiwaAxis7"/>
    <child link="LBRiiwaFlange"/>
    <origin rpy="-0.0 0.0 0.0" xyz="0.0 0.0 0.071"/>
    <axis xyz="0.0 0.0 1.0"/>
  </joint>
  <transmission name="Transmission_LBRiiwa7Joint1">
    <type>transmission_interface/SimpleTransmission</type>
    <joint name="LBRiiwa7Joint1">
      <hardwareInterface>hardware_interface/EffortJointInterface</hardwareInterface>
    </joint>
    <actuator name="motor_LBRiiwa7Joint1">
      <hardwareInterface>EffortJointInterface</hardwareInterface>
      <mechanicalReduction>1.0</mechanicalReduction>
    </actuator>
  </transmission>
  <transmission name="Transmission_LBRiiwa7Joint2">
    <type>transmission_interface/SimpleTransmission</type>
    <joint name="LBRiiwa7Joint2">
      <hardwareInterface>hardware_interface/EffortJointInterface</hardwareInterface>
    </joint>
    <actuator name="motor_LBRiiwa7Joint2">
      <hardwareInterface>EffortJointInterface</hardwareInterface>
      <mechanicalReduction>1.0</mechanicalReduction>
    </actuator>
  </transmission>
  <transmission name="Transmission_LBRiiwaJoint3">
    <type>transmission_interface/SimpleTransmission</type>
    <joint name="LBRiiwaJoint3">
      <hardwareInterface>hardware_interface/EffortJointInterface</hardwareInterface>
    </joint>
    <actuator name="motor_LBRiiwaJoint3">
      <hardwareInterface>EffortJointInterface</hardwareInterface>
      <mechanicalReduction>1.0</mechanicalReduction>
    </actuator>
  </transmission>
  <transmission name="Transmission_LBRiiwaJoint4">
    <type>transmission_interface/SimpleTransmission</type>
    <joint name="LBRiiwaJoint4">
      <hardwareInterface>hardware_interface/EffortJointInterface</hardwareInterface>
    </joint>
    <actuator name="motor_LBRiiwaJoint4">
      <hardwareInterface>EffortJointInterface</hardwareInterface>
      <mechanicalReduction>1.0</mechanicalReduction>
    </actuator>
  </transmission>
  <transmission name="Transmission_LBRiiwaJoint5">
    <type>transmission_interface/SimpleTransmission</type>
    <joint name="LBRiiwaJoint5">
      <hardwareInterface>hardware_interface/EffortJointInterface</hardwareInterface>
    </joint>
    <actuator name="motor_LBRiiwaJoint5">
      <hardwareInterface>EffortJointInterface</hardwareInterface>
      <mechanicalReduction>1.0</mechanicalReduction>
    </actuator>
  </transmission>
  <transmission name="Transmission_LBRiiwaJoint6">
    <type>transmission_interface/SimpleTransmission</type>
    <joint name="LBRiiwaJoint6">
      <hardwareInterface>hardware_interface/EffortJointInterface</hardwareInterface>
    </joint>
    <actuator name="motor_LBRiiwaJoint6">
      <hardwareInterface>EffortJointInterface</hardwareInterface>
      <mechanicalReduction>1.0</mechanicalReduction>
    </actuator>
  </transmission>
  <transmission name="Transmission_LBRiiwaJoint7">
    <type>transmission_interface/SimpleTransmission</type>
    <joint name="LBRiiwaJoint7">
      <hardwareInterface>hardware_interface/EffortJointInterface</hardwareInterface>
    </joint>
    <actuator name="motor_LBRiiwaJoint7">
      <hardwareInterface>EffortJointInterface</hardwareInterface>
      <mechanicalReduction>1.0</mechanicalReduction>
    </actuator>
  </transmission>
  </xacro:macro>
</robot>
