<?xml version="1.0" encoding="UTF-8"?>
<robot name="genericMR_37146123288">
  <joint name="caster_wheel_br_joint" type="continuous">
    <axis xyz="0.0 1.0 0.0"/>
    <child link="caster_wheel_br_link"/>
    <origin rpy="-0.0 0.0 -0.0" xyz="-0.015 0.0 -0.026"/>
    <parent link="caster_base_br_link"/>
  </joint>
  <joint name="left_wheel_motor" type="continuous">
    <axis xyz="0.0 1.0 0.0"/>
    <child link="left_wheel"/>
    <limit effort="5.0E2" velocity="1.0E2"/>
    <origin rpy="-0.0 0.0 -0.0" xyz="0.0 0.325 0.06"/>
    <parent link="generic_mr_body"/>
  </joint>
  <joint name="right_wheel_motor" type="continuous">
    <axis xyz="0.0 1.0 0.0"/>
    <child link="right_wheel"/>
    <limit effort="5.0E2" velocity="1.0E1"/>
    <origin rpy="-0.0 0.0 -0.0" xyz="0.0 -0.325 0.0"/>
    <parent link="generic_mr_body"/>
  </joint>
  <joint name="caster_base_fl_joint" type="continuous">
    <axis xyz="0.0 0.0 1.0"/>
    <child link="caster_base_fl_link"/>
    <origin rpy="-0.0 0.0 -0.0" xyz="0.48 0.27 0.055"/>
    <parent link="generic_mr_body"/>
  </joint>
  <joint name="caster_base_rl_joint" type="continuous">
    <axis xyz="0.0 0.0 1.0"/>
    <child link="caster_base_rl_link"/>
    <origin rpy="-0.0 0.0 -0.0" xyz="0.48 -0.27 0.055"/>
    <parent link="generic_mr_body"/>
  </joint>
  <joint name="caster_base_bl_joint" type="continuous">
    <axis xyz="0.0 0.0 1.0"/>
    <child link="caster_base_bl_link"/>
    <origin rpy="-0.0 0.0 -0.0" xyz="-0.48 0.27 0.055"/>
    <parent link="generic_mr_body"/>
  </joint>
  <joint name="caster_base_br_joint" type="continuous">
    <axis xyz="0.0 0.0 1.0"/>
    <child link="caster_base_br_link"/>
    <origin rpy="-0.0 0.0 -0.0" xyz="-0.48 -0.27 0.055"/>
    <parent link="generic_mr_body"/>
  </joint>
  <joint name="caster_wheel_fl_joint" type="continuous">
    <axis xyz="0.0 1.0 0.0"/>
    <child link="caster_wheel_fl_link"/>
    <origin rpy="-0.0 0.0 -0.0" xyz="-0.015 0.0 -0.026"/>
    <parent link="caster_base_fl_link"/>
  </joint>
  <joint name="caster_wheel_rl_joint" type="continuous">
    <axis xyz="0.0 1.0 0.0"/>
    <child link="caster_wheel_rl_link"/>
    <origin rpy="-0.0 0.0 -0.0" xyz="-0.015 0.0 -0.026"/>
    <parent link="caster_base_rl_link"/>
  </joint>
  <joint name="caster_wheel_bl_joint" type="continuous">
    <axis xyz="0.0 1.0 0.0"/>
    <child link="caster_wheel_bl_link"/>
    <origin rpy="-0.0 0.0 -0.0" xyz="-0.015 0.0 -0.026"/>
    <parent link="caster_base_bl_link"/>
  </joint>
  <link name="generic_mr_body">
    <collision>
      <geometry>
        <mesh filename="package://generic_differential_mr_description/meshes/37156934227.stl"/>
      </geometry>
      <origin rpy="-0.0 0.0 -0.0" xyz="0.0 0.0 0.0"/>
    </collision>
    <inertial>
      <inertia ixx="5.0" ixy="0.0" ixz="0.0" iyy="10.0" iyz="0.0" izz="10.0"/>
      <mass value="1.0E1"/>
      <origin rpy="-0.0 0.0 -0.0" xyz="0.0 0.0 0.325"/>
    </inertial>
    <visual>
      <geometry>
        <mesh filename="package://generic_differential_mr_description/meshes/37156942086.stl"/>
      </geometry>
      <origin rpy="-0.0 0.0 -0.0" xyz="0.0 0.0 0.0"/>
    </visual>
  </link>
  <link name="caster_wheel_fl_link">
    <collision>
      <geometry>
        <mesh filename="package://generic_differential_mr_description/meshes/37149321854.stl"/>
      </geometry>
      <origin rpy="1.5707963267948963 0.0 -0.0" xyz="0.0 0.0 0.0"/>
    </collision>
    <inertial>
      <inertia ixx="1.0E-4" ixy="0.0" ixz="0.0" iyy="1.0E-4" iyz="0.0" izz="1.0E-4"/>
      <mass value="1.0E-1"/>
      <origin rpy="-0.0 0.0 -0.0" xyz="0.0 0.0 0.0"/>
    </inertial>
    <visual>
      <geometry>
        <mesh filename="package://generic_differential_mr_description/meshes/37149329314.stl"/>
      </geometry>
      <origin rpy="1.5707963267948963 0.0 -0.0" xyz="0.0 0.0 0.0"/>
    </visual>
  </link>
  <link name="left_wheel">
    <collision>
      <geometry>
        <mesh filename="package://generic_differential_mr_description/meshes/37153975930.stl"/>
      </geometry>
      <origin rpy="1.5707963267948963 0.0 -0.0" xyz="0.0 0.0 0.0"/>
    </collision>
    <inertial>
      <inertia ixx="5.0E-4" ixy="0.0" ixz="0.0" iyy="5.0E-4" iyz="0.0" izz="5.0E-4"/>
      <mass value="3.0E0"/>
      <origin rpy="-0.0 0.0 -0.0" xyz="0.0 0.0 0.0"/>
    </inertial>
    <visual>
      <geometry>
        <mesh filename="package://generic_differential_mr_description/meshes/37153983406.stl"/>
      </geometry>
      <origin rpy="0.0 0.0 -1.5707963267948963" xyz="0.0 -0.02 0.0"/>
    </visual>
  </link>
  <link name="caster_base_fl_link">
    <collision>
      <geometry>
        <mesh filename="package://generic_differential_mr_description/meshes/37153528620.stl"/>
      </geometry>
      <origin rpy="-0.0 0.0 -0.0" xyz="0.0 0.0 0.0"/>
    </collision>
    <inertial>
      <inertia ixx="1.0E-4" ixy="0.0" ixz="0.0" iyy="1.0E-4" iyz="0.0" izz="1.0E-4"/>
      <mass value="1.0E-1"/>
      <origin rpy="-0.0 0.0 -0.0" xyz="0.0 0.0 0.0"/>
    </inertial>
    <visual>
      <geometry>
        <mesh filename="package://generic_differential_mr_description/meshes/37153537063.stl"/>
      </geometry>
      <origin rpy="-0.0 0.0 -0.0" xyz="0.0 0.0 0.0"/>
    </visual>
  </link>
  <link name="caster_wheel_rl_link">
    <collision>
      <geometry>
        <mesh filename="package://generic_differential_mr_description/meshes/37149321854.stl"/>
      </geometry>
      <origin rpy="1.5707963267948963 0.0 -0.0" xyz="0.0 0.0 0.0"/>
    </collision>
    <inertial>
      <inertia ixx="1.0E-4" ixy="0.0" ixz="0.0" iyy="1.0E-4" iyz="0.0" izz="1.0E-4"/>
      <mass value="1.0E-1"/>
      <origin rpy="-0.0 0.0 -0.0" xyz="0.0 0.0 0.0"/>
    </inertial>
    <visual>
      <geometry>
        <mesh filename="package://generic_differential_mr_description/meshes/37149329314.stl"/>
      </geometry>
      <origin rpy="1.5707963267948963 0.0 -0.0" xyz="0.0 0.0 0.0"/>
    </visual>
  </link>
  <link name="caster_base_rl_link">
    <collision>
      <geometry>
        <mesh filename="package://generic_differential_mr_description/meshes/37153636399.stl"/>
      </geometry>
      <origin rpy="-0.0 0.0 -0.0" xyz="0.0 0.0 0.0"/>
    </collision>
    <inertial>
      <inertia ixx="1.0E-4" ixy="0.0" ixz="0.0" iyy="1.0E-4" iyz="0.0" izz="1.0E-4"/>
      <mass value="1.0E-1"/>
      <origin rpy="-0.0 0.0 -0.0" xyz="0.0 0.0 0.0"/>
    </inertial>
    <visual>
      <geometry>
        <mesh filename="package://generic_differential_mr_description/meshes/37153643851.stl"/>
      </geometry>
      <origin rpy="-0.0 0.0 -0.0" xyz="0.0 0.0 0.0"/>
    </visual>
  </link>
  <link name="right_wheel">
    <collision>
      <geometry>
        <mesh filename="package://generic_differential_mr_description/meshes/37154306984.stl"/>
      </geometry>
      <origin rpy="1.5707963267948963 0.0 -0.0" xyz="0.0 0.0 0.0"/>
    </collision>
    <inertial>
      <inertia ixx="5.0E-4" ixy="0.0" ixz="0.0" iyy="5.0E-4" iyz="0.0" izz="5.0E-4"/>
      <mass value="3.0E0"/>
      <origin rpy="-0.0 0.0 -0.0" xyz="0.0 0.0 0.0"/>
    </inertial>
    <visual>
      <geometry>
        <mesh filename="package://generic_differential_mr_description/meshes/37154317878.stl"/>
      </geometry>
      <origin rpy="-0.0 0.0 1.5707963267948963" xyz="0.0 0.02 0.0"/>
    </visual>
  </link>
  <link name="caster_wheel_bl_link">
    <collision>
      <geometry>
        <mesh filename="package://generic_differential_mr_description/meshes/37149321854.stl"/>
      </geometry>
      <origin rpy="1.5707963267948963 0.0 -0.0" xyz="0.0 0.0 0.0"/>
    </collision>
    <inertial>
      <inertia ixx="1.0E-4" ixy="0.0" ixz="0.0" iyy="1.0E-4" iyz="0.0" izz="1.0E-4"/>
      <mass value="1.0E-1"/>
      <origin rpy="-0.0 0.0 -0.0" xyz="0.0 0.0 0.0"/>
    </inertial>
    <visual>
      <geometry>
        <mesh filename="package://generic_differential_mr_description/meshes/37149329314.stl"/>
      </geometry>
      <origin rpy="1.5707963267948963 0.0 -0.0" xyz="0.0 0.0 0.0"/>
    </visual>
  </link>
  <link name="caster_base_bl_link">
    <collision>
      <geometry>
        <mesh filename="package://generic_differential_mr_description/meshes/37152976775.stl"/>
      </geometry>
      <origin rpy="-0.0 0.0 -0.0" xyz="0.0 0.0 0.0"/>
    </collision>
    <inertial>
      <inertia ixx="1.0E-4" ixy="0.0" ixz="0.0" iyy="1.0E-4" iyz="0.0" izz="1.0E-4"/>
      <mass value="1.0E-1"/>
      <origin rpy="-0.0 0.0 -0.0" xyz="0.0 0.0 0.0"/>
    </inertial>
    <visual>
      <geometry>
        <mesh filename="package://generic_differential_mr_description/meshes/37152984509.stl"/>
      </geometry>
      <origin rpy="-0.0 0.0 -0.0" xyz="0.0 0.0 0.0"/>
    </visual>
  </link>
  <link name="caster_wheel_br_link">
    <collision>
      <geometry>
        <mesh filename="package://generic_differential_mr_description/meshes/37149321854.stl"/>
      </geometry>
      <origin rpy="1.5707963267948963 0.0 -0.0" xyz="0.0 0.0 0.0"/>
    </collision>
    <inertial>
      <inertia ixx="1.0E-4" ixy="0.0" ixz="0.0" iyy="1.0E-4" iyz="0.0" izz="1.0E-4"/>
      <mass value="1.0E-1"/>
      <origin rpy="-0.0 0.0 -0.0" xyz="0.0 0.0 0.0"/>
    </inertial>
    <visual>
      <geometry>
        <mesh filename="package://generic_differential_mr_description/meshes/37149329314.stl"/>
      </geometry>
      <origin rpy="1.5707963267948963 0.0 -0.0" xyz="0.0 0.0 0.0"/>
    </visual>
  </link>
  <link name="caster_base_br_link">
    <collision>
      <geometry>
        <mesh filename="package://generic_differential_mr_description/meshes/37153311411.stl"/>
      </geometry>
      <origin rpy="-0.0 0.0 -0.0" xyz="0.0 0.0 0.0"/>
    </collision>
    <inertial>
      <inertia ixx="1.0E-4" ixy="0.0" ixz="0.0" iyy="1.0E-4" iyz="0.0" izz="1.0E-4"/>
      <mass value="1.0E-1"/>
      <origin rpy="-0.0 0.0 -0.0" xyz="0.0 0.0 0.0"/>
    </inertial>
    <visual>
      <geometry>
        <mesh filename="package://generic_differential_mr_description/meshes/37153318102.stl"/>
      </geometry>
      <origin rpy="-0.0 0.0 -0.0" xyz="0.0 0.0 0.0"/>
    </visual>
  </link>
</robot>