<?xml version="1.0"?>
<robot xmlns:xacro="http://wiki.ros.org/xacro">
  <xacro:macro name="kuka_lbr_iiwa14_r820_robot" params="io_access prefix">
  <ros2_control name="iiwa_hardware" type="system">
    <hardware>
      <plugin>kuka_sunrise::KUKAFRIHardwareInterface</plugin>
    </hardware>
    <!-- define joints and command/state interfaces for each joint -->
    <joint name="${prefix}joint_a1">
      <command_interface name="position">
        <param name="min">-1</param>
        <param name="max"> 1</param>
      </command_interface>
      <command_interface name="effort">
        <param name="min">-1</param>
        <param name="max"> 1</param>
      </command_interface>
      <state_interface name="position"/>
      <state_interface name="effort"/>
      <state_interface name="external_torque"/>
    </joint>
    <joint name="${prefix}joint_a2">
      <command_interface name="position">
        <param name="min">-1</param>
        <param name="max"> 1</param>
      </command_interface>
      <command_interface name="effort">
        <param name="min">-1</param>
        <param name="max"> 1</param>
      </command_interface>
      <state_interface name="position"/>
      <state_interface name="effort"/>
      <state_interface name="external_torque"/>
    </joint>
    <joint name="${prefix}joint_a3">
      <command_interface name="position">
        <param name="min">-1</param>
        <param name="max"> 1</param>
      </command_interface>
      <command_interface name="effort">
        <param name="min">-1</param>
        <param name="max"> 1</param>
      </command_interface>
      <state_interface name="position"/>
      <state_interface name="effort"/>
      <state_interface name="external_torque"/>
    </joint>
    <joint name="${prefix}joint_a4">
      <command_interface name="position">
        <param name="min">-1</param>
        <param name="max"> 1</param>
      </command_interface>
      <command_interface name="effort">
        <param name="min">-1</param>
        <param name="max"> 1</param>
      </command_interface>
      <state_interface name="position"/>
      <state_interface name="effort"/>
      <state_interface name="external_torque"/>
    </joint>
    <joint name="${prefix}joint_a5">
      <command_interface name="position">
        <param name="min">-1</param>
        <param name="max"> 1</param>
      </command_interface>
      <command_interface name="effort">
        <param name="min">-1</param>
        <param name="max"> 1</param>
      </command_interface>
      <state_interface name="position"/>
      <state_interface name="effort"/>
      <state_interface name="external_torque"/>
    </joint>
    <joint name="${prefix}joint_a6">
      <command_interface name="position">
        <param name="min">-1</param>
        <param name="max"> 1</param>
      </command_interface>
      <command_interface name="effort">
        <param name="min">-1</param>
        <param name="max"> 1</param>
      </command_interface>
      <state_interface name="position"/>
      <state_interface name="effort"/>
      <state_interface name="external_torque"/>
    </joint>
    <joint name="${prefix}joint_a7">
      <command_interface name="position">
        <param name="min">-1</param>
        <param name="max"> 1</param>
      </command_interface>
      <command_interface name="effort">
        <param name="min">-1</param>
        <param name="max"> 1</param>
      </command_interface>
      <state_interface name="position"/>
      <state_interface name="effort"/>
      <state_interface name="external_torque"/>
    </joint>
    <!-- TODO(Svastits): update GPIO list from config file-->
    <xacro:if value="${io_access}">
      <xacro:include filename="$(find kuka_sunrise)/config/gpio_config.xacro" />
      <xacro:fri_gpio_config/>
    </xacro:if>
    <xacro:unless value="${io_access}">
      <gpio name="gpio"/>
    </xacro:unless>
  </ros2_control>
  <gazebo>
    <plugin name="gazebo_ros2_control" filename="libgazebo_ros2_control.so">
      <robotSimType>gazebo_ros2_control/DefaultRobotHWSim</robotSimType>
      <parameters>$(find kuka_lbr_iiwa_support)/config/lbriiwa_control.yaml</parameters>
    </plugin>
  </gazebo>
  <gazebo reference="${prefix}base_link">
    <selfCollide>true</selfCollide>
    <material>Gazebo/Orange</material>
  </gazebo>
  <gazebo reference="${prefix}link_1">
    <selfCollide>true</selfCollide>
    <material>Gazebo/Orange</material>
  </gazebo>
  <gazebo reference="${prefix}link_2">
    <selfCollide>true</selfCollide>
    <material>Gazebo/Orange</material>
  </gazebo>
  <gazebo reference="${prefix}link_3">
    <selfCollide>true</selfCollide>
    <material>Gazebo/Orange</material>
  </gazebo>
  <gazebo reference="${prefix}link_4">
    <selfCollide>true</selfCollide>
    <material>Gazebo/Orange</material>
  </gazebo>
  <gazebo reference="${prefix}link_5">
    <selfCollide>true</selfCollide>
    <material>Gazebo/Orange</material>
  </gazebo>
  <gazebo reference="${prefix}link_6">
    <selfCollide>true</selfCollide>
    <material>Gazebo/Orange</material>
  </gazebo>
  <gazebo reference="${prefix}link_7">
    <selfCollide>true</selfCollide>
    <material>Gazebo/Orange</material>
  </gazebo>
  <link name="world"/>
  <link name="${prefix}base_link">
    <visual>
      <geometry>
        <mesh filename="package://kuka_lbr_iiwa_support/lbr_iiwa14_r820/meshes/visual/base_link.stl"/>
      </geometry>
      <origin rpy="-0.0 0.0 0.0" xyz="0.0 0.0 0.0"/>
    </visual>
    <collision>
      <origin rpy="-0.0 0.0 0.0" xyz="0.0 0.0 0.0"/>
      <geometry>
        <mesh filename="package://kuka_lbr_iiwa_support/lbr_iiwa14_r820/meshes/collision/base_link.stl"/>
      </geometry>
    </collision>
    <inertial>
      <mass value="3.2832"/>
      <origin rpy="0 0 0" xyz="0.0 0.0 0.0"/>
      <inertia ixx="5.0E-4" ixy="0.0" ixz="0.0" iyy="5.0E-4" iyz="0.0" izz="5.0E-4"/>
    </inertial>
  </link>
  <link name="${prefix}link_1">
    <visual>
      <geometry>
        <mesh filename="package://kuka_lbr_iiwa_support/lbr_iiwa14_r820/meshes/visual/link_1.stl"/>
      </geometry>
      <origin rpy="-0.0 0.0 0.0" xyz="0.0 0.0 0.0"/>
    </visual>
    <collision>
      <origin rpy="-0.0 0.0 0.0" xyz="0.0 0.0 0.0"/>
      <geometry>
        <mesh filename="package://kuka_lbr_iiwa_support/lbr_iiwa14_r820/meshes/collision/link_1.stl"/>
      </geometry>
    </collision>
    <inertial>
      <mass value="6.495"/>
      <origin rpy="0 0 0" xyz="0.0 0.0 0.0"/>
      <inertia ixx="0.06907" ixy="0.0" ixz="0.0" iyy="0.0711" iyz="0.0" izz="0.02"/>
    </inertial>
  </link>
  <link name="${prefix}link_2">
    <visual>
      <geometry>
        <mesh filename="package://kuka_lbr_iiwa_support/lbr_iiwa14_r820/meshes/visual/link_2.stl"/>
      </geometry>
      <origin rpy="-0.0 0.0 0.0" xyz="0.0 0.0 0.0"/>
    </visual>
    <collision>
      <origin rpy="-0.0 0.0 0.0" xyz="0.0 0.0 0.0"/>
      <geometry>
        <mesh filename="package://kuka_lbr_iiwa_support/lbr_iiwa14_r820/meshes/collision/link_2.stl"/>
      </geometry>
    </collision>
    <inertial>
      <mass value="8.365"/>
      <origin rpy="0 0 0" xyz="0.0 0.0 0.0"/>
      <inertia ixx="0.08" ixy="0.0" ixz="0.0" iyy="0.08" iyz="0.0" izz="0.01"/>
    </inertial>
  </link>
  <link name="${prefix}link_3">
    <visual>
      <geometry>
        <mesh filename="package://kuka_lbr_iiwa_support/lbr_iiwa14_r820/meshes/visual/link_3.stl"/>
      </geometry>
      <origin rpy="-0.0 0.0 0.0" xyz="0.0 0.0 0.0"/>
    </visual>
    <collision>
      <origin rpy="-0.0 0.0 0.0" xyz="0.0 0.0 0.0"/>
      <geometry>
        <mesh filename="package://kuka_lbr_iiwa_support/lbr_iiwa14_r820/meshes/collision/link_3.stl"/>
      </geometry>
    </collision>
    <inertial>
      <mass value="2.5697"/>
      <origin rpy="0 0 0" xyz="0.0 0.0 0.0"/>
      <inertia ixx="0.02" ixy="0.0" ixz="0.0" iyy="0.02" iyz="0.0" izz="0.06"/>
    </inertial>
  </link>
  <link name="${prefix}link_4">
    <visual>
      <geometry>
        <mesh filename="package://kuka_lbr_iiwa_support/lbr_iiwa14_r820/meshes/visual/link_4.stl"/>
      </geometry>
      <origin rpy="-0.0 0.0 0.0" xyz="0.0 0.0 0.0"/>
    </visual>
    <collision>
      <origin rpy="-0.0 0.0 0.0" xyz="0.0 0.0 0.0"/>
      <geometry>
        <mesh filename="package://kuka_lbr_iiwa_support/lbr_iiwa14_r820/meshes/collision/link_4.stl"/>
      </geometry>
    </collision>
    <inertial>
      <mass value="5.41"/>
      <origin rpy="0 0 0" xyz="0.0 0.0 0.0"/>
      <inertia ixx="0.04" ixy="0.0" ixz="0.0" iyy="0.03" iyz="0.0" izz="0.01"/>
    </inertial>
  </link>
  <link name="${prefix}link_5">
    <visual>
      <geometry>
        <mesh filename="package://kuka_lbr_iiwa_support/lbr_iiwa14_r820/meshes/visual/link_5.stl"/>
      </geometry>
      <origin rpy="-0.0 0.0 0.0" xyz="0.0 0.0 0.0"/>
    </visual>
    <collision>
      <origin rpy="-0.0 0.0 0.0" xyz="0.0 0.0 0.0"/>
      <geometry>
        <mesh filename="package://kuka_lbr_iiwa_support/lbr_iiwa14_r820/meshes/collision/link_5.stl"/>
      </geometry>
    </collision>
    <inertial>
      <mass value="1.867"/>
      <origin rpy="0 0 0" xyz="0.0 0.0 0.0"/>
      <inertia ixx="0.01" ixy="0.0" ixz="0.0" iyy="0.01" iyz="0.0" izz="0.01"/>
    </inertial>
  </link>
  <link name="${prefix}link_6">
    <visual>
      <geometry>
        <mesh filename="package://kuka_lbr_iiwa_support/lbr_iiwa14_r820/meshes/visual/link_6.stl"/>
      </geometry>
      <origin rpy="-0.0 0.0 0.0" xyz="0.0 0.0 0.0"/>
    </visual>
    <collision>
      <origin rpy="-0.0 0.0 0.0" xyz="0.0 0.0 0.0"/>
      <geometry>
        <mesh filename="package://kuka_lbr_iiwa_support/lbr_iiwa14_r820/meshes/collision/link_6.stl"/>
      </geometry>
    </collision>
    <inertial>
      <mass value="2.458"/>
      <origin rpy="0 0 0" xyz="0.0 0.0 0.0"/>
      <inertia ixx="0.007" ixy="0.0" ixz="0.0" iyy="0.006" iyz="0.0" izz="0.005"/>
    </inertial>
  </link>
  <link name="${prefix}link_7">
    <visual>
      <geometry>
        <mesh filename="package://kuka_lbr_iiwa_support/lbr_iiwa14_r820/meshes/visual/link_7.stl"/>
      </geometry>
      <origin rpy="-0.0 0.0 0.0" xyz="0.0 0.0 0.0"/>
    </visual>
    <collision>
      <origin rpy="-0.0 0.0 0.0" xyz="0.0 0.0 0.0"/>
      <geometry>
        <mesh filename="package://kuka_lbr_iiwa_support/lbr_iiwa14_r820/meshes/collision/link_7.stl"/>
      </geometry>
    </collision>
    <inertial>
      <mass value="0.627"/>
      <origin rpy="0 0 0" xyz="0.0 0.0 0.0"/>
      <inertia ixx="3.0E-4" ixy="0.0" ixz="0.0" iyy="3.0E-4" iyz="0.0" izz="5.0E-4"/>
    </inertial>
  </link>
  <link name="LBRiiwaFlange"></link>
  <joint name="${prefix}base_linkJoint" type="fixed">
    <parent link="world"/>
    <child link="${prefix}base_link"/>
  </joint>
  <joint name="${prefix}joint_a1" type="revolute">
    <parent link="${prefix}base_link"/>
    <child link="${prefix}link_1"/>
    <origin rpy="-0.0 0.0 0.0" xyz="0.0 0.0 0.1375"/>
    <axis xyz="0.0 0.0 1.0"/>
    <limit effort="158.4" lower="-2.67035" upper="2.67035" velocity="6.283"/>
  </joint>
  <joint name="${prefix}joint_a2" type="revolute">
    <parent link="${prefix}link_1"/>
    <child link="${prefix}link_2"/>
    <origin rpy="-0.0 0.0 0.0" xyz="0.0 0.0 0.2025"/>
    <axis xyz="0.0 1.0 0.0"/>
    <limit effort="158.4" lower="-1.8849" upper="1.8849" velocity="6.283"/>
  </joint>
  <joint name="${prefix}joint_a3" type="revolute">
    <parent link="${prefix}link_2"/>
    <child link="${prefix}link_3"/>
    <origin rpy="-0.0 0.0 0.0" xyz="0.0 0.0 0.1845"/>
    <axis xyz="0.0 0.0 1.0"/>
    <limit effort="99" lower="-2.67035" upper="2.67035" velocity="6.283"/>
  </joint>
  <joint name="${prefix}joint_a4" type="revolute">
    <parent link="${prefix}link_3"/>
    <child link="${prefix}link_4"/>
    <origin rpy="-0.0 0.0 0.0" xyz="0.0 0.0 0.2155"/>
    <axis xyz="0.0 -1.0 0.0"/>
    <limit effort="99" lower="-1.8849" upper="1.8849" velocity="6.283"/>
  </joint>
  <joint name="${prefix}joint_a5" type="revolute">
    <parent link="${prefix}link_4"/>
    <child link="${prefix}link_5"/>
    <origin rpy="-0.0 0.0 0.0" xyz="0.0 0.0 0.1845"/>
    <axis xyz="0.0 0.0 1.0"/>
    <limit effort="99" lower="-2.67035" upper="2.67035" velocity="6.283"/>
  </joint>
  <joint name="${prefix}joint_a6" type="revolute">
    <parent link="${prefix}link_5"/>
    <child link="${prefix}link_6"/>
    <origin rpy="-0.0 0.0 0.0" xyz="0.0 0.0 0.2155"/>
    <axis xyz="0.0 1.0 0.0"/>
    <limit effort="36" lower="-1.8849" upper="1.8849" velocity="6.283"/>
  </joint>
  <joint name="${prefix}joint_a7" type="revolute">
    <parent link="${prefix}link_6"/>
    <child link="${prefix}link_7"/>
    <origin rpy="-0.0 0.0 0.0" xyz="0.0 0.0 0.081"/>
    <axis xyz="0.0 0.0 1.0"/>
    <limit effort="36" lower="-2.74889" upper="2.74889" velocity="6.283"/>
  </joint>
  <joint name="LBRiiwaTCP" type="fixed">
    <parent link="${prefix}link_7"/>
    <child link="LBRiiwaFlange"/>
    <origin rpy="-0.0 0.0 0.0" xyz="0.0 0.0 0.071"/>
    <axis xyz="0.0 0.0 1.0"/>
  </joint>
  <transmission name="Transmission_${prefix}joint_a1">
    <type>transmission_interface/SimpleTransmission</type>
    <joint name="${prefix}joint_a1">
      <hardwareInterface>hardware_interface/EffortJointInterface</hardwareInterface>
    </joint>
    <actuator name="motor_${prefix}joint_a1">
      <hardwareInterface>EffortJointInterface</hardwareInterface>
      <mechanicalReduction>1.0</mechanicalReduction>
    </actuator>
  </transmission>
  <transmission name="Transmission_${prefix}joint_a2">
    <type>transmission_interface/SimpleTransmission</type>
    <joint name="${prefix}joint_a2">
      <hardwareInterface>hardware_interface/EffortJointInterface</hardwareInterface>
    </joint>
    <actuator name="motor_${prefix}joint_a2">
      <hardwareInterface>EffortJointInterface</hardwareInterface>
      <mechanicalReduction>1.0</mechanicalReduction>
    </actuator>
  </transmission>
  <transmission name="Transmission_${prefix}joint_a3">
    <type>transmission_interface/SimpleTransmission</type>
    <joint name="${prefix}joint_a3">
      <hardwareInterface>hardware_interface/EffortJointInterface</hardwareInterface>
    </joint>
    <actuator name="motor_${prefix}joint_a3">
      <hardwareInterface>EffortJointInterface</hardwareInterface>
      <mechanicalReduction>1.0</mechanicalReduction>
    </actuator>
  </transmission>
  <transmission name="Transmission_${prefix}joint_a4">
    <type>transmission_interface/SimpleTransmission</type>
    <joint name="${prefix}joint_a4">
      <hardwareInterface>hardware_interface/EffortJointInterface</hardwareInterface>
    </joint>
    <actuator name="motor_${prefix}joint_a4">
      <hardwareInterface>EffortJointInterface</hardwareInterface>
      <mechanicalReduction>1.0</mechanicalReduction>
    </actuator>
  </transmission>
  <transmission name="Transmission_${prefix}joint_a5">
    <type>transmission_interface/SimpleTransmission</type>
    <joint name="${prefix}joint_a5">
      <hardwareInterface>hardware_interface/EffortJointInterface</hardwareInterface>
    </joint>
    <actuator name="motor_${prefix}joint_a5">
      <hardwareInterface>EffortJointInterface</hardwareInterface>
      <mechanicalReduction>1.0</mechanicalReduction>
    </actuator>
  </transmission>
  <transmission name="Transmission_${prefix}joint_a6">
    <type>transmission_interface/SimpleTransmission</type>
    <joint name="${prefix}joint_a6">
      <hardwareInterface>hardware_interface/EffortJointInterface</hardwareInterface>
    </joint>
    <actuator name="motor_${prefix}joint_a6">
      <hardwareInterface>EffortJointInterface</hardwareInterface>
      <mechanicalReduction>1.0</mechanicalReduction>
    </actuator>
  </transmission>
  <transmission name="Transmission_${prefix}joint_a7">
    <type>transmission_interface/SimpleTransmission</type>
    <joint name="${prefix}joint_a7">
      <hardwareInterface>hardware_interface/EffortJointInterface</hardwareInterface>
    </joint>
    <actuator name="motor_${prefix}joint_a7">
      <hardwareInterface>EffortJointInterface</hardwareInterface>
      <mechanicalReduction>1.0</mechanicalReduction>
    </actuator>
  </transmission>
  </xacro:macro>
</robot>
