<?xml version="1.0"?>
<robot xmlns:xacro="http://wiki.ros.org/xacro">
  <!-- include helper xacros -->
  <xacro:include filename="$(find kuka_lbr_iiwa_support)/urdf/lbr_iiwa_ros2_control.xacro"/>
  <xacro:include filename="$(find kuka_resources)/urdf/common_materials.xacro"/>
  <xacro:include filename="$(find kuka_lbr_iiwa_support)/urdf/lbr_iiwa_transmission.xacro"/>
  <xacro:macro name="kuka_lbr_iiwa14_r820_robot" params="io_access prefix use_fake_hardware roundtrip_time controller_ip client_ip client_port *origin">
    <!-- ros2 control instance -->
    <xacro:kuka_lbr_iiwa_ros2_control name="${prefix}lbr_iiwa14_r820" prefix="${prefix}" io_access="${io_access}" use_fake_hardware="${use_fake_hardware}" roundtrip_time="${roundtrip_time}" controller_ip="${controller_ip}" client_ip="${client_ip}" client_port="${client_port}"/>
    <!-- links - main serial chain -->
    <link name="world"/>
    <link name="${prefix}base_link">
      <visual>
        <geometry>
          <mesh filename="package://kuka_lbr_iiwa_support/meshes/lbr_iiwa14_r820/visual/base_link.stl"/>
        </geometry>
        <origin rpy="-0.0 0.0 0.0" xyz="0.0 0.0 0.0"/>
      </visual>
      <collision>
        <origin rpy="-0.0 0.0 0.0" xyz="0.0 0.0 0.0"/>
        <geometry>
          <mesh filename="package://kuka_lbr_iiwa_support/meshes/lbr_iiwa14_r820/collision/base_link.stl"/>
        </geometry>
      </collision>
    </link>
    <link name="${prefix}link_1">
      <visual>
        <geometry>
          <mesh filename="package://kuka_lbr_iiwa_support/meshes/lbr_iiwa14_r820/visual/link_1.stl"/>
        </geometry>
        <origin rpy="-0.0 0.0 0.0" xyz="0.0 0.0 0.0"/>
      </visual>
      <collision>
        <origin rpy="-0.0 0.0 0.0" xyz="0.0 0.0 0.0"/>
        <geometry>
          <mesh filename="package://kuka_lbr_iiwa_support/meshes/lbr_iiwa14_r820/collision/link_1.stl"/>
        </geometry>
      </collision>
    </link>
    <link name="${prefix}link_2">
      <visual>
        <geometry>
          <mesh filename="package://kuka_lbr_iiwa_support/meshes/lbr_iiwa14_r820/visual/link_2.stl"/>
        </geometry>
        <origin rpy="-0.0 0.0 0.0" xyz="0.0 0.0 0.0"/>
      </visual>
      <collision>
        <origin rpy="-0.0 0.0 0.0" xyz="0.0 0.0 0.0"/>
        <geometry>
          <mesh filename="package://kuka_lbr_iiwa_support/meshes/lbr_iiwa14_r820/collision/link_2.stl"/>
        </geometry>
      </collision>
    </link>
    <link name="${prefix}link_3">
      <visual>
        <geometry>
          <mesh filename="package://kuka_lbr_iiwa_support/meshes/lbr_iiwa14_r820/visual/link_3.stl"/>
        </geometry>
        <origin rpy="-0.0 0.0 0.0" xyz="0.0 0.0 0.0"/>
      </visual>
      <collision>
        <origin rpy="-0.0 0.0 0.0" xyz="0.0 0.0 0.0"/>
        <geometry>
          <mesh filename="package://kuka_lbr_iiwa_support/meshes/lbr_iiwa14_r820/collision/link_3.stl"/>
        </geometry>
      </collision>
    </link>
    <link name="${prefix}link_4">
      <visual>
        <geometry>
          <mesh filename="package://kuka_lbr_iiwa_support/meshes/lbr_iiwa14_r820/visual/link_4.stl"/>
        </geometry>
        <origin rpy="-0.0 0.0 0.0" xyz="0.0 0.0 0.0"/>
      </visual>
      <collision>
        <origin rpy="-0.0 0.0 0.0" xyz="0.0 0.0 0.0"/>
        <geometry>
          <mesh filename="package://kuka_lbr_iiwa_support/meshes/lbr_iiwa14_r820/collision/link_4.stl"/>
        </geometry>
      </collision>
    </link>
    <link name="${prefix}link_5">
      <visual>
        <geometry>
          <mesh filename="package://kuka_lbr_iiwa_support/meshes/lbr_iiwa14_r820/visual/link_5.stl"/>
        </geometry>
        <origin rpy="-0.0 0.0 0.0" xyz="0.0 0.0 0.0"/>
      </visual>
      <collision>
        <origin rpy="-0.0 0.0 0.0" xyz="0.0 0.0 0.0"/>
        <geometry>
          <mesh filename="package://kuka_lbr_iiwa_support/meshes/lbr_iiwa14_r820/collision/link_5.stl"/>
        </geometry>
      </collision>
    </link>
    <link name="${prefix}link_6">
      <visual>
        <geometry>
          <mesh filename="package://kuka_lbr_iiwa_support/meshes/lbr_iiwa14_r820/visual/link_6.stl"/>
        </geometry>
        <origin rpy="-0.0 0.0 0.0" xyz="0.0 0.0 0.0"/>
      </visual>
      <collision>
        <origin rpy="-0.0 0.0 0.0" xyz="0.0 0.0 0.0"/>
        <geometry>
          <mesh filename="package://kuka_lbr_iiwa_support/meshes/lbr_iiwa14_r820/collision/link_6.stl"/>
        </geometry>
      </collision>
    </link>
    <link name="${prefix}link_7">
      <visual>
        <geometry>
          <mesh filename="package://kuka_lbr_iiwa_support/meshes/lbr_iiwa14_r820/visual/link_7.stl"/>
        </geometry>
        <origin rpy="-0.0 0.0 0.0" xyz="0.0 0.0 0.0"/>
      </visual>
      <collision>
        <origin rpy="-0.0 0.0 0.0" xyz="0.0 0.0 0.0"/>
        <geometry>
          <mesh filename="package://kuka_lbr_iiwa_support/meshes/lbr_iiwa14_r820/collision/link_7.stl"/>
        </geometry>
      </collision>
    </link>
    <!-- joints - main serial chain -->
    <joint name="${prefix}world-base_link" type="fixed">
      <parent link="world"/>
      <child link="${prefix}base_link"/>
      <xacro:insert_block name="origin"/>
    </joint>
    <joint name="${prefix}joint_1" type="revolute">
      <parent link="${prefix}base_link"/>
      <child link="${prefix}link_1"/>
      <origin rpy="-0.0 0.0 0.0" xyz="0.0 0.0 0.1375"/>
      <axis xyz="0.0 0.0 1.0"/>
      <limit effort="0" lower="${radians(-170)}" upper="${radians(170)}" velocity="${radians(85)}"/>
    </joint>
    <joint name="${prefix}joint_2" type="revolute">
      <parent link="${prefix}link_1"/>
      <child link="${prefix}link_2"/>
      <origin rpy="-0.0 0.0 0.0" xyz="0.0 0.0 0.2025"/>
      <axis xyz="0.0 1.0 0.0"/>
      <limit effort="0" lower="${radians(-120)}" upper="${radians(120)}" velocity="${radians(85)}"/>
    </joint>
    <joint name="${prefix}joint_3" type="revolute">
      <parent link="${prefix}link_2"/>
      <child link="${prefix}link_3"/>
      <origin rpy="-0.0 0.0 0.0" xyz="0.0 0.0 0.1845"/>
      <axis xyz="0.0 0.0 1.0"/>
      <limit effort="0" lower="${radians(-170)}" upper="${radians(170)}" velocity="${radians(100)}"/>
    </joint>
    <joint name="${prefix}joint_4" type="revolute">
      <parent link="${prefix}link_3"/>
      <child link="${prefix}link_4"/>
      <origin rpy="-0.0 0.0 0.0" xyz="0.0 0.0 0.2155"/>
      <axis xyz="0.0 -1.0 0.0"/>
      <limit effort="0" lower="${radians(-120)}" upper="${radians(120)}" velocity="${radians(75)}"/>
    </joint>
    <joint name="${prefix}joint_5" type="revolute">
      <parent link="${prefix}link_4"/>
      <child link="${prefix}link_5"/>
      <origin rpy="-0.0 0.0 0.0" xyz="0.0 0.0 0.1845"/>
      <axis xyz="0.0 0.0 1.0"/>
      <limit effort="0" lower="${radians(-170)}" upper="${radians(170)}" velocity="${radians(130)}"/>
    </joint>
    <joint name="${prefix}joint_6" type="revolute">
      <parent link="${prefix}link_5"/>
      <child link="${prefix}link_6"/>
      <origin rpy="-0.0 0.0 0.0" xyz="0.0 0.0 0.2155"/>
      <axis xyz="0.0 1.0 0.0"/>
      <limit effort="0" lower="${radians(-120)}" upper="${radians(120)}" velocity="${radians(135)}"/>
    </joint>
    <joint name="${prefix}joint_7" type="revolute">
      <parent link="${prefix}link_6"/>
      <child link="${prefix}link_7"/>
      <origin rpy="-0.0 0.0 0.0" xyz="0.0 0.0 0.081"/>
      <axis xyz="0.0 0.0 1.0"/>
      <limit effort="0" lower="${radians(-175)}" upper="${radians(175)}" velocity="${radians(135)}"/>
    </joint>
    <!-- ROS-Industrial 'base' frame - equivalent of 'KUKA ROBROOT'-->
    <link name="${prefix}base"/>
    <joint name="${prefix}base_link-base" type="fixed">
      <origin xyz="0 0 0" rpy="0 0 0"/>
      <parent link="${prefix}base_link"/>
      <child link="${prefix}base"/>
    </joint>
    <!-- ROS-Industrial 'flange' frame - attachment point for EEF models -->
    <link name="${prefix}flange"/>
    <joint name="${prefix}link7-flange" type="fixed">
      <parent link="${prefix}link_7"/>
      <child link="${prefix}flange"/>
      <origin rpy="-0.0 0.0 0.0" xyz="0.0 0.0 0.071"/>
    </joint>
    <!-- ROS-Industrial 'tool0' frame - all-zeros tool frame -->
    <link name="${prefix}tool0"/>
    <joint name="${prefix}link7-tool0" type="fixed">
      <parent link="${prefix}link_7"/>
      <child link="${prefix}tool0"/>
      <origin rpy="-0.0 0.0 0.0" xyz="0.0 0.0 0.071"/>
    </joint>
  </xacro:macro>
</robot>
