<?xml version="1.0" encoding="UTF-8"?>
<robot xmlns:xacro="http://www.ros.org/wiki/xacro" name="kr12_r1450_3_hw">
  <xacro:macro name="kuka_kr12_r1450_3_hw_robot" params="prefix package_name *origin">
    <link name="${prefix}base"/>
    <link name="${prefix}base_link">
      <collision>
        <geometry>
          <mesh filename="package://${package_name}/meshes/kr12_r1450_3_hw/collision/base_link.stl"/>
        </geometry>
        <origin rpy="0.0 -0.0 0.0" xyz="0.0 0.0 0.0"/>
      </collision>
      <inertial>
        <inertia ixx="0.4960299910274121" ixy="0.0" ixz="0.0" iyy="0.6048157081105422" iyz="0.0" izz="0.6360659708620461"/>
        <mass value="3.727E1"/>
        <origin rpy="-1.55312900753334 -1.5297115505069407 -3.1392650967640674" xyz="-0.007639999999999999 -3.0E-5 0.17743"/>
      </inertial>
      <visual>
        <geometry>
          <mesh filename="package://${package_name}/meshes/kr12_r1450_3_hw/visual/base_link.dae"/>
        </geometry>
        <origin rpy="0.0 -0.0 0.0" xyz="0.0 0.0 0.0"/>
      </visual>
    </link>
    <link name="${prefix}flange"/>
    <link name="${prefix}link_1">
      <collision>
        <geometry>
          <mesh filename="package://${package_name}/meshes/kr12_r1450_3_hw/collision/link_1.stl"/>
        </geometry>
        <origin rpy="-3.141592653589793 0.0 -0.0" xyz="0.0 -1.7512449227807152e-17 0.14300000000000002"/>
      </collision>
      <inertial>
        <inertia ixx="1.1070389663856106" ixy="0.0" ixz="0.0" iyy="0.9542136834731694" iyz="0.0" izz="1.3157517337003277"/>
        <mass value="6.844E1"/>
        <origin rpy="0.46884540930966767 0.33788002249960064 -0.6970875425285978" xyz="0.07197355961426066 -0.04009006151373466 -0.1686780800701344"/>
      </inertial>
      <visual>
        <geometry>
          <mesh filename="package://${package_name}/meshes/kr12_r1450_3_hw/visual/link_1.dae"/>
        </geometry>
        <origin rpy="-3.141592653589793 0.0 -0.0" xyz="0.0 -1.7512449227807152e-17 0.14300000000000002"/>
      </visual>
    </link>
    <link name="${prefix}link_2">
      <collision>
        <geometry>
          <mesh filename="package://${package_name}/meshes/kr12_r1450_3_hw/collision/link_2.stl"/>
        </geometry>
        <origin rpy="1.5707963267948968 -0.0 1.5707963267948966" xyz="-0.374 -0.16499999999999998 0.08340000000000004"/>
      </collision>
      <inertial>
        <inertia ixx="1.6356924888576403" ixy="0.0" ixz="0.0" iyy="0.11407398602997554" iyz="0.0" izz="1.6483548252231541"/>
        <mass value="2.8532E1"/>
        <origin rpy="2.484093989675895 -1.5635756866435466 2.233732909604762" xyz="0.24280395864292725 3.87396607318099E-4 -0.0409828683583345"/>
      </inertial>
      <visual>
        <geometry>
          <mesh filename="package://${package_name}/meshes/kr12_r1450_3_hw/visual/link_2.dae"/>
        </geometry>
        <origin rpy="1.5707963267948968 -0.0 1.5707963267948966" xyz="-0.374 -0.16499999999999998 0.08340000000000004"/>
      </visual>
    </link>
    <link name="${prefix}link_3">
      <collision>
        <geometry>
          <mesh filename="package://${package_name}/meshes/kr12_r1450_3_hw/collision/link_3.stl"/>
        </geometry>
        <origin rpy="1.5707963267948968 -0.0 -0.0" xyz="-0.16500000000000004 0.934 0.07544500000000004"/>
      </collision>
      <inertial>
        <inertia ixx="0.38475715639313324" ixy="0.0" ixz="0.0" iyy="0.28985566710648264" iyz="0.0" izz="0.5180855326212194"/>
        <mass value="2.391E1"/>
        <origin rpy="0.33417721174947274 -0.23553563739349756 1.208184813745186" xyz="0.1235252208281054 -0.0939537720618988 0.06767732747804266"/>
      </inertial>
      <visual>
        <geometry>
          <mesh filename="package://${package_name}/meshes/kr12_r1450_3_hw/visual/link_3.dae"/>
        </geometry>
        <origin rpy="1.5707963267948968 -0.0 -0.0" xyz="-0.16500000000000004 0.934 0.07544500000000004"/>
      </visual>
    </link>
    <link name="${prefix}link_4">
      <collision>
        <geometry>
          <mesh filename="package://${package_name}/meshes/kr12_r1450_3_hw/collision/link_4.stl"/>
        </geometry>
        <origin rpy="1.8369701987210297e-16 1.5707963267948966 0.0" xyz="-1.122 1.678228889588536e-17 0.454"/>
      </collision>
      <inertial>
        <inertia ixx="0.0266324235481152" ixy="0.0" ixz="0.0" iyy="0.12335500610038092" iyz="0.0" izz="0.1278161448559377"/>
        <mass value="9.9E0"/>
        <origin rpy="-3.1293274108527234 -1.432579422001952 -1.5644645134037816" xyz="4.1292929292929305E-4 -0.07045919595959596 -0.21818545454545454"/>
      </inertial>
      <visual>
        <geometry>
          <mesh filename="package://${package_name}/meshes/kr12_r1450_3_hw/visual/link_4.dae"/>
        </geometry>
        <origin rpy="1.8369701987210297e-16 1.5707963267948966 0.0" xyz="-1.122 1.678228889588536e-17 0.454"/>
      </visual>
    </link>
    <link name="${prefix}link_5">
      <collision>
        <geometry>
          <mesh filename="package://${package_name}/meshes/kr12_r1450_3_hw/collision/link_5.stl"/>
        </geometry>
        <origin rpy="1.5707963267948968 -3.749399456654644e-33 -6.123233995736766e-17" xyz="-0.8651999999999999 1.122 0.0645"/>
      </collision>
      <inertial>
        <inertia ixx="0.0021390105045295924" ixy="0.0" ixz="0.0" iyy="0.004443322771594145" iyz="0.0" izz="0.004863426723876266"/>
        <mass value="1.94E0"/>
        <origin rpy="-0.011400445811909628 -0.9423868288967098 3.1397288077672774" xyz="0.01791 -5.0000000000000016E-5 0.02925000000000001"/>
      </inertial>
      <visual>
        <geometry>
          <mesh filename="package://${package_name}/meshes/kr12_r1450_3_hw/visual/link_5.dae"/>
        </geometry>
        <origin rpy="1.5707963267948968 -3.749399456654644e-33 -6.123233995736766e-17" xyz="-0.8651999999999999 1.122 0.0645"/>
      </visual>
    </link>
    <link name="${prefix}link_6">
      <collision>
        <geometry>
          <mesh filename="package://${package_name}/meshes/kr12_r1450_3_hw/collision/link_6.stl"/>
        </geometry>
        <origin rpy="1.2246467991473532e-16 1.5707963267948966 0.0" xyz="-1.1220000000000003 -5.249702461892625e-17 0.9167"/>
      </collision>
      <inertial>
        <inertia ixx="3.0104E-4" ixy="0.0" ixz="0.0" iyy="3.0185E-4" iyz="0.0" izz="4.4735E-4"/>
        <mass value="5.0E-1"/>
        <origin rpy="0.0 -0.0 0.0" xyz="0.0 -5.0E-5 -0.00862"/>
      </inertial>
      <visual>
        <geometry>
          <mesh filename="package://${package_name}/meshes/kr12_r1450_3_hw/visual/link_6.dae"/>
        </geometry>
        <origin rpy="1.2246467991473532e-16 1.5707963267948966 0.0" xyz="-1.1220000000000003 -5.249702461892625e-17 0.9167"/>
      </visual>
    </link>
    <link name="${prefix}tool0"/>
    <link name="world"/>
    <joint name="${prefix}base_link-base" type="fixed">
      <child link="${prefix}base"/>
      <parent link="${prefix}base_link"/>
    </joint>
    <joint name="${prefix}joint_1" type="revolute">
      <axis xyz="0.0 0.0 1.0"/>
      <child link="${prefix}link_1"/>
      <limit effort="7.1712E2" lower="-2.967059725E0" upper="2.967059725E0" velocity="3.1415926535897931E0"/>
      <origin rpy="3.141592653589793 -0.0 0.0" xyz="0.0 0.0 0.14300000000000002"/>
      <parent link="${prefix}base_link"/>
    </joint>
    <joint name="${prefix}joint_2" type="revolute">
      <axis xyz="0.0 0.0 1.0"/>
      <child link="${prefix}link_2"/>
      <limit effort="6.4717893753510191E2" lower="-3.2288591125E0" upper="1.1344640125E0" velocity="2.9670597283903604E0"/>
      <origin rpy="1.5707963267948966 -0.0 0.0" xyz="0.165 0.0834 -0.231"/>
      <parent link="${prefix}link_1"/>
    </joint>
    <joint name="${prefix}joint_3" type="revolute">
      <axis xyz="0.0 0.0 1.0"/>
      <child link="${prefix}link_3"/>
      <limit effort="3.7800154574697081E2" lower="-2.0943951E0" upper="3.14159265E0" velocity="4.5378560551852569E0"/>
      <origin rpy="0.0 -0.0 0.0" xyz="0.56 0.0 0.007954999999999999"/>
      <parent link="${prefix}link_2"/>
    </joint>
    <joint name="${prefix}joint_4" type="revolute">
      <axis xyz="0.0 0.0 1.0"/>
      <child link="${prefix}link_4"/>
      <limit effort="5.4835130643148524E1" lower="-3.14159265E0" upper="3.14159265E0" velocity="7.5049157835756173E0"/>
      <origin rpy="1.5707963267948966 -0.0 -1.5707963267948966" xyz="0.289 -0.188 0.075445"/>
      <parent link="${prefix}link_3"/>
    </joint>
    <joint name="${prefix}joint_5" type="revolute">
      <axis xyz="0.0 0.0 1.0"/>
      <child link="${prefix}link_5"/>
      <limit effort="4.96756170567014E1" lower="-2.44346095E0" upper="2.44346095E0" velocity="7.8539816339744828E0"/>
      <origin rpy="0.0 1.5707963267948966 1.5707963267948966" xyz="0.0 -0.0645 -0.4112"/>
      <parent link="${prefix}link_4"/>
    </joint>
    <joint name="${prefix}joint_6" type="revolute">
      <axis xyz="0.0 0.0 1.0"/>
      <child link="${prefix}link_6"/>
      <limit effort="2.8117123201915362E1" lower="-6.108652375E0" upper="6.108652375E0" velocity="1.2566370614359172E1"/>
      <origin rpy="1.5707963267948966 -0.0 -1.5707963267948966" xyz="0.051500000000000004 0.0 0.0645"/>
      <parent link="${prefix}link_5"/>
    </joint>
    <joint name="${prefix}link6-flange" type="fixed">
      <child link="${prefix}flange"/>
      <origin rpy="0.0 1.5707963267948966 0.0" xyz="0.0 0.0 -0.0285"/>
      <parent link="${prefix}link_6"/>
    </joint>
    <joint name="${prefix}link6-tool0" type="fixed">
      <child link="${prefix}tool0"/>
      <origin rpy="3.141592653589793 1.2246467991473532E-16 3.141592653589793" xyz="0.0 0.0 -0.0285"/>
      <parent link="${prefix}link_6"/>
    </joint>
    <joint name="${prefix}world-base_link" type="fixed">
      <child link="${prefix}base_link"/>
      <parent link="world"/>
      <xacro:insert_block name="origin"/>
    </joint>
  </xacro:macro>
</robot>
