<?xml version='1.0' encoding='UTF-8'?>
<robot xmlns:xacro="http://www.ros.org/wiki/xacro" name="kr300_r2800_2_mt">
  <xacro:macro name="kuka_kr300_r2800_2_mt_robot" params="prefix package_name *origin">
    <link name="${prefix}base"/>
    <link name="${prefix}base_link">
      <collision>
        <geometry>
          <mesh filename="package://${package_name}/meshes/kr300_r2800_2_mt/collision/base_link.stl"/>
        </geometry>
        <origin rpy="0.0 -0.0 0.0" xyz="0.0 0.0 0.0"/>
      </collision>
      <inertial>
        <inertia ixx="35.410866659825984" ixy="0.0" ixz="0.0" iyy="34.55474294133751" iyz="0.0" izz="38.97491524228647"/>
        <mass value="4.3839E2"/>
        <origin rpy="-0.2634507794798889 -0.011417952338033853 -1.583116210409526" xyz="-0.02196341111795434 2.6633773580602294E-4 0.2908246588653938"/>
      </inertial>
      <visual>
        <geometry>
          <mesh filename="package://${package_name}/meshes/kr300_r2800_2_mt/visual/base_link.dae"/>
        </geometry>
        <origin rpy="0.0 -0.0 0.0" xyz="0.0 0.0 0.0"/>
      </visual>
    </link>
    <link name="${prefix}flange"/>
    <link name="${prefix}link_1">
      <collision>
        <geometry>
          <mesh filename="package://${package_name}/meshes/kr300_r2800_2_mt/collision/link_1.stl"/>
        </geometry>
        <origin rpy="-3.141592653589793 0.0 -0.0" xyz="0.0 -5.634599922876973e-17 0.4601"/>
      </collision>
      <inertial>
        <inertia ixx="33.87155206611269" ixy="0.0" ixz="0.0" iyy="73.40332727644804" iyz="0.0" izz="90.87256570826523"/>
        <mass value="5.8662E2"/>
        <origin rpy="-1.5900025949519248 -0.0055486359630952525 0.005318876071887375" xyz="0.06073307456274931 0.008179142374961645 -0.3078055828304523"/>
      </inertial>
      <visual>
        <geometry>
          <mesh filename="package://${package_name}/meshes/kr300_r2800_2_mt/visual/link_1.dae"/>
        </geometry>
        <origin rpy="-3.141592653589793 0.0 -0.0" xyz="0.0 -5.634599922876973e-17 0.4601"/>
      </visual>
    </link>
    <link name="${prefix}link_2">
      <collision>
        <geometry>
          <mesh filename="package://${package_name}/meshes/kr300_r2800_2_mt/collision/link_2.stl"/>
        </geometry>
        <origin rpy="1.5707963267948968 -0.0 1.5707963267948966" xyz="-0.86 -0.49999999999999994 1.0900581159210591e-16"/>
      </collision>
      <inertial>
        <inertia ixx="244.50647647353642" ixy="0.0" ixz="0.0" iyy="49.198090154026325" iyz="0.0" izz="279.8190505897405"/>
        <mass value="7.3429000000000019E2"/>
        <origin rpy="-1.3718367456754406 -1.547362584971657 2.9399464369736323" xyz="0.5473160743030682 -0.007731954949679284 0.04776093559765214"/>
      </inertial>
      <visual>
        <geometry>
          <mesh filename="package://${package_name}/meshes/kr300_r2800_2_mt/visual/link_2.dae"/>
        </geometry>
        <origin rpy="1.5707963267948968 -0.0 1.5707963267948966" xyz="-0.86 -0.49999999999999994 1.0900581159210591e-16"/>
      </visual>
    </link>
    <link name="${prefix}link_3">
      <collision>
        <geometry>
          <mesh filename="package://${package_name}/meshes/kr300_r2800_2_mt/collision/link_3.stl"/>
        </geometry>
        <origin rpy="1.5707963267948968 -0.0 -0.0" xyz="-0.5000000000000001 2.11 1.0900581159210584e-16"/>
      </collision>
      <inertial>
        <inertia ixx="94.58779070370784" ixy="0.0" ixz="0.0" iyy="12.778429491747248" iyz="0.0" izz="98.5803684136603"/>
        <mass value="5.0064599999999996E2"/>
        <origin rpy="-0.004167314080299402 0.05497939548244204 1.5015439278651141" xyz="-0.23525594541424868 -0.09332184547575578 -0.009671485786503266"/>
      </inertial>
      <visual>
        <geometry>
          <mesh filename="package://${package_name}/meshes/kr300_r2800_2_mt/visual/link_3.dae"/>
        </geometry>
        <origin rpy="1.5707963267948968 -0.0 -0.0" xyz="-0.5000000000000001 2.11 1.0900581159210584e-16"/>
      </visual>
    </link>
    <link name="${prefix}link_4">
      <collision>
        <geometry>
          <mesh filename="package://${package_name}/meshes/kr300_r2800_2_mt/collision/link_4.stl"/>
        </geometry>
        <origin rpy="1.8369701987210297e-16 1.5707963267948966 0.0" xyz="-2.29 3.479833879777203e-17 1.2118999999999998"/>
      </collision>
      <inertial>
        <inertia ixx="0.6936780086008919" ixy="0.0" ixz="0.0" iyy="2.785065576107537" iyz="0.0" izz="2.8625100540828337"/>
        <mass value="9.7442000000000007E1"/>
        <origin rpy="1.5709322720910581 -1.2743253802401944 -1.5707667143862865" xyz="-5.438697948307435E-7 0.0422933343722767 -0.18193497897865968"/>
      </inertial>
      <visual>
        <geometry>
          <mesh filename="package://${package_name}/meshes/kr300_r2800_2_mt/visual/link_4.dae"/>
        </geometry>
        <origin rpy="1.8369701987210297e-16 1.5707963267948966 0.0" xyz="-2.29 3.479833879777203e-17 1.2118999999999998"/>
      </visual>
    </link>
    <link name="${prefix}link_5">
      <collision>
        <geometry>
          <mesh filename="package://${package_name}/meshes/kr300_r2800_2_mt/collision/link_5.stl"/>
        </geometry>
        <origin rpy="1.5707963267948968 -3.749399456654644e-33 -6.123233995736766e-17" xyz="-1.5344999999999998 2.29 -0.1251"/>
      </collision>
      <inertial>
        <inertia ixx="1.1020383254601218" ixy="0.0" ixz="0.0" iyy="0.7839386923973062" iyz="0.0" izz="1.2082847469979934"/>
        <mass value="5.36088E1"/>
        <origin rpy="-1.5642278602027881 -0.8175710147649947 -0.011709797778757787" xyz="0.06813413576091985 -4.9894728477414026E-5 -0.08933900512266643"/>
      </inertial>
      <visual>
        <geometry>
          <mesh filename="package://${package_name}/meshes/kr300_r2800_2_mt/visual/link_5.dae"/>
        </geometry>
        <origin rpy="1.5707963267948968 -3.749399456654644e-33 -6.123233995736766e-17" xyz="-1.5344999999999998 2.29 -0.1251"/>
      </visual>
    </link>
    <link name="${prefix}link_6">
      <collision>
        <geometry>
          <mesh filename="package://${package_name}/meshes/kr300_r2800_2_mt/collision/link_6.stl"/>
        </geometry>
        <origin rpy="1.2246467991473532e-16 1.5707963267948966 0.0" xyz="-2.29 -1.0542371970459992e-16 1.7495999999999998"/>
      </collision>
      <inertial>
        <inertia ixx="0.1546272532239273" ixy="0.0" ixz="0.0" iyy="0.1547598728909128" iyz="0.0" izz="0.18961138268388045"/>
        <mass value="3.202E1"/>
        <origin rpy="0.0020471651340902893 7.476904024900574E-5 -1.5692303732486166" xyz="-4.8657089319175515E-5 -2.5301686445971257E-6 -0.020301339787632735"/>
      </inertial>
      <visual>
        <geometry>
          <mesh filename="package://${package_name}/meshes/kr300_r2800_2_mt/visual/link_6.dae"/>
        </geometry>
        <origin rpy="1.2246467991473532e-16 1.5707963267948966 0.0" xyz="-2.29 -1.0542371970459992e-16 1.7495999999999998"/>
      </visual>
    </link>
    <link name="${prefix}tool0"/>
    <link name="world"/>
    <joint name="${prefix}base_link-base" type="fixed">
      <child link="${prefix}base"/>
      <parent link="${prefix}base_link"/>
    </joint>
    <joint name="${prefix}joint_1" type="revolute">
      <axis xyz="0.0 0.0 1.0"/>
      <child link="${prefix}link_1"/>
      <limit effort="1.5E4" lower="-3.2288591125E0" upper="3.2288591125E0" velocity="6.9813170079773179E-1"/>
      <origin rpy="3.141592653589793 -0.0 0.0" xyz="0.0 0.0 0.4601"/>
      <parent link="${prefix}base_link"/>
    </joint>
    <joint name="${prefix}joint_2" type="revolute">
      <axis xyz="0.0 0.0 1.0"/>
      <child link="${prefix}link_2"/>
      <limit effort="1.788024E4" lower="-2.268928025E0" upper="3.4906585E-1" velocity="6.9813170079773179E-1"/>
      <origin rpy="1.5707963267948966 -0.0 0.0" xyz="0.5 0.0 -0.3999"/>
      <parent link="${prefix}link_1"/>
    </joint>
    <joint name="${prefix}joint_3" type="revolute">
      <axis xyz="0.0 0.0 1.0"/>
      <child link="${prefix}link_3"/>
      <limit effort="1.6714602145257235E4" lower="-1.74532925E0" upper="2.8797932625E0" velocity="6.9813170079773179E-1"/>
      <origin rpy="0.0 -0.0 0.0" xyz="1.25 0.0 0.0"/>
      <parent link="${prefix}link_2"/>
    </joint>
    <joint name="${prefix}joint_4" type="revolute">
      <axis xyz="0.0 0.0 1.0"/>
      <child link="${prefix}link_4"/>
      <limit effort="6.4398108360664783E3" lower="-6.108652375E0" upper="6.108652375E0" velocity="1.5707963267948966E0"/>
      <origin rpy="1.5707963267948966 -0.0 -1.5707963267948966" xyz="0.7119 -0.18 0.0"/>
      <parent link="${prefix}link_3"/>
    </joint>
    <joint name="${prefix}joint_5" type="revolute">
      <axis xyz="0.0 0.0 1.0"/>
      <child link="${prefix}link_5"/>
      <limit effort="6.4095991959749445E3" lower="-2.0943951E0" upper="2.0943951E0" velocity="1.5707963267948966E0"/>
      <origin rpy="0.0 1.5707963267948966 1.5707963267948966" xyz="0.0 0.1251 -0.32260000000000005"/>
      <parent link="${prefix}link_4"/>
    </joint>
    <joint name="${prefix}joint_6" type="revolute">
      <axis xyz="0.0 0.0 1.0"/>
      <child link="${prefix}link_6"/>
      <limit effort="3.1540572942480439E3" lower="-6.108652375E0" upper="6.108652375E0" velocity="2.2689280275926285E0"/>
      <origin rpy="1.5707963267948966 -0.0 -1.5707963267948966" xyz="0.21509999999999996 0.0 -0.1251"/>
      <parent link="${prefix}link_5"/>
    </joint>
    <joint name="${prefix}link6-flange" type="fixed">
      <child link="${prefix}flange"/>
      <origin rpy="0.0 1.5707963267948966 0.0" xyz="0.0 0.0 -0.08990000000000001"/>
      <parent link="${prefix}link_6"/>
    </joint>
    <joint name="${prefix}link6-tool0" type="fixed">
      <child link="${prefix}tool0"/>
      <origin rpy="3.141592653589793 1.2246467991473532E-16 3.141592653589793" xyz="0.0 0.0 -0.08990000000000001"/>
      <parent link="${prefix}link_6"/>
    </joint>
    <joint name="${prefix}world-base_link" type="fixed">
      <child link="${prefix}base_link"/>
      <parent link="world"/>
      <xacro:insert_block name="origin"/>
    </joint>
  </xacro:macro>
</robot>