<?xml version="1.0" encoding="UTF-8"?>
<robot xmlns:xacro="http://www.ros.org/wiki/xacro" name="kr600_r2830">
  <xacro:macro name="kuka_kr600_r2830_robot" params="prefix package_name">
    <link name="${prefix}base"/>
    <link name="${prefix}base_link">
      <collision>
        <geometry>
          <mesh filename="package://${package_name}/meshes/kr600_r2830/collision/base_link.stl"/>
        </geometry>
        <origin rpy="0.0 -0.0 0.0" xyz="0.0 0.0 0.0"/>
      </collision>
      <inertial>
        <!-- Note that these values are only rough estimates -->
        <inertia ixx="51.517115" ixy="0.0" ixz="0.0" iyy="51.517115" iyz="0.0" izz="78.877915"/>
        <mass value="4.461E2"/>
        <origin rpy="0.0 -0.0 0.0" xyz="0.0 0.0 0.0"/>
      </inertial>
      <visual>
        <geometry>
          <mesh filename="package://${package_name}/meshes/kr600_r2830/visual/base_link.dae"/>
        </geometry>
        <origin rpy="0.0 -0.0 0.0" xyz="0.0 0.0 0.0"/>
      </visual>
    </link>
    <link name="${prefix}flange"/>
    <link name="${prefix}link_1">
      <collision>
        <geometry>
          <mesh filename="package://${package_name}/meshes/kr600_r2830/collision/link_1.stl"/>
        </geometry>
        <origin rpy="-3.141592653589793 0.0 -0.0" xyz="0.0 -4.898587196589413e-17 0.4"/>
      </collision>
      <inertial>
        <!-- Note that these values are only rough estimates -->
        <inertia ixx="123.69141666666667" ixy="0.0" ixz="0.0" iyy="142.48258833333333" iyz="0.0" izz="206.27758833333334"/>
        <mass value="8.506E2"/>
        <origin rpy="0.0 -0.0 0.0" xyz="0.1452291 0.0490361 -0.4425695"/>
      </inertial>
      <visual>
        <geometry>
          <mesh filename="package://${package_name}/meshes/kr600_r2830/visual/link_1.dae"/>
        </geometry>
        <origin rpy="-3.141592653589793 0.0 -0.0" xyz="0.0 -4.898587196589413e-17 0.4"/>
      </visual>
    </link>
    <link name="${prefix}link_2">
      <collision>
        <geometry>
          <mesh filename="package://${package_name}/meshes/kr600_r2830/collision/link_2.stl"/>
        </geometry>
        <origin rpy="1.5707963267948968 -0.0 1.5707963267948966" xyz="-1.045 -0.49999999999999994 1.1297366722134329e-16"/>
      </collision>
      <inertial>
        <inertia ixx="14.5413" ixy="0.0" ixz="0.0" iyy="147.936" iyz="0.0" izz="151.0383"/>
        <mass value="4.476E2"/>
        <origin rpy="0.0 -0.0 0.0" xyz="0.48573200000000005 0.0 -0.0583625"/>
      </inertial>
      <visual>
        <geometry>
          <mesh filename="package://${package_name}/meshes/kr600_r2830/visual/link_2.dae"/>
        </geometry>
        <origin rpy="1.5707963267948968 -0.0 1.5707963267948966" xyz="-1.045 -0.49999999999999994 1.1297366722134329e-16"/>
      </visual>
    </link>
    <link name="${prefix}link_3">
      <collision>
        <geometry>
          <mesh filename="package://${package_name}/meshes/kr600_r2830/collision/link_3.stl"/>
        </geometry>
        <origin rpy="1.5707963267948968 -0.0 -0.0" xyz="-0.5000000000000001 2.345 1.1297366722134334e-16"/>
      </collision>
      <inertial>
        <inertia ixx="20.2289" ixy="0.0" ixz="0.0" iyy="99.2862" iyz="0.0" izz="102.1398"/>
        <mass value="5.4522E2"/>
        <origin rpy="0.0 -0.0 0.0" xyz="-0.3247315 0.0 0.24993"/>
      </inertial>
      <visual>
        <geometry>
          <mesh filename="package://${package_name}/meshes/kr600_r2830/visual/link_3.dae"/>
        </geometry>
        <origin rpy="1.5707963267948968 -0.0 -0.0" xyz="-0.5000000000000001 2.345 1.1297366722134334e-16"/>
      </visual>
    </link>
    <link name="${prefix}link_4">
      <collision>
        <geometry>
          <mesh filename="package://${package_name}/meshes/kr600_r2830/collision/link_4.stl"/>
        </geometry>
        <origin rpy="1.8369701987210297e-16 1.5707963267948966 0.0" xyz="-2.29 4.7822457506704105e-17 1.0639999999999998"/>
      </collision>
      <inertial>
        <inertia ixx="7.0753" ixy="0.0" ixz="0.0" iyy="3.2141" iyz="0.0" izz="8.8541"/>
        <mass value="1.76E2"/>
        <origin rpy="1.5707963267948966 -0.0 1.5707963267948966" xyz="0.0 0.0 -0.3250174"/>
      </inertial>
      <visual>
        <geometry>
          <mesh filename="package://${package_name}/meshes/kr600_r2830/visual/link_4.dae"/>
        </geometry>
        <origin rpy="1.8369701987210297e-16 1.5707963267948966 0.0" xyz="-2.29 4.7822457506704105e-17 1.0639999999999998"/>
      </visual>
    </link>
    <link name="${prefix}link_5">
      <collision>
        <geometry>
          <mesh filename="package://${package_name}/meshes/kr600_r2830/collision/link_5.stl"/>
        </geometry>
        <origin rpy="1.5707963267948968 -3.749399456654644e-33 -6.123233995736766e-17" xyz="-1.525 2.29 9.79717439317831e-19"/>
      </collision>
      <inertial>
        <!-- Note that these values are only rough estimates -->
        <inertia ixx="1.6033333333333335E-8" ixy="0.0" ixz="0.0" iyy="2.056666666666667E-8" iyz="0.0" izz="1.9533333333333333E-8"/>
        <mass value="1.0E-6"/>
        <origin rpy="0.0 -0.0 0.0" xyz="0.0 0.0 0.0"/>
      </inertial>
      <visual>
        <geometry>
          <mesh filename="package://${package_name}/meshes/kr600_r2830/visual/link_5.dae"/>
        </geometry>
        <origin rpy="1.5707963267948968 -3.749399456654644e-33 -6.123233995736766e-17" xyz="-1.525 2.29 9.79717439317831e-19"/>
      </visual>
    </link>
    <link name="${prefix}link_6">
      <collision>
        <geometry>
          <mesh filename="package://${package_name}/meshes/kr600_r2830/collision/link_6.stl"/>
        </geometry>
        <origin rpy="1.2246467991473532e-16 1.5707963267948966 0.0" xyz="-2.2900000000000005 -1.1015697958330443e-16 1.8149999999999997"/>
      </collision>
      <inertial>
        <!-- Note that these values are only rough estimates -->
        <inertia ixx="5.416666666666666E-9" ixy="0.0" ixz="0.0" iyy="5.416666666666666E-9" iyz="0.0" izz="1.0416666666666666E-8"/>
        <mass value="1.0E-6"/>
        <origin rpy="0.0 -0.0 0.0" xyz="0.0 0.0 0.0"/>
      </inertial>
      <visual>
        <geometry>
          <mesh filename="package://${package_name}/meshes/kr600_r2830/visual/link_6.dae"/>
        </geometry>
        <origin rpy="1.2246467991473532e-16 1.5707963267948966 0.0" xyz="-2.2900000000000005 -1.1015697958330443e-16 1.8149999999999997"/>
      </visual>
    </link>
    <link name="${prefix}tool0"/>
    <joint name="${prefix}base_link-base" type="fixed">
      <child link="${prefix}base"/>
      <parent link="${prefix}base_link"/>
    </joint>
    <joint name="${prefix}joint_1" type="revolute">
      <axis xyz="0.0 0.0 1.0"/>
      <child link="${prefix}link_1"/>
      <limit effort="1.44E4" lower="-3.2288591125E0" upper="3.2288591125E0" velocity="1.3964E0"/>
      <origin rpy="3.141592653589793 -0.0 0.0" xyz="0.0 0.0 0.4"/>
      <parent link="${prefix}base_link"/>
    </joint>
    <joint name="${prefix}joint_2" type="revolute">
      <axis xyz="0.0 0.0 1.0"/>
      <child link="${prefix}link_2"/>
      <limit effort="1.44E4" lower="-2.268928025E0" upper="3.4906585E-1" velocity="1.3092E0"/>
      <origin rpy="1.5707963267948966 -0.0 0.0" xyz="0.5 0.0 -0.645"/>
      <parent link="${prefix}link_1"/>
    </joint>
    <joint name="${prefix}joint_3" type="revolute">
      <axis xyz="0.0 0.0 1.0"/>
      <child link="${prefix}link_3"/>
      <limit effort="1.13315047E4" lower="-1.74532925E0" upper="2.51327412E0" velocity="1.2219E0"/>
      <origin rpy="0.0 -0.0 0.0" xyz="1.3 0.0 0.0"/>
      <parent link="${prefix}link_2"/>
    </joint>
    <joint name="${prefix}joint_4" type="revolute">
      <axis xyz="0.0 0.0 1.0"/>
      <child link="${prefix}link_4"/>
      <limit effort="4.3824374E3" lower="-6.108652375E0" upper="6.108652375E0" velocity="1.23E0"/>
      <origin rpy="1.5707963267948966 -0.0 -1.5707963267948966" xyz="0.5640000000000001 0.055 0.0"/>
      <parent link="${prefix}link_3"/>
    </joint>
    <joint name="${prefix}joint_5" type="revolute">
      <axis xyz="0.0 0.0 1.0"/>
      <child link="${prefix}link_5"/>
      <limit effort="4.3824374E3" lower="-2.0943951E0" upper="2.0943951E0" velocity="1.2297E0"/>
      <origin rpy="0.0 1.5707963267948966 1.5707963267948966" xyz="0.0 0.0 -0.461"/>
      <parent link="${prefix}link_4"/>
    </joint>
    <joint name="${prefix}joint_6" type="revolute">
      <axis xyz="0.0 0.0 1.0"/>
      <child link="${prefix}link_6"/>
      <limit effort="2.14398E3" lower="-6.108652375E0" upper="6.108652375E0" velocity="1.9141E0"/>
      <origin rpy="1.5707963267948966 -0.0 -1.5707963267948966" xyz="0.29 0.0 0.0"/>
      <parent link="${prefix}link_5"/>
    </joint>
    <joint name="${prefix}link6-flange" type="fixed">
      <child link="${prefix}flange"/>
      <origin rpy="0.0 1.5707963267948966 0.0" xyz="0.0 0.0 0.0"/>
      <parent link="${prefix}link_6"/>
    </joint>
    <joint name="${prefix}link6-tool0" type="fixed">
      <child link="${prefix}tool0"/>
      <origin rpy="3.141592653589793 1.2246467991473532E-16 3.141592653589793" xyz="0.0 0.0 0.0"/>
      <parent link="${prefix}link_6"/>
    </joint>
  </xacro:macro>
</robot>
